Workbook

Sheet Welcome
C1: PROTEIN RATIO Harbour Market catalogue
A5: HARBOUR MARKET · CATALOGUE 2026
A6: 30 products from your catalogue file, each classified for WWF and for the Protein Tracker. Protein contents: your declared values, then the Altera reference database, Open Food Facts (ODbL), NEVO and CIQUAL.
A8: What this workbook contains | B8: The share of the protein you put on the market that is plant-based, and how it breaks down.
A10: How to use it | B10: Enter your sales volumes in the yellow column, further down this page. All tabs recalculate automatically.
A12: Your volumes | B12: Units sold over twelve months, from your file: type others over them and every tab recalculates.
A14: ACCURACY | B14: Measured by hand | C14: Measured on your own catalogue, one rate per field, on a control sample sealed before review: • 500 products drawn at random • the 500 heaviest products in tonnes of protein • the 3 best sellers of every category Reviewed by hand, row by row.
A19: THE TABS
A20: Protein Tracker | B20: the ratio and the four classes of the GPA methodology
A21: WWF | B21: the seven food groups, whole versus composite, the detail by subgroup
A22: By category | B22: the WWF sub-groups and the 28 retailer categories
A23: By department | B23: the 15 departments
A24: By brand | B24: the 30 brands
A25: By product | B25: the 10 products carrying the most plant protein and the 10 carrying the most animal protein
A26: Data | B26: one row per product, 30 in total
A30: YOUR SALES VOLUMES · enter them in the yellow column
A31: Sorted by sales rank: item 1 is the one that sells the most.
A32: Sales rank | B32: EAN 13 | C32: Product | D32: Volume sold (units)
A33: 1 | B33: 3428273980046 | C33: Matin Léger semi-skimmed milk, 1 L | D33: 612000
A34: 2 | B34: 5449000214911 | C34: Coca-Cola Original, 33 cl | D34: 296000
A35: 3 | B35: 8076800195057 | C35: Spaghetti n°5, 500 g | D35: 254000
A36: 4 | B36: 3154230809302 | C36: Le Bon Paris cooked ham, 4 slices | D36: 228000
A37: 5 | B37: 3251320080617 | C37: 6 free-range eggs, Label Rouge | D37: 214000
A38: 6 | B38: 3181232220286 | C38: Minced beef patties 5% fat, 2 × 130 g | D38: 186000
A39: 7 | B39: 3119780259625 | C39: Heineken lager, 33 cl | D39: 180000
A40: 8 | B40: 3228857000852 | C40: Crustless white sandwich bread, 500 g | D40: 167000
A41: 9 | B41: 3033491147067 | C41: Activia natural yogurt, 4 × 125 g | D41: 164000
A42: 10 | B42: 3266980891411 | C42: Chicken breast fillets, 300 g | D42: 142000
A43: 11 | B43: 3017620422003 | C43: Nutella hazelnut spread, 400 g | D43: 139000
A44: 12 | B44: 3412290015980 | C44: Unsalted butter, 250 g | D44: 131000
... A62: 30 | B62: 4012359144003 | C62: Japanese-style tofu fillets, 160 g | D62: 9800

Sheet Protein Tracker
A1: PROTEIN TRACKER · Green Protein Alliance
A3: Plant share of protein | C3: =IF(SUMIFS(Data!$S$2:$S$31,Data!$K$2:$K$31,"<>not applicable")+SUMIFS(Data!$T$2:$T$31,Data!$K$2:$K$31,"<>not applicable")=0,"",SUMIFS(Data!$S$2:$S$31,Data!$K$2:$K$31,"<>not applicable")/(SUMIFS(Data!$S$2:$S$31,Data!$K$2:$K$31,"<>not applicable")+SUMIFS(Data!$T$2:$T$31,Data!$K$2:$K$31,"<>not applicable")))
A4: across the Protein Tracker scope
A6: Each product falls into one class and only one. The four classes below cover the whole scope.
A8: THE FOUR CLASSES
B10: Protein (t) | C10: Share
A11: Animal core | B11: =(SUMIFS(Data!$S$2:$S$31,Data!$K$2:$K$31,"animal_core")+SUMIFS(Data!$T$2:$T$31,Data!$K$2:$K$31,"animal_core"))/1000 | C11: =IF((SUMIFS(Data!$S$2:$S$31,Data!$K$2:$K$31,"<>not applicable")+SUMIFS(Data!$T$2:$T$31,Data!$K$2:$K$31,"<>not applicable"))=0,"",B11*1000/(SUMIFS(Data!$S$2:$S$31,Data!$K$2:$K$31,"<>not applicable")+SUMIFS(Data!$T$2:$T$31,Data!$K$2:$K$31,"<>not applicable")))
A12: Animal and plant composite | B12: =(SUMIFS(Data!$S$2:$S$31,Data!$K$2:$K$31,"animal-plant-based composite")+SUMIFS(Data!$T$2:$T$31,Data!$K$2:$K$31,"animal-plant-based composite"))/1000 | C12: =IF((SUMIFS(Data!$S$2:$S$31,Data!$K$2:$K$31,"<>not applicable")+SUMIFS(Data!$T$2:$T$31,Data!$K$2:$K$31,"<>not applicable"))=0,"",B12*1000/(SUMIFS(Data!$S$2:$S$31,Data!$K$2:$K$31,"<>not applicable")+SUMIFS(Data!$T$2:$T$31,Data!$K$2:$K$31,"<>not applicable")))
A13: Plant-based non-core | B13: =(SUMIFS(Data!$S$2:$S$31,Data!$K$2:$K$31,"plant_non_core")+SUMIFS(Data!$T$2:$T$31,Data!$K$2:$K$31,"plant_non_core"))/1000 | C13: =IF((SUMIFS(Data!$S$2:$S$31,Data!$K$2:$K$31,"<>not applicable")+SUMIFS(Data!$T$2:$T$31,Data!$K$2:$K$31,"<>not applicable"))=0,"",B13*1000/(SUMIFS(Data!$S$2:$S$31,Data!$K$2:$K$31,"<>not applicable")+SUMIFS(Data!$T$2:$T$31,Data!$K$2:$K$31,"<>not applicable")))
A14: Plant-based core | B14: =(SUMIFS(Data!$S$2:$S$31,Data!$K$2:$K$31,"plant_core")+SUMIFS(Data!$T$2:$T$31,Data!$K$2:$K$31,"plant_core"))/1000 | C14: =IF((SUMIFS(Data!$S$2:$S$31,Data!$K$2:$K$31,"<>not applicable")+SUMIFS(Data!$T$2:$T$31,Data!$K$2:$K$31,"<>not applicable"))=0,"",B14*1000/(SUMIFS(Data!$S$2:$S$31,Data!$K$2:$K$31,"<>not applicable")+SUMIFS(Data!$T$2:$T$31,Data!$K$2:$K$31,"<>not applicable")))
A15: Total | B15: =(SUMIFS(Data!$S$2:$S$31,Data!$K$2:$K$31,"<>not applicable")+SUMIFS(Data!$T$2:$T$31,Data!$K$2:$K$31,"<>not applicable"))/1000 | C15: =IF((SUMIFS(Data!$S$2:$S$31,Data!$K$2:$K$31,"<>not applicable")+SUMIFS(Data!$T$2:$T$31,Data!$K$2:$K$31,"<>not applicable"))=0,"",B15*1000/(SUMIFS(Data!$S$2:$S$31,Data!$K$2:$K$31,"<>not applicable")+SUMIFS(Data!$T$2:$T$31,Data!$K$2:$K$31,"<>not applicable")))
A18: THE DETAIL OF EACH CLASS
A20: The two core groups are broken down into subgroups. Please note the Animal core subgroups are not a part of the Protein Tracker methodology but are included voluntarily by Altera.
B22: Protein (t) | C22: Share
A23: Animal core
A24: Red meat | B24: =(SUMIFS(Data!$S$2:$S$31,Data!$K$2:$K$31,"animal_core",Data!$G$2:$G$31,"red_meat")+SUMIFS(Data!$T$2:$T$31,Data!$K$2:$K$31,"animal_core",Data!$G$2:$G$31,"red_meat"))/1000 | C24: =IF((SUMIFS(Data!$S$2:$S$31,Data!$K$2:$K$31,"<>not applicable")+SUMIFS(Data!$T$2:$T$31,Data!$K$2:$K$31,"<>not applicable"))=0,"",B24*1000/(SUMIFS(Data!$S$2:$S$31,Data!$K$2:$K$31,"<>not applicable")+SUMIFS(Data!$T$2:$T$31,Data!$K$2:$K$31,"<>not applicable")))
A25: Poultry | B25: =(SUMIFS(Data!$S$2:$S$31,Data!$K$2:$K$31,"animal_core",Data!$G$2:$G$31,"poultry")+SUMIFS(Data!$T$2:$T$31,Data!$K$2:$K$31,"animal_core",Data!$G$2:$G$31,"poultry"))/1000 | C25: =IF((SUMIFS(Data!$S$2:$S$31,Data!$K$2:$K$31,"<>not applicable")+SUMIFS(Data!$T$2:$T$31,Data!$K$2:$K$31,"<>not applicable"))=0,"",B25*1000/(SUMIFS(Data!$S$2:$S$31,Data!$K$2:$K$31,"<>not applicable")+SUMIFS(Data!$T$2:$T$31,Data!$K$2:$K$31,"<>not applicable")))
A26: Fish and seafood | B26: =(SUMIFS(Data!$S$2:$S$31,Data!$K$2:$K$31,"animal_core",Data!$G$2:$G$31,"seafood")+SUMIFS(Data!$T$2:$T$31,Data!$K$2:$K$31,"animal_core",Data!$G$2:$G$31,"seafood"))/1000 | C26: =IF((SUMIFS(Data!$S$2:$S$31,Data!$K$2:$K$31,"<>not applicable")+SUMIFS(Data!$T$2:$T$31,Data!$K$2:$K$31,"<>not applicable"))=0,"",B26*1000/(SUMIFS(Data!$S$2:$S$31,Data!$K$2:$K$31,"<>not applicable")+SUMIFS(Data!$T$2:$T$31,Data!$K$2:$K$31,"<>not applicable")))
A27: Eggs | B27: =(SUMIFS(Data!$S$2:$S$31,Data!$K$2:$K$31,"animal_core",Data!$G$2:$G$31,"eggs")+SUMIFS(Data!$T$2:$T$31,Data!$K$2:$K$31,"animal_core",Data!$G$2:$G$31,"eggs"))/1000 | C27: =IF((SUMIFS(Data!$S$2:$S$31,Data!$K$2:$K$31,"<>not applicable")+SUMIFS(Data!$T$2:$T$31,Data!$K$2:$K$31,"<>not applicable"))=0,"",B27*1000/(SUMIFS(Data!$S$2:$S$31,Data!$K$2:$K$31,"<>not applicable")+SUMIFS(Data!$T$2:$T$31,Data!$K$2:$K$31,"<>not applicable")))
A28: Other animals (snails) | B28: =(SUMIFS(Data!$S$2:$S$31,Data!$K$2:$K$31,"animal_core",Data!$G$2:$G$31,"other_animal")+SUMIFS(Data!$T$2:$T$31,Data!$K$2:$K$31,"animal_core",Data!$G$2:$G$31,"other_animal"))/1000 | C28: =IF((SUMIFS(Data!$S$2:$S$31,Data!$K$2:$K$31,"<>not applicable")+SUMIFS(Data!$T$2:$T$31,Data!$K$2:$K$31,"<>not applicable"))=0,"",B28*1000/(SUMIFS(Data!$S$2:$S$31,Data!$K$2:$K$31,"<>not applicable")+SUMIFS(Data!$T$2:$T$31,Data!$K$2:$K$31,"<>not applicable")))
A29: Cheese | B29: =(SUMIFS(Data!$S$2:$S$31,Data!$K$2:$K$31,"animal_core",Data!$G$2:$G$31,"dairy_animal",Data!$AC$2:$AC$31,10)+SUMIFS(Data!$T$2:$T$31,Data!$K$2:$K$31,"animal_core",Data!$G$2:$G$31,"dairy_animal",Data!$AC$2:$AC$31,10))/1000 | C29: =IF((SUMIFS(Data!$S$2:$S$31,Data!$K$2:$K$31,"<>not applicable")+SUMIFS(Data!$T$2:$T$31,Data!$K$2:$K$31,"<>not applicable"))=0,"",B29*1000/(SUMIFS(Data!$S$2:$S$31,Data!$K$2:$K$31,"<>not applicable")+SUMIFS(Data!$T$2:$T$31,Data!$K$2:$K$31,"<>not applicable")))
A30: Milk, yoghurts and creams | B30: =(SUMIFS(Data!$S$2:$S$31,Data!$K$2:$K$31,"animal_core",Data!$G$2:$G$31,"dairy_animal",Data!$AC$2:$AC$31,1)+SUMIFS(Data!$T$2:$T$31,Data!$K$2:$K$31,"animal_core",Data!$G$2:$G$31,"dairy_animal",Data!$AC$2:$AC$31,1))/1000 | C30: =IF((SUMIFS(Data!$S$2:$S$31,Data!$K$2:$K$31,"<>not applicable")+SUMIFS(Data!$T$2:$T$31,Data!$K$2:$K$31,"<>not applicable"))=0,"",B30*1000/(SUMIFS(Data!$S$2:$S$31,Data!$K$2:$K$31,"<>not applicable")+SUMIFS(Data!$T$2:$T$31,Data!$K$2:$K$31,"<>not applicable")))
A31: Other | B31: =(SUMIFS(Data!$S$2:$S$31,Data!$K$2:$K$31,"animal_core")+SUMIFS(Data!$T$2:$T$31,Data!$K$2:$K$31,"animal_core"))/1000-SUM(B24:B30) | C31: =IF((SUMIFS(Data!$S$2:$S$31,Data!$K$2:$K$31,"<>not applicable")+SUMIFS(Data!$T$2:$T$31,Data!$K$2:$K$31,"<>not applicable"))=0,"",B31*1000/(SUMIFS(Data!$S$2:$S$31,Data!$K$2:$K$31,"<>not applicable")+SUMIFS(Data!$T$2:$T$31,Data!$K$2:$K$31,"<>not applicable")))
A32: Plant-based core
A33: Pulses | B33: =(SUMIFS(Data!$S$2:$S$31,Data!$K$2:$K$31,"plant_core",Data!$G$2:$G$31,"legumes")+SUMIFS(Data!$T$2:$T$31,Data!$K$2:$K$31,"plant_core",Data!$G$2:$G$31,"legumes"))/1000 | C33: =IF((SUMIFS(Data!$S$2:$S$31,Data!$K$2:$K$31,"<>not applicable")+SUMIFS(Data!$T$2:$T$31,Data!$K$2:$K$31,"<>not applicable"))=0,"",B33*1000/(SUMIFS(Data!$S$2:$S$31,Data!$K$2:$K$31,"<>not applicable")+SUMIFS(Data!$T$2:$T$31,Data!$K$2:$K$31,"<>not applicable")))
A34: Nuts | B34: =(SUMIFS(Data!$S$2:$S$31,Data!$K$2:$K$31,"plant_core",Data!$G$2:$G$31,"nuts")+SUMIFS(Data!$T$2:$T$31,Data!$K$2:$K$31,"plant_core",Data!$G$2:$G$31,"nuts"))/1000 | C34: =IF((SUMIFS(Data!$S$2:$S$31,Data!$K$2:$K$31,"<>not applicable")+SUMIFS(Data!$T$2:$T$31,Data!$K$2:$K$31,"<>not applicable"))=0,"",B34*1000/(SUMIFS(Data!$S$2:$S$31,Data!$K$2:$K$31,"<>not applicable")+SUMIFS(Data!$T$2:$T$31,Data!$K$2:$K$31,"<>not applicable")))
A35: Seeds | B35: =(SUMIFS(Data!$S$2:$S$31,Data!$K$2:$K$31,"plant_core",Data!$G$2:$G$31,"seeds")+SUMIFS(Data!$T$2:$T$31,Data!$K$2:$K$31,"plant_core",Data!$G$2:$G$31,"seeds"))/1000 | C35: =IF((SUMIFS(Data!$S$2:$S$31,Data!$K$2:$K$31,"<>not applicable")+SUMIFS(Data!$T$2:$T$31,Data!$K$2:$K$31,"<>not applicable"))=0,"",B35*1000/(SUMIFS(Data!$S$2:$S$31,Data!$K$2:$K$31,"<>not applicable")+SUMIFS(Data!$T$2:$T$31,Data!$K$2:$K$31,"<>not applicable")))
A36: Plant-based meat alternatives | B36: =(SUMIFS(Data!$S$2:$S$31,Data!$K$2:$K$31,"plant_core",Data!$G$2:$G$31,"meat_egg_seafood_alternatives")+SUMIFS(Data!$T$2:$T$31,Data!$K$2:$K$31,"plant_core",Data!$G$2:$G$31,"meat_egg_seafood_alternatives"))/1000 | C36: =IF((SUMIFS(Data!$S$2:$S$31,Data!$K$2:$K$31,"<>not applicable")+SUMIFS(Data!$T$2:$T$31,Data!$K$2:$K$31,"<>not applicable"))=0,"",B36*1000/(SUMIFS(Data!$S$2:$S$31,Data!$K$2:$K$31,"<>not applicable")+SUMIFS(Data!$T$2:$T$31,Data!$K$2:$K$31,"<>not applicable")))
A37: Tofu, tempeh, seitan | B37: =(SUMIFS(Data!$S$2:$S$31,Data!$K$2:$K$31,"plant_core",Data!$G$2:$G$31,"tofu_tempeh_seitan")+SUMIFS(Data!$T$2:$T$31,Data!$K$2:$K$31,"plant_core",Data!$G$2:$G$31,"tofu_tempeh_seitan"))/1000 | C37: =IF((SUMIFS(Data!$S$2:$S$31,Data!$K$2:$K$31,"<>not applicable")+SUMIFS(Data!$T$2:$T$31,Data!$K$2:$K$31,"<>not applicable"))=0,"",B37*1000/(SUMIFS(Data!$S$2:$S$31,Data!$K$2:$K$31,"<>not applicable")+SUMIFS(Data!$T$2:$T$31,Data!$K$2:$K$31,"<>not applicable")))
A38: Plant-based dairy alternatives | B38: =(SUMIFS(Data!$S$2:$S$31,Data!$K$2:$K$31,"plant_core",Data!$G$2:$G$31,"dairy_alternative_plant")+SUMIFS(Data!$T$2:$T$31,Data!$K$2:$K$31,"plant_core",Data!$G$2:$G$31,"dairy_alternative_plant"))/1000 | C38: =IF((SUMIFS(Data!$S$2:$S$31,Data!$K$2:$K$31,"<>not applicable")+SUMIFS(Data!$T$2:$T$31,Data!$K$2:$K$31,"<>not applicable"))=0,"",B38*1000/(SUMIFS(Data!$S$2:$S$31,Data!$K$2:$K$31,"<>not applicable")+SUMIFS(Data!$T$2:$T$31,Data!$K$2:$K$31,"<>not applicable")))
A39: Other | B39: =(SUMIFS(Data!$S$2:$S$31,Data!$K$2:$K$31,"plant_core")+SUMIFS(Data!$T$2:$T$31,Data!$K$2:$K$31,"plant_core"))/1000-SUM(B33:B38) | C39: =IF((SUMIFS(Data!$S$2:$S$31,Data!$K$2:$K$31,"<>not applicable")+SUMIFS(Data!$T$2:$T$31,Data!$K$2:$K$31,"<>not applicable"))=0,"",B39*1000/(SUMIFS(Data!$S$2:$S$31,Data!$K$2:$K$31,"<>not applicable")+SUMIFS(Data!$T$2:$T$31,Data!$K$2:$K$31,"<>not applicable")))
A40: Total | B40: =(SUMIFS(Data!$S$2:$S$31,Data!$K$2:$K$31,"<>not applicable")+SUMIFS(Data!$T$2:$T$31,Data!$K$2:$K$31,"<>not applicable"))/1000 | C40: =IF((SUMIFS(Data!$S$2:$S$31,Data!$K$2:$K$31,"<>not applicable")+SUMIFS(Data!$T$2:$T$31,Data!$K$2:$K$31,"<>not applicable"))=0,"",B40*1000/(SUMIFS(Data!$S$2:$S$31,Data!$K$2:$K$31,"<>not applicable")+SUMIFS(Data!$T$2:$T$31,Data!$K$2:$K$31,"<>not applicable")))
A43: MASS AND PLANT / ANIMAL SPLIT
A45: Class | B45: Mass (t) | C45: Protein (t) | D45: Plant protein (t) | E45: Animal protein (t) | F45: Plant share | G45: Animal share
A46: Plant core | B46: =SUMIFS(Data!$R$2:$R$31,Data!$K$2:$K$31,"plant_core")/1000 | C46: =D46+E46 | D46: =SUMIFS(Data!$S$2:$S$31,Data!$K$2:$K$31,"plant_core")/1000 | E46: =SUMIFS(Data!$T$2:$T$31,Data!$K$2:$K$31,"plant_core")/1000 | F46: =IF(C46=0,"",D46/C46) | G46: =IF(C46=0,"",E46/C46)
A47: Plant non-core | B47: =SUMIFS(Data!$R$2:$R$31,Data!$K$2:$K$31,"plant_non_core")/1000 | C47: =D47+E47 | D47: =SUMIFS(Data!$S$2:$S$31,Data!$K$2:$K$31,"plant_non_core")/1000 | E47: =SUMIFS(Data!$T$2:$T$31,Data!$K$2:$K$31,"plant_non_core")/1000 | F47: =IF(C47=0,"",D47/C47) | G47: =IF(C47=0,"",E47/C47)
A48: Animal-plant-based composite | B48: =SUMIFS(Data!$R$2:$R$31,Data!$K$2:$K$31,"animal-plant-based composite")/1000 | C48: =D48+E48 | D48: =SUMIFS(Data!$S$2:$S$31,Data!$K$2:$K$31,"animal-plant-based composite")/1000 | E48: =SUMIFS(Data!$T$2:$T$31,Data!$K$2:$K$31,"animal-plant-based composite")/1000 | F48: =IF(C48=0,"",D48/C48) | G48: =IF(C48=0,"",E48/C48)
A49: Animal core | B49: =SUMIFS(Data!$R$2:$R$31,Data!$K$2:$K$31,"animal_core")/1000 | C49: =D49+E49 | D49: =SUMIFS(Data!$S$2:$S$31,Data!$K$2:$K$31,"animal_core")/1000 | E49: =SUMIFS(Data!$T$2:$T$31,Data!$K$2:$K$31,"animal_core")/1000 | F49: =IF(C49=0,"",D49/C49) | G49: =IF(C49=0,"",E49/C49)
A50: Total | B50: =SUM(B46:B49) | C50: =SUM(C46:C49) | D50: =SUM(D46:D49) | E50: =SUM(E46:E49) | F50: =IF(C50=0,"",D50/C50) | G50: =IF(C50=0,"",E50/C50)
A52: Outside the scope
...

Sheet WWF
A1: WWF PLANET-BASED DIETS · REPORT IN APPENDIX D FORMAT
A3: METHODOLOGY | B3: WWF Planet-Based Diets
A4: INPUT DATA | B4: Harbour Market catalogue, 30 products, volumes entered on the Welcome tab
A5: STEP | B5: Step 1 · product level
A7: WHOLE PRODUCTS
B9: Dairy equivalents · Retailer | F9: Product mass · Retailer | I9: Protein · Retailer
B10: Mass (t) | C10: Share | D10: PHD | F10: Mass (t) | G10: Share | I10: Protein (t) | J10: Share
A11: FOOD GROUP 1
A12: Plant-Based | B12: =(SUMIFS(Data!$AD$2:$AD$31,Data!$G$2:$G$31,"legumes") + SUMIFS(Data!$AD$2:$AD$31,Data!$G$2:$G$31,"nuts") + SUMIFS(Data!$AD$2:$AD$31,Data!$G$2:$G$31,"seeds") + SUMIFS(Data!$AD$2:$AD$31,Data!$G$2:$G$31,"meat_egg_seafood_alternatives") + SUMIFS(Data!$AD$2:$AD$31,Data!$G$2:$G$31,"tofu_tempeh_seitan"))/1000 | C12: =IF(SUMIFS(Data!$AD$2:$AD$31,Data!$I$2:$I$31,"No")=0,"",B12*1000/SUMIFS(Data!$AD$2:$AD$31,Data!$I$2:$I$31,"No")) | D12: 0.1 | F12: =(SUMIFS(Data!$R$2:$R$31,Data!$G$2:$G$31,"legumes") + SUMIFS(Data!$R$2:$R$31,Data!$G$2:$G$31,"nuts") + SUMIFS(Data!$R$2:$R$31,Data!$G$2:$G$31,"seeds") + SUMIFS(Data!$R$2:$R$31,Data!$G$2:$G$31,"meat_egg_seafood_alternatives") + SUMIFS(Data!$R$2:$R$31,Data!$G$2:$G$31,"tofu_tempeh_seitan"))/1000 | G12: =IF(SUMIFS(Data!$R$2:$R$31,Data!$I$2:$I$31,"No")=0,"",F12*1000/SUMIFS(Data!$R$2:$R$31,Data!$I$2:$I$31,"No")) | I12: =(SUMIFS(Data!$S$2:$S$31,Data!$G$2:$G$31,"legumes")+SUMIFS(Data!$T$2:$T$31,Data!$G$2:$G$31,"legumes") + SUMIFS(Data!$S$2:$S$31,Data!$G$2:$G$31,"nuts")+SUMIFS(Data!$T$2:$T$31,Data!$G$2:$G$31,"nuts") + SUMIFS(Data!$S$2:$S$31,Data!$G$2:$G$31,"seeds")+SUMIFS(Data!$T$2:$T$31,Data!$G$2:$G$31,"seeds") + SUMIFS(Data!$S$2:$S$31,Data!$G$2:$G$31,"meat_egg_seafood_alternatives")+SUMIFS(Data!$T$2:$T$31,Data!$G$2:$G$31,"meat_egg_seafood_alternatives") + SUMIFS(Data!$S$2:$S$31,Data!$G$2:$G$31,"tofu_tempeh_seitan")+SUMIFS(Data!$T$2:$T$31,Data!$G$2:$G$31,"tofu_tempeh_seitan"))/1000 | J12: =IF((SUMIFS(Data!$S$2:$S$31,Data!$I$2:$I$31,"No")+SUMIFS(Data!$T$2:$T$31,Data!$I$2:$I$31,"No"))=0,"",I12*1000/(SUMIFS(Data!$S$2:$S$31,Data!$I$2:$I$31,"No")+SUMIFS(Data!$T$2:$T$31,Data!$I$2:$I$31,"No")))
A13: Pulses | B13: =(SUMIFS(Data!$AD$2:$AD$31,Data!$G$2:$G$31,"legumes"))/1000 | C13: =IF(SUMIFS(Data!$AD$2:$AD$31,Data!$I$2:$I$31,"No")=0,"",B13*1000/SUMIFS(Data!$AD$2:$AD$31,Data!$I$2:$I$31,"No")) | D13: N/A | F13: =(SUMIFS(Data!$R$2:$R$31,Data!$G$2:$G$31,"legumes"))/1000 | G13: =IF(SUMIFS(Data!$R$2:$R$31,Data!$I$2:$I$31,"No")=0,"",F13*1000/SUMIFS(Data!$R$2:$R$31,Data!$I$2:$I$31,"No")) | I13: =(SUMIFS(Data!$S$2:$S$31,Data!$G$2:$G$31,"legumes")+SUMIFS(Data!$T$2:$T$31,Data!$G$2:$G$31,"legumes"))/1000 | J13: =IF((SUMIFS(Data!$S$2:$S$31,Data!$I$2:$I$31,"No")+SUMIFS(Data!$T$2:$T$31,Data!$I$2:$I$31,"No"))=0,"",I13*1000/(SUMIFS(Data!$S$2:$S$31,Data!$I$2:$I$31,"No")+SUMIFS(Data!$T$2:$T$31,Data!$I$2:$I$31,"No")))
A14: Nuts | B14: =(SUMIFS(Data!$AD$2:$AD$31,Data!$G$2:$G$31,"nuts"))/1000 | C14: =IF(SUMIFS(Data!$AD$2:$AD$31,Data!$I$2:$I$31,"No")=0,"",B14*1000/SUMIFS(Data!$AD$2:$AD$31,Data!$I$2:$I$31,"No")) | D14: N/A | F14: =(SUMIFS(Data!$R$2:$R$31,Data!$G$2:$G$31,"nuts"))/1000 | G14: =IF(SUMIFS(Data!$R$2:$R$31,Data!$I$2:$I$31,"No")=0,"",F14*1000/SUMIFS(Data!$R$2:$R$31,Data!$I$2:$I$31,"No")) | I14: =(SUMIFS(Data!$S$2:$S$31,Data!$G$2:$G$31,"nuts")+SUMIFS(Data!$T$2:$T$31,Data!$G$2:$G$31,"nuts"))/1000 | J14: =IF((SUMIFS(Data!$S$2:$S$31,Data!$I$2:$I$31,"No")+SUMIFS(Data!$T$2:$T$31,Data!$I$2:$I$31,"No"))=0,"",I14*1000/(SUMIFS(Data!$S$2:$S$31,Data!$I$2:$I$31,"No")+SUMIFS(Data!$T$2:$T$31,Data!$I$2:$I$31,"No")))
A15: Seeds | B15: =(SUMIFS(Data!$AD$2:$AD$31,Data!$G$2:$G$31,"seeds"))/1000 | C15: =IF(SUMIFS(Data!$AD$2:$AD$31,Data!$I$2:$I$31,"No")=0,"",B15*1000/SUMIFS(Data!$AD$2:$AD$31,Data!$I$2:$I$31,"No")) | D15: N/A | F15: =(SUMIFS(Data!$R$2:$R$31,Data!$G$2:$G$31,"seeds"))/1000 | G15: =IF(SUMIFS(Data!$R$2:$R$31,Data!$I$2:$I$31,"No")=0,"",F15*1000/SUMIFS(Data!$R$2:$R$31,Data!$I$2:$I$31,"No")) | I15: =(SUMIFS(Data!$S$2:$S$31,Data!$G$2:$G$31,"seeds")+SUMIFS(Data!$T$2:$T$31,Data!$G$2:$G$31,"seeds"))/1000 | J15: =IF((SUMIFS(Data!$S$2:$S$31,Data!$I$2:$I$31,"No")+SUMIFS(Data!$T$2:$T$31,Data!$I$2:$I$31,"No"))=0,"",I15*1000/(SUMIFS(Data!$S$2:$S$31,Data!$I$2:$I$31,"No")+SUMIFS(Data!$T$2:$T$31,Data!$I$2:$I$31,"No")))
A16: Alternative Products | B16: =(SUMIFS(Data!$AD$2:$AD$31,Data!$G$2:$G$31,"meat_egg_seafood_alternatives"))/1000 | C16: =IF(SUMIFS(Data!$AD$2:$AD$31,Data!$I$2:$I$31,"No")=0,"",B16*1000/SUMIFS(Data!$AD$2:$AD$31,Data!$I$2:$I$31,"No")) | D16: N/A | F16: =(SUMIFS(Data!$R$2:$R$31,Data!$G$2:$G$31,"meat_egg_seafood_alternatives"))/1000 | G16: =IF(SUMIFS(Data!$R$2:$R$31,Data!$I$2:$I$31,"No")=0,"",F16*1000/SUMIFS(Data!$R$2:$R$31,Data!$I$2:$I$31,"No")) | I16: =(SUMIFS(Data!$S$2:$S$31,Data!$G$2:$G$31,"meat_egg_seafood_alternatives")+SUMIFS(Data!$T$2:$T$31,Data!$G$2:$G$31,"meat_egg_seafood_alternatives"))/1000 | J16: =IF((SUMIFS(Data!$S$2:$S$31,Data!$I$2:$I$31,"No")+SUMIFS(Data!$T$2:$T$31,Data!$I$2:$I$31,"No"))=0,"",I16*1000/(SUMIFS(Data!$S$2:$S$31,Data!$I$2:$I$31,"No")+SUMIFS(Data!$T$2:$T$31,Data!$I$2:$I$31,"No")))
A17: Tofu, tempeh & seitan | B17: =(SUMIFS(Data!$AD$2:$AD$31,Data!$G$2:$G$31,"tofu_tempeh_seitan"))/1000 | C17: =IF(SUMIFS(Data!$AD$2:$AD$31,Data!$I$2:$I$31,"No")=0,"",B17*1000/SUMIFS(Data!$AD$2:$AD$31,Data!$I$2:$I$31,"No")) | D17: N/A | F17: =(SUMIFS(Data!$R$2:$R$31,Data!$G$2:$G$31,"tofu_tempeh_seitan"))/1000 | G17: =IF(SUMIFS(Data!$R$2:$R$31,Data!$I$2:$I$31,"No")=0,"",F17*1000/SUMIFS(Data!$R$2:$R$31,Data!$I$2:$I$31,"No")) | I17: =(SUMIFS(Data!$S$2:$S$31,Data!$G$2:$G$31,"tofu_tempeh_seitan")+SUMIFS(Data!$T$2:$T$31,Data!$G$2:$G$31,"tofu_tempeh_seitan"))/1000 | J17: =IF((SUMIFS(Data!$S$2:$S$31,Data!$I$2:$I$31,"No")+SUMIFS(Data!$T$2:$T$31,Data!$I$2:$I$31,"No"))=0,"",I17*1000/(SUMIFS(Data!$S$2:$S$31,Data!$I$2:$I$31,"No")+SUMIFS(Data!$T$2:$T$31,Data!$I$2:$I$31,"No")))
A18: Animal-Based | B18: =(SUMIFS(Data!$AD$2:$AD$31,Data!$G$2:$G$31,"red_meat") + SUMIFS(Data!$AD$2:$AD$31,Data!$G$2:$G$31,"poultry") + SUMIFS(Data!$AD$2:$AD$31,Data!$G$2:$G$31,"seafood") + SUMIFS(Data!$AD$2:$AD$31,Data!$G$2:$G$31,"eggs") + SUMIFS(Data!$AD$2:$AD$31,Data!$G$2:$G$31,"other_animal"))/1000 | C18: =IF(SUMIFS(Data!$AD$2:$AD$31,Data!$I$2:$I$31,"No")=0,"",B18*1000/SUMIFS(Data!$AD$2:$AD$31,Data!$I$2:$I$31,"No")) | D18: 0.06 | F18: =(SUMIFS(Data!$R$2:$R$31,Data!$G$2:$G$31,"red_meat") + SUMIFS(Data!$R$2:$R$31,Data!$G$2:$G$31,"poultry") + SUMIFS(Data!$R$2:$R$31,Data!$G$2:$G$31,"seafood") + SUMIFS(Data!$R$2:$R$31,Data!$G$2:$G$31,"eggs") + SUMIFS(Data!$R$2:$R$31,Data!$G$2:$G$31,"other_animal"))/1000 | G18: =IF(SUMIFS(Data!$R$2:$R$31,Data!$I$2:$I$31,"No")=0,"",F18*1000/SUMIFS(Data!$R$2:$R$31,Data!$I$2:$I$31,"No")) | I18: =(SUMIFS(Data!$S$2:$S$31,Data!$G$2:$G$31,"red_meat")+SUMIFS(Data!$T$2:$T$31,Data!$G$2:$G$31,"red_meat") + SUMIFS(Data!$S$2:$S$31,Data!$G$2:$G$31,"poultry")+SUMIFS(Data!$T$2:$T$31,Data!$G$2:$G$31,"poultry") + SUMIFS(Data!$S$2:$S$31,Data!$G$2:$G$31,"seafood")+SUMIFS(Data!$T$2:$T$31,Data!$G$2:$G$31,"seafood") + SUMIFS(Data!$S$2:$S$31,Data!$G$2:$G$31,"eggs")+SUMIFS(Data!$T$2:$T$31,Data!$G$2:$G$31,"eggs") + SUMIFS(Data!$S$2:$S$31,Data!$G$2:$G$31,"other_animal")+SUMIFS(Data!$T$2:$T$31,Data!$G$2:$G$31,"other_animal"))/1000 | J18: =IF((SUMIFS(Data!$S$2:$S$31,Data!$I$2:$I$31,"No")+SUMIFS(Data!$T$2:$T$31,Data!$I$2:$I$31,"No"))=0,"",I18*1000/(SUMIFS(Data!$S$2:$S$31,Data!$I$2:$I$31,"No")+SUMIFS(Data!$T$2:$T$31,Data!$I$2:$I$31,"No")))
A19: Red meat | B19: =(SUMIFS(Data!$AD$2:$AD$31,Data!$G$2:$G$31,"red_meat"))/1000 | C19: =IF(SUMIFS(Data!$AD$2:$AD$31,Data!$I$2:$I$31,"No")=0,"",B19*1000/SUMIFS(Data!$AD$2:$AD$31,Data!$I$2:$I$31,"No")) | D19: N/A | F19: =(SUMIFS(Data!$R$2:$R$31,Data!$G$2:$G$31,"red_meat"))/1000 | G19: =IF(SUMIFS(Data!$R$2:$R$31,Data!$I$2:$I$31,"No")=0,"",F19*1000/SUMIFS(Data!$R$2:$R$31,Data!$I$2:$I$31,"No")) | I19: =(SUMIFS(Data!$S$2:$S$31,Data!$G$2:$G$31,"red_meat")+SUMIFS(Data!$T$2:$T$31,Data!$G$2:$G$31,"red_meat"))/1000 | J19: =IF((SUMIFS(Data!$S$2:$S$31,Data!$I$2:$I$31,"No")+SUMIFS(Data!$T$2:$T$31,Data!$I$2:$I$31,"No"))=0,"",I19*1000/(SUMIFS(Data!$S$2:$S$31,Data!$I$2:$I$31,"No")+SUMIFS(Data!$T$2:$T$31,Data!$I$2:$I$31,"No")))
A20: Poultry | B20: =(SUMIFS(Data!$AD$2:$AD$31,Data!$G$2:$G$31,"poultry"))/1000 | C20: =IF(SUMIFS(Data!$AD$2:$AD$31,Data!$I$2:$I$31,"No")=0,"",B20*1000/SUMIFS(Data!$AD$2:$AD$31,Data!$I$2:$I$31,"No")) | D20: N/A | F20: =(SUMIFS(Data!$R$2:$R$31,Data!$G$2:$G$31,"poultry"))/1000 | G20: =IF(SUMIFS(Data!$R$2:$R$31,Data!$I$2:$I$31,"No")=0,"",F20*1000/SUMIFS(Data!$R$2:$R$31,Data!$I$2:$I$31,"No")) | I20: =(SUMIFS(Data!$S$2:$S$31,Data!$G$2:$G$31,"poultry")+SUMIFS(Data!$T$2:$T$31,Data!$G$2:$G$31,"poultry"))/1000 | J20: =IF((SUMIFS(Data!$S$2:$S$31,Data!$I$2:$I$31,"No")+SUMIFS(Data!$T$2:$T$31,Data!$I$2:$I$31,"No"))=0,"",I20*1000/(SUMIFS(Data!$S$2:$S$31,Data!$I$2:$I$31,"No")+SUMIFS(Data!$T$2:$T$31,Data!$I$2:$I$31,"No")))
A21: Fish & Shellfish | B21: =(SUMIFS(Data!$AD$2:$AD$31,Data!$G$2:$G$31,"seafood"))/1000 | C21: =IF(SUMIFS(Data!$AD$2:$AD$31,Data!$I$2:$I$31,"No")=0,"",B21*1000/SUMIFS(Data!$AD$2:$AD$31,Data!$I$2:$I$31,"No")) | D21: N/A | F21: =(SUMIFS(Data!$R$2:$R$31,Data!$G$2:$G$31,"seafood"))/1000 | G21: =IF(SUMIFS(Data!$R$2:$R$31,Data!$I$2:$I$31,"No")=0,"",F21*1000/SUMIFS(Data!$R$2:$R$31,Data!$I$2:$I$31,"No")) | I21: =(SUMIFS(Data!$S$2:$S$31,Data!$G$2:$G$31,"seafood")+SUMIFS(Data!$T$2:$T$31,Data!$G$2:$G$31,"seafood"))/1000 | J21: =IF((SUMIFS(Data!$S$2:$S$31,Data!$I$2:$I$31,"No")+SUMIFS(Data!$T$2:$T$31,Data!$I$2:$I$31,"No"))=0,"",I21*1000/(SUMIFS(Data!$S$2:$S$31,Data!$I$2:$I$31,"No")+SUMIFS(Data!$T$2:$T$31,Data!$I$2:$I$31,"No")))
A22: Eggs | B22: =(SUMIFS(Data!$AD$2:$AD$31,Data!$G$2:$G$31,"eggs"))/1000 | C22: =IF(SUMIFS(Data!$AD$2:$AD$31,Data!$I$2:$I$31,"No")=0,"",B22*1000/SUMIFS(Data!$AD$2:$AD$31,Data!$I$2:$I$31,"No")) | D22: N/A | F22: =(SUMIFS(Data!$R$2:$R$31,Data!$G$2:$G$31,"eggs"))/1000 | G22: =IF(SUMIFS(Data!$R$2:$R$31,Data!$I$2:$I$31,"No")=0,"",F22*1000/SUMIFS(Data!$R$2:$R$31,Data!$I$2:$I$31,"No")) | I22: =(SUMIFS(Data!$S$2:$S$31,Data!$G$2:$G$31,"eggs")+SUMIFS(Data!$T$2:$T$31,Data!$G$2:$G$31,"eggs"))/1000 | J22: =IF((SUMIFS(Data!$S$2:$S$31,Data!$I$2:$I$31,"No")+SUMIFS(Data!$T$2:$T$31,Data!$I$2:$I$31,"No"))=0,"",I22*1000/(SUMIFS(Data!$S$2:$S$31,Data!$I$2:$I$31,"No")+SUMIFS(Data!$T$2:$T$31,Data!$I$2:$I$31,"No")))
A23: Other (e.g. snails) | B23: =(SUMIFS(Data!$AD$2:$AD$31,Data!$G$2:$G$31,"other_animal"))/1000 | C23: =IF(SUMIFS(Data!$AD$2:$AD$31,Data!$I$2:$I$31,"No")=0,"",B23*1000/SUMIFS(Data!$AD$2:$AD$31,Data!$I$2:$I$31,"No")) | D23: N/A | F23: =(SUMIFS(Data!$R$2:$R$31,Data!$G$2:$G$31,"other_animal"))/1000 | G23: =IF(SUMIFS(Data!$R$2:$R$31,Data!$I$2:$I$31,"No")=0,"",F23*1000/SUMIFS(Data!$R$2:$R$31,Data!$I$2:$I$31,"No")) | I23: =(SUMIFS(Data!$S$2:$S$31,Data!$G$2:$G$31,"other_animal")+SUMIFS(Data!$T$2:$T$31,Data!$G$2:$G$31,"other_animal"))/1000 | J23: =IF((SUMIFS(Data!$S$2:$S$31,Data!$I$2:$I$31,"No")+SUMIFS(Data!$T$2:$T$31,Data!$I$2:$I$31,"No"))=0,"",I23*1000/(SUMIFS(Data!$S$2:$S$31,Data!$I$2:$I$31,"No")+SUMIFS(Data!$T$2:$T$31,Data!$I$2:$I$31,"No")))
A24: FOOD GROUP 2
A25: Dairy | B25: =(SUMIFS(Data!$AD$2:$AD$31,Data!$G$2:$G$31,"dairy_animal"))/1000 | C25: =IF(SUMIFS(Data!$AD$2:$AD$31,Data!$I$2:$I$31,"No")=0,"",B25*1000/SUMIFS(Data!$AD$2:$AD$31,Data!$I$2:$I$31,"No")) | D25: 0.19 | F25: =(SUMIFS(Data!$R$2:$R$31,Data!$G$2:$G$31,"dairy_animal"))/1000 | G25: =IF(SUMIFS(Data!$R$2:$R$31,Data!$I$2:$I$31,"No")=0,"",F25*1000/SUMIFS(Data!$R$2:$R$31,Data!$I$2:$I$31,"No")) | I25: =(SUMIFS(Data!$S$2:$S$31,Data!$G$2:$G$31,"dairy_animal")+SUMIFS(Data!$T$2:$T$31,Data!$G$2:$G$31,"dairy_animal"))/1000 | J25: =IF((SUMIFS(Data!$S$2:$S$31,Data!$I$2:$I$31,"No")+SUMIFS(Data!$T$2:$T$31,Data!$I$2:$I$31,"No"))=0,"",I25*1000/(SUMIFS(Data!$S$2:$S$31,Data!$I$2:$I$31,"No")+SUMIFS(Data!$T$2:$T$31,Data!$I$2:$I$31,"No")))
A26: Dairy Alternatives | B26: =(SUMIFS(Data!$AD$2:$AD$31,Data!$G$2:$G$31,"dairy_alternative_plant"))/1000 | C26: =IF(SUMIFS(Data!$AD$2:$AD$31,Data!$I$2:$I$31,"No")=0,"",B26*1000/SUMIFS(Data!$AD$2:$AD$31,Data!$I$2:$I$31,"No")) | D26: N/A | F26: =(SUMIFS(Data!$R$2:$R$31,Data!$G$2:$G$31,"dairy_alternative_plant"))/1000 | G26: =IF(SUMIFS(Data!$R$2:$R$31,Data!$I$2:$I$31,"No")=0,"",F26*1000/SUMIFS(Data!$R$2:$R$31,Data!$I$2:$I$31,"No")) | I26: =(SUMIFS(Data!$S$2:$S$31,Data!$G$2:$G$31,"dairy_alternative_plant")+SUMIFS(Data!$T$2:$T$31,Data!$G$2:$G$31,"dairy_alternative_plant"))/1000 | J26: =IF((SUMIFS(Data!$S$2:$S$31,Data!$I$2:$I$31,"No")+SUMIFS(Data!$T$2:$T$31,Data!$I$2:$I$31,"No"))=0,"",I26*1000/(SUMIFS(Data!$S$2:$S$31,Data!$I$2:$I$31,"No")+SUMIFS(Data!$T$2:$T$31,Data!$I$2:$I$31,"No")))
A27: FOOD GROUP 3
A28: Animal-Based Fats | B28: =(SUMIFS(Data!$AD$2:$AD$31,Data!$G$2:$G$31,"animal_based_fat"))/1000 | C28: =IF(SUMIFS(Data!$AD$2:$AD$31,Data!$I$2:$I$31,"No")=0,"",B28*1000/SUMIFS(Data!$AD$2:$AD$31,Data!$I$2:$I$31,"No")) | D28: 0.01 | F28: =(SUMIFS(Data!$R$2:$R$31,Data!$G$2:$G$31,"animal_based_fat"))/1000 | G28: =IF(SUMIFS(Data!$R$2:$R$31,Data!$I$2:$I$31,"No")=0,"",F28*1000/SUMIFS(Data!$R$2:$R$31,Data!$I$2:$I$31,"No")) | I28: =(SUMIFS(Data!$S$2:$S$31,Data!$G$2:$G$31,"animal_based_fat")+SUMIFS(Data!$T$2:$T$31,Data!$G$2:$G$31,"animal_based_fat"))/1000 | J28: =IF((SUMIFS(Data!$S$2:$S$31,Data!$I$2:$I$31,"No")+SUMIFS(Data!$T$2:$T$31,Data!$I$2:$I$31,"No"))=0,"",I28*1000/(SUMIFS(Data!$S$2:$S$31,Data!$I$2:$I$31,"No")+SUMIFS(Data!$T$2:$T$31,Data!$I$2:$I$31,"No")))
A29: Plant-Based Fats | B29: =(SUMIFS(Data!$AD$2:$AD$31,Data!$G$2:$G$31,"plant_based_fat"))/1000 | C29: =IF(SUMIFS(Data!$AD$2:$AD$31,Data!$I$2:$I$31,"No")=0,"",B29*1000/SUMIFS(Data!$AD$2:$AD$31,Data!$I$2:$I$31,"No")) | D29: 0.03 | F29: =(SUMIFS(Data!$R$2:$R$31,Data!$G$2:$G$31,"plant_based_fat"))/1000 | G29: =IF(SUMIFS(Data!$R$2:$R$31,Data!$I$2:$I$31,"No")=0,"",F29*1000/SUMIFS(Data!$R$2:$R$31,Data!$I$2:$I$31,"No")) | I29: =(SUMIFS(Data!$S$2:$S$31,Data!$G$2:$G$31,"plant_based_fat")+SUMIFS(Data!$T$2:$T$31,Data!$G$2:$G$31,"plant_based_fat"))/1000 | J29: =IF((SUMIFS(Data!$S$2:$S$31,Data!$I$2:$I$31,"No")+SUMIFS(Data!$T$2:$T$31,Data!$I$2:$I$31,"No"))=0,"",I29*1000/(SUMIFS(Data!$S$2:$S$31,Data!$I$2:$I$31,"No")+SUMIFS(Data!$T$2:$T$31,Data!$I$2:$I$31,"No")))
A30: FOOD GROUP 4
A31: Fruits & Vegetables | B31: =(SUMIFS(Data!$AD$2:$AD$31,Data!$F$2:$F$31,"FG4"))/1000 | C31: =IF(SUMIFS(Data!$AD$2:$AD$31,Data!$I$2:$I$31,"No")=0,"",B31*1000/SUMIFS(Data!$AD$2:$AD$31,Data!$I$2:$I$31,"No")) | D31: 0.38 | F31: =(SUMIFS(Data!$R$2:$R$31,Data!$F$2:$F$31,"FG4"))/1000 | G31: =IF(SUMIFS(Data!$R$2:$R$31,Data!$I$2:$I$31,"No")=0,"",F31*1000/SUMIFS(Data!$R$2:$R$31,Data!$I$2:$I$31,"No")) | I31: =(SUMIFS(Data!$S$2:$S$31,Data!$F$2:$F$31,"FG4")+SUMIFS(Data!$T$2:$T$31,Data!$F$2:$F$31,"FG4"))/1000 | J31: =IF((SUMIFS(Data!$S$2:$S$31,Data!$I$2:$I$31,"No")+SUMIFS(Data!$T$2:$T$31,Data!$I$2:$I$31,"No"))=0,"",I31*1000/(SUMIFS(Data!$S$2:$S$31,Data!$I$2:$I$31,"No")+SUMIFS(Data!$T$2:$T$31,Data!$I$2:$I$31,"No")))
A32: FOOD GROUP 5
A33: Whole Grains | B33: =(SUMIFS(Data!$AD$2:$AD$31,Data!$G$2:$G$31,"whole_grain"))/1000 | C33: =IF(SUMIFS(Data!$AD$2:$AD$31,Data!$I$2:$I$31,"No")=0,"",B33*1000/SUMIFS(Data!$AD$2:$AD$31,Data!$I$2:$I$31,"No")) | D33: 0.18 | F33: =(SUMIFS(Data!$R$2:$R$31,Data!$G$2:$G$31,"whole_grain"))/1000 | G33: =IF(SUMIFS(Data!$R$2:$R$31,Data!$I$2:$I$31,"No")=0,"",F33*1000/SUMIFS(Data!$R$2:$R$31,Data!$I$2:$I$31,"No")) | I33: =(SUMIFS(Data!$S$2:$S$31,Data!$G$2:$G$31,"whole_grain")+SUMIFS(Data!$T$2:$T$31,Data!$G$2:$G$31,"whole_grain"))/1000 | J33: =IF((SUMIFS(Data!$S$2:$S$31,Data!$I$2:$I$31,"No")+SUMIFS(Data!$T$2:$T$31,Data!$I$2:$I$31,"No"))=0,"",I33*1000/(SUMIFS(Data!$S$2:$S$31,Data!$I$2:$I$31,"No")+SUMIFS(Data!$T$2:$T$31,Data!$I$2:$I$31,"No")))
A34: Refined Grains | B34: =(SUMIFS(Data!$AD$2:$AD$31,Data!$G$2:$G$31,"refined_grain"))/1000 | C34: =IF(SUMIFS(Data!$AD$2:$AD$31,Data!$I$2:$I$31,"No")=0,"",B34*1000/SUMIFS(Data!$AD$2:$AD$31,Data!$I$2:$I$31,"No")) | D34: 0 | F34: =(SUMIFS(Data!$R$2:$R$31,Data!$G$2:$G$31,"refined_grain"))/1000 | G34: =IF(SUMIFS(Data!$R$2:$R$31,Data!$I$2:$I$31,"No")=0,"",F34*1000/SUMIFS(Data!$R$2:$R$31,Data!$I$2:$I$31,"No")) | I34: =(SUMIFS(Data!$S$2:$S$31,Data!$G$2:$G$31,"refined_grain")+SUMIFS(Data!$T$2:$T$31,Data!$G$2:$G$31,"refined_grain"))/1000 | J34: =IF((SUMIFS(Data!$S$2:$S$31,Data!$I$2:$I$31,"No")+SUMIFS(Data!$T$2:$T$31,Data!$I$2:$I$31,"No"))=0,"",I34*1000/(SUMIFS(Data!$S$2:$S$31,Data!$I$2:$I$31,"No")+SUMIFS(Data!$T$2:$T$31,Data!$I$2:$I$31,"No")))
A35: FOOD GROUP 6
A36: Starchy Vegetables | B36: =(SUMIFS(Data!$AD$2:$AD$31,Data!$F$2:$F$31,"FG6"))/1000 | C36: =IF(SUMIFS(Data!$AD$2:$AD$31,Data!$I$2:$I$31,"No")=0,"",B36*1000/SUMIFS(Data!$AD$2:$AD$31,Data!$I$2:$I$31,"No")) | D36: 0.04 | F36: =(SUMIFS(Data!$R$2:$R$31,Data!$F$2:$F$31,"FG6"))/1000 | G36: =IF(SUMIFS(Data!$R$2:$R$31,Data!$I$2:$I$31,"No")=0,"",F36*1000/SUMIFS(Data!$R$2:$R$31,Data!$I$2:$I$31,"No")) | I36: =(SUMIFS(Data!$S$2:$S$31,Data!$F$2:$F$31,"FG6")+SUMIFS(Data!$T$2:$T$31,Data!$F$2:$F$31,"FG6"))/1000 | J36: =IF((SUMIFS(Data!$S$2:$S$31,Data!$I$2:$I$31,"No")+SUMIFS(Data!$T$2:$T$31,Data!$I$2:$I$31,"No"))=0,"",I36*1000/(SUMIFS(Data!$S$2:$S$31,Data!$I$2:$I$31,"No")+SUMIFS(Data!$T$2:$T$31,Data!$I$2:$I$31,"No")))
A37: FOOD GROUP 7
A38: Plant-Based | B38: =(SUMIFS(Data!$AD$2:$AD$31,Data!$F$2:$F$31,"FG7",Data!$H$2:$H$31,"plant_based"))/1000 | C38: =IF(SUMIFS(Data!$AD$2:$AD$31,Data!$I$2:$I$31,"No")=0,"",B38*1000/SUMIFS(Data!$AD$2:$AD$31,Data!$I$2:$I$31,"No")) | D38: N/A | F38: =(SUMIFS(Data!$R$2:$R$31,Data!$F$2:$F$31,"FG7",Data!$H$2:$H$31,"plant_based"))/1000 | G38: =IF(SUMIFS(Data!$R$2:$R$31,Data!$I$2:$I$31,"No")=0,"",F38*1000/SUMIFS(Data!$R$2:$R$31,Data!$I$2:$I$31,"No")) | I38: =(SUMIFS(Data!$S$2:$S$31,Data!$F$2:$F$31,"FG7",Data!$H$2:$H$31,"plant_based")+SUMIFS(Data!$T$2:$T$31,Data!$F$2:$F$31,"FG7",Data!$H$2:$H$31,"plant_based"))/1000 | J38: =IF((SUMIFS(Data!$S$2:$S$31,Data!$I$2:$I$31,"No")+SUMIFS(Data!$T$2:$T$31,Data!$I$2:$I$31,"No"))=0,"",I38*1000/(SUMIFS(Data!$S$2:$S$31,Data!$I$2:$I$31,"No")+SUMIFS(Data!$T$2:$T$31,Data!$I$2:$I$31,"No")))
A39: Animal-Based | B39: =(SUMIFS(Data!$AD$2:$AD$31,Data!$F$2:$F$31,"FG7",Data!$H$2:$H$31,"animal_based"))/1000 | C39: =IF(SUMIFS(Data!$AD$2:$AD$31,Data!$I$2:$I$31,"No")=0,"",B39*1000/SUMIFS(Data!$AD$2:$AD$31,Data!$I$2:$I$31,"No")) | D39: N/A | F39: =(SUMIFS(Data!$R$2:$R$31,Data!$F$2:$F$31,"FG7",Data!$H$2:$H$31,"animal_based"))/1000 | G39: =IF(SUMIFS(Data!$R$2:$R$31,Data!$I$2:$I$31,"No")=0,"",F39*1000/SUMIFS(Data!$R$2:$R$31,Data!$I$2:$I$31,"No")) | I39: =(SUMIFS(Data!$S$2:$S$31,Data!$F$2:$F$31,"FG7",Data!$H$2:$H$31,"animal_based")+SUMIFS(Data!$T$2:$T$31,Data!$F$2:$F$31,"FG7",Data!$H$2:$H$31,"animal_based"))/1000 | J39: =IF((SUMIFS(Data!$S$2:$S$31,Data!$I$2:$I$31,"No")+SUMIFS(Data!$T$2:$T$31,Data!$I$2:$I$31,"No"))=0,"",I39*1000/(SUMIFS(Data!$S$2:$S$31,Data!$I$2:$I$31,"No")+SUMIFS(Data!$T$2:$T$31,Data!$I$2:$I$31,"No")))
A40: Origin not determined | B40: =(SUMIFS(Data!$AD$2:$AD$31,Data!$F$2:$F$31,"FG7",Data!$H$2:$H$31,"not applicable"))/1000 | C40: =IF(SUMIFS(Data!$AD$2:$AD$31,Data!$I$2:$I$31,"No")=0,"",B40*1000/SUMIFS(Data!$AD$2:$AD$31,Data!$I$2:$I$31,"No")) | D40: N/A | F40: =(SUMIFS(Data!$R$2:$R$31,Data!$F$2:$F$31,"FG7",Data!$H$2:$H$31,"not applicable"))/1000 | G40: =IF(SUMIFS(Data!$R$2:$R$31,Data!$I$2:$I$31,"No")=0,"",F40*1000/SUMIFS(Data!$R$2:$R$31,Data!$I$2:$I$31,"No")) | I40: =(SUMIFS(Data!$S$2:$S$31,Data!$F$2:$F$31,"FG7",Data!$H$2:$H$31,"not applicable")+SUMIFS(Data!$T$2:$T$31,Data!$F$2:$F$31,"FG7",Data!$H$2:$H$31,"not applicable"))/1000 | J40: =IF((SUMIFS(Data!$S$2:$S$31,Data!$I$2:$I$31,"No")+SUMIFS(Data!$T$2:$T$31,Data!$I$2:$I$31,"No"))=0,"",I40*1000/(SUMIFS(Data!$S$2:$S$31,Data!$I$2:$I$31,"No")+SUMIFS(Data!$T$2:$T$31,Data!$I$2:$I$31,"No")))
A42: FOOD GROUP 1 PROPORTION BY SOURCE
A43: Plant | C43: =IF(((SUMIFS(Data!$AD$2:$AD$31,Data!$G$2:$G$31,"legumes") + SUMIFS(Data!$AD$2:$AD$31,Data!$G$2:$G$31,"nuts") + SUMIFS(Data!$AD$2:$AD$31,Data!$G$2:$G$31,"seeds") + SUMIFS(Data!$AD$2:$AD$31,Data!$G$2:$G$31,"meat_egg_seafood_alternatives") + SUMIFS(Data!$AD$2:$AD$31,Data!$G$2:$G$31,"tofu_tempeh_seitan"))+(SUMIFS(Data!$AD$2:$AD$31,Data!$G$2:$G$31,"red_meat") + SUMIFS(Data!$AD$2:$AD$31,Data!$G$2:$G$31,"poultry") + SUMIFS(Data!$AD$2:$AD$31,Data!$G$2:$G$31,"seafood") + SUMIFS(Data!$AD$2:$AD$31,Data!$G$2:$G$31,"eggs") + SUMIFS(Data!$AD$2:$AD$31,Data!$G$2:$G$31,"other_animal")))=0,"",(SUMIFS(Data!$AD$2:$AD$31,Data!$G$2:$G$31,"legumes") + SUMIFS(Data!$AD$2:$AD$31,Data!$G$2:$G$31,"nuts") + SUMIFS(Data!$AD$2:$AD$31,Data!$G$2:$G$31,"seeds") + SUMIFS(Data!$AD$2:$AD$31,Data!$G$2:$G$31,"meat_egg_seafood_alternatives") + SUMIFS(Data!$AD$2:$AD$31,Data!$G$2:$G$31,"tofu_tempeh_seitan"))/((SUMIFS(Data!$AD$2:$AD$31,Data!$G$2:$G$31,"legumes") + SUMIFS(Data!$AD$2:$AD$31,Data!$G$2:$G$31,"nuts") + SUMIFS(Data!$AD$2:$AD$31,Data!$G$2:$G$31,"seeds") + SUMIFS(Data!$AD$2:$AD$31,Data!$G$2:$G$31,"meat_egg_seafood_alternatives") + SUMIFS(Data!$AD$2:$AD$31,Data!$G$2:$G$31,"tofu_tempeh_seitan"))+(SUMIFS(Data!$AD$2:$AD$31,Data!$G$2:$G$31,"red_meat") + SUMIFS(Data!$AD$2:$AD$31,Data!$G$2:$G$31,"poultry") + SUMIFS(Data!$AD$2:$AD$31,Data!$G$2:$G$31,"seafood") + SUMIFS(Data!$AD$2:$AD$31,Data!$G$2:$G$31,"eggs") + SUMIFS(Data!$AD$2:$AD$31,Data!$G$2:$G$31,"other_animal")))) | D43: 0.6
A44: Animal | C44: =IF(((SUMIFS(Data!$AD$2:$AD$31,Data!$G$2:$G$31,"legumes") + SUMIFS(Data!$AD$2:$AD$31,Data!$G$2:$G$31,"nuts") + SUMIFS(Data!$AD$2:$AD$31,Data!$G$2:$G$31,"seeds") + SUMIFS(Data!$AD$2:$AD$31,Data!$G$2:$G$31,"meat_egg_seafood_alternatives") + SUMIFS(Data!$AD$2:$AD$31,Data!$G$2:$G$31,"tofu_tempeh_seitan"))+(SUMIFS(Data!$AD$2:$AD$31,Data!$G$2:$G$31,"red_meat") + SUMIFS(Data!$AD$2:$AD$31,Data!$G$2:$G$31,"poultry") + SUMIFS(Data!$AD$2:$AD$31,Data!$G$2:$G$31,"seafood") + SUMIFS(Data!$AD$2:$AD$31,Data!$G$2:$G$31,"eggs") + SUMIFS(Data!$AD$2:$AD$31,Data!$G$2:$G$31,"other_animal")))=0,"",(SUMIFS(Data!$AD$2:$AD$31,Data!$G$2:$G$31,"red_meat") + SUMIFS(Data!$AD$2:$AD$31,Data!$G$2:$G$31,"poultry") + SUMIFS(Data!$AD$2:$AD$31,Data!$G$2:$G$31,"seafood") + SUMIFS(Data!$AD$2:$AD$31,Data!$G$2:$G$31,"eggs") + SUMIFS(Data!$AD$2:$AD$31,Data!$G$2:$G$31,"other_animal"))/((SUMIFS(Data!$AD$2:$AD$31,Data!$G$2:$G$31,"legumes") + SUMIFS(Data!$AD$2:$AD$31,Data!$G$2:$G$31,"nuts") + SUMIFS(Data!$AD$2:$AD$31,Data!$G$2:$G$31,"seeds") + SUMIFS(Data!$AD$2:$AD$31,Data!$G$2:$G$31,"meat_egg_seafood_alternatives") + SUMIFS(Data!$AD$2:$AD$31,Data!$G$2:$G$31,"tofu_tempeh_seitan"))+(SUMIFS(Data!$AD$2:$AD$31,Data!$G$2:$G$31,"red_meat") + SUMIFS(Data!$AD$2:$AD$31,Data!$G$2:$G$31,"poultry") + SUMIFS(Data!$AD$2:$AD$31,Data!$G$2:$G$31,"seafood") + SUMIFS(Data!$AD$2:$AD$31,Data!$G$2:$G$31,"eggs") + SUMIFS(Data!$AD$2:$AD$31,Data!$G$2:$G$31,"other_animal")))) | D44: 0.4
...

Sheet By category
A1: BY CATEGORY
A3: WWF sub-groups
A5: WWF subgroup | B5: Mass (t) | C5: Protein (t) | D5: Plant protein (t) | E5: Animal protein (t) | F5: Plant share (weight) | G5: Animal share (weight)
A6: FG1 · red_meat | B6: =SUMIFS(Data!$R$2:$R$31,Data!$G$2:$G$31,"red_meat")/1000 | C6: =D6+E6 | D6: =SUMIFS(Data!$S$2:$S$31,Data!$G$2:$G$31,"red_meat")/1000 | E6: =SUMIFS(Data!$T$2:$T$31,Data!$G$2:$G$31,"red_meat")/1000 | F6: =IF(SUMIFS(Data!$R$2:$R$31,Data!$G$2:$G$31,"red_meat",Data!$H$2:$H$31,"plant_based")+SUMIFS(Data!$R$2:$R$31,Data!$G$2:$G$31,"red_meat",Data!$H$2:$H$31,"animal_based")=0,"",SUMIFS(Data!$R$2:$R$31,Data!$G$2:$G$31,"red_meat",Data!$H$2:$H$31,"plant_based")/(SUMIFS(Data!$R$2:$R$31,Data!$G$2:$G$31,"red_meat",Data!$H$2:$H$31,"plant_based")+SUMIFS(Data!$R$2:$R$31,Data!$G$2:$G$31,"red_meat",Data!$H$2:$H$31,"animal_based"))) | G6: =IF(SUMIFS(Data!$R$2:$R$31,Data!$G$2:$G$31,"red_meat",Data!$H$2:$H$31,"plant_based")+SUMIFS(Data!$R$2:$R$31,Data!$G$2:$G$31,"red_meat",Data!$H$2:$H$31,"animal_based")=0,"",SUMIFS(Data!$R$2:$R$31,Data!$G$2:$G$31,"red_meat",Data!$H$2:$H$31,"animal_based")/(SUMIFS(Data!$R$2:$R$31,Data!$G$2:$G$31,"red_meat",Data!$H$2:$H$31,"plant_based")+SUMIFS(Data!$R$2:$R$31,Data!$G$2:$G$31,"red_meat",Data!$H$2:$H$31,"animal_based")))
A7: FG1 · poultry | B7: =SUMIFS(Data!$R$2:$R$31,Data!$G$2:$G$31,"poultry")/1000 | C7: =D7+E7 | D7: =SUMIFS(Data!$S$2:$S$31,Data!$G$2:$G$31,"poultry")/1000 | E7: =SUMIFS(Data!$T$2:$T$31,Data!$G$2:$G$31,"poultry")/1000 | F7: =IF(SUMIFS(Data!$R$2:$R$31,Data!$G$2:$G$31,"poultry",Data!$H$2:$H$31,"plant_based")+SUMIFS(Data!$R$2:$R$31,Data!$G$2:$G$31,"poultry",Data!$H$2:$H$31,"animal_based")=0,"",SUMIFS(Data!$R$2:$R$31,Data!$G$2:$G$31,"poultry",Data!$H$2:$H$31,"plant_based")/(SUMIFS(Data!$R$2:$R$31,Data!$G$2:$G$31,"poultry",Data!$H$2:$H$31,"plant_based")+SUMIFS(Data!$R$2:$R$31,Data!$G$2:$G$31,"poultry",Data!$H$2:$H$31,"animal_based"))) | G7: =IF(SUMIFS(Data!$R$2:$R$31,Data!$G$2:$G$31,"poultry",Data!$H$2:$H$31,"plant_based")+SUMIFS(Data!$R$2:$R$31,Data!$G$2:$G$31,"poultry",Data!$H$2:$H$31,"animal_based")=0,"",SUMIFS(Data!$R$2:$R$31,Data!$G$2:$G$31,"poultry",Data!$H$2:$H$31,"animal_based")/(SUMIFS(Data!$R$2:$R$31,Data!$G$2:$G$31,"poultry",Data!$H$2:$H$31,"plant_based")+SUMIFS(Data!$R$2:$R$31,Data!$G$2:$G$31,"poultry",Data!$H$2:$H$31,"animal_based")))
A8: FG1 · seafood | B8: =SUMIFS(Data!$R$2:$R$31,Data!$G$2:$G$31,"seafood")/1000 | C8: =D8+E8 | D8: =SUMIFS(Data!$S$2:$S$31,Data!$G$2:$G$31,"seafood")/1000 | E8: =SUMIFS(Data!$T$2:$T$31,Data!$G$2:$G$31,"seafood")/1000 | F8: =IF(SUMIFS(Data!$R$2:$R$31,Data!$G$2:$G$31,"seafood",Data!$H$2:$H$31,"plant_based")+SUMIFS(Data!$R$2:$R$31,Data!$G$2:$G$31,"seafood",Data!$H$2:$H$31,"animal_based")=0,"",SUMIFS(Data!$R$2:$R$31,Data!$G$2:$G$31,"seafood",Data!$H$2:$H$31,"plant_based")/(SUMIFS(Data!$R$2:$R$31,Data!$G$2:$G$31,"seafood",Data!$H$2:$H$31,"plant_based")+SUMIFS(Data!$R$2:$R$31,Data!$G$2:$G$31,"seafood",Data!$H$2:$H$31,"animal_based"))) | G8: =IF(SUMIFS(Data!$R$2:$R$31,Data!$G$2:$G$31,"seafood",Data!$H$2:$H$31,"plant_based")+SUMIFS(Data!$R$2:$R$31,Data!$G$2:$G$31,"seafood",Data!$H$2:$H$31,"animal_based")=0,"",SUMIFS(Data!$R$2:$R$31,Data!$G$2:$G$31,"seafood",Data!$H$2:$H$31,"animal_based")/(SUMIFS(Data!$R$2:$R$31,Data!$G$2:$G$31,"seafood",Data!$H$2:$H$31,"plant_based")+SUMIFS(Data!$R$2:$R$31,Data!$G$2:$G$31,"seafood",Data!$H$2:$H$31,"animal_based")))
A9: FG1 · eggs | B9: =SUMIFS(Data!$R$2:$R$31,Data!$G$2:$G$31,"eggs")/1000 | C9: =D9+E9 | D9: =SUMIFS(Data!$S$2:$S$31,Data!$G$2:$G$31,"eggs")/1000 | E9: =SUMIFS(Data!$T$2:$T$31,Data!$G$2:$G$31,"eggs")/1000 | F9: =IF(SUMIFS(Data!$R$2:$R$31,Data!$G$2:$G$31,"eggs",Data!$H$2:$H$31,"plant_based")+SUMIFS(Data!$R$2:$R$31,Data!$G$2:$G$31,"eggs",Data!$H$2:$H$31,"animal_based")=0,"",SUMIFS(Data!$R$2:$R$31,Data!$G$2:$G$31,"eggs",Data!$H$2:$H$31,"plant_based")/(SUMIFS(Data!$R$2:$R$31,Data!$G$2:$G$31,"eggs",Data!$H$2:$H$31,"plant_based")+SUMIFS(Data!$R$2:$R$31,Data!$G$2:$G$31,"eggs",Data!$H$2:$H$31,"animal_based"))) | G9: =IF(SUMIFS(Data!$R$2:$R$31,Data!$G$2:$G$31,"eggs",Data!$H$2:$H$31,"plant_based")+SUMIFS(Data!$R$2:$R$31,Data!$G$2:$G$31,"eggs",Data!$H$2:$H$31,"animal_based")=0,"",SUMIFS(Data!$R$2:$R$31,Data!$G$2:$G$31,"eggs",Data!$H$2:$H$31,"animal_based")/(SUMIFS(Data!$R$2:$R$31,Data!$G$2:$G$31,"eggs",Data!$H$2:$H$31,"plant_based")+SUMIFS(Data!$R$2:$R$31,Data!$G$2:$G$31,"eggs",Data!$H$2:$H$31,"animal_based")))
A10: FG1 · other_animal | B10: =SUMIFS(Data!$R$2:$R$31,Data!$G$2:$G$31,"other_animal")/1000 | C10: =D10+E10 | D10: =SUMIFS(Data!$S$2:$S$31,Data!$G$2:$G$31,"other_animal")/1000 | E10: =SUMIFS(Data!$T$2:$T$31,Data!$G$2:$G$31,"other_animal")/1000 | F10: =IF(SUMIFS(Data!$R$2:$R$31,Data!$G$2:$G$31,"other_animal",Data!$H$2:$H$31,"plant_based")+SUMIFS(Data!$R$2:$R$31,Data!$G$2:$G$31,"other_animal",Data!$H$2:$H$31,"animal_based")=0,"",SUMIFS(Data!$R$2:$R$31,Data!$G$2:$G$31,"other_animal",Data!$H$2:$H$31,"plant_based")/(SUMIFS(Data!$R$2:$R$31,Data!$G$2:$G$31,"other_animal",Data!$H$2:$H$31,"plant_based")+SUMIFS(Data!$R$2:$R$31,Data!$G$2:$G$31,"other_animal",Data!$H$2:$H$31,"animal_based"))) | G10: =IF(SUMIFS(Data!$R$2:$R$31,Data!$G$2:$G$31,"other_animal",Data!$H$2:$H$31,"plant_based")+SUMIFS(Data!$R$2:$R$31,Data!$G$2:$G$31,"other_animal",Data!$H$2:$H$31,"animal_based")=0,"",SUMIFS(Data!$R$2:$R$31,Data!$G$2:$G$31,"other_animal",Data!$H$2:$H$31,"animal_based")/(SUMIFS(Data!$R$2:$R$31,Data!$G$2:$G$31,"other_animal",Data!$H$2:$H$31,"plant_based")+SUMIFS(Data!$R$2:$R$31,Data!$G$2:$G$31,"other_animal",Data!$H$2:$H$31,"animal_based")))
A11: FG1 · legumes | B11: =SUMIFS(Data!$R$2:$R$31,Data!$G$2:$G$31,"legumes")/1000 | C11: =D11+E11 | D11: =SUMIFS(Data!$S$2:$S$31,Data!$G$2:$G$31,"legumes")/1000 | E11: =SUMIFS(Data!$T$2:$T$31,Data!$G$2:$G$31,"legumes")/1000 | F11: =IF(SUMIFS(Data!$R$2:$R$31,Data!$G$2:$G$31,"legumes",Data!$H$2:$H$31,"plant_based")+SUMIFS(Data!$R$2:$R$31,Data!$G$2:$G$31,"legumes",Data!$H$2:$H$31,"animal_based")=0,"",SUMIFS(Data!$R$2:$R$31,Data!$G$2:$G$31,"legumes",Data!$H$2:$H$31,"plant_based")/(SUMIFS(Data!$R$2:$R$31,Data!$G$2:$G$31,"legumes",Data!$H$2:$H$31,"plant_based")+SUMIFS(Data!$R$2:$R$31,Data!$G$2:$G$31,"legumes",Data!$H$2:$H$31,"animal_based"))) | G11: =IF(SUMIFS(Data!$R$2:$R$31,Data!$G$2:$G$31,"legumes",Data!$H$2:$H$31,"plant_based")+SUMIFS(Data!$R$2:$R$31,Data!$G$2:$G$31,"legumes",Data!$H$2:$H$31,"animal_based")=0,"",SUMIFS(Data!$R$2:$R$31,Data!$G$2:$G$31,"legumes",Data!$H$2:$H$31,"animal_based")/(SUMIFS(Data!$R$2:$R$31,Data!$G$2:$G$31,"legumes",Data!$H$2:$H$31,"plant_based")+SUMIFS(Data!$R$2:$R$31,Data!$G$2:$G$31,"legumes",Data!$H$2:$H$31,"animal_based")))
A12: FG1 · nuts | B12: =SUMIFS(Data!$R$2:$R$31,Data!$G$2:$G$31,"nuts")/1000 | C12: =D12+E12 | D12: =SUMIFS(Data!$S$2:$S$31,Data!$G$2:$G$31,"nuts")/1000 | E12: =SUMIFS(Data!$T$2:$T$31,Data!$G$2:$G$31,"nuts")/1000 | F12: =IF(SUMIFS(Data!$R$2:$R$31,Data!$G$2:$G$31,"nuts",Data!$H$2:$H$31,"plant_based")+SUMIFS(Data!$R$2:$R$31,Data!$G$2:$G$31,"nuts",Data!$H$2:$H$31,"animal_based")=0,"",SUMIFS(Data!$R$2:$R$31,Data!$G$2:$G$31,"nuts",Data!$H$2:$H$31,"plant_based")/(SUMIFS(Data!$R$2:$R$31,Data!$G$2:$G$31,"nuts",Data!$H$2:$H$31,"plant_based")+SUMIFS(Data!$R$2:$R$31,Data!$G$2:$G$31,"nuts",Data!$H$2:$H$31,"animal_based"))) | G12: =IF(SUMIFS(Data!$R$2:$R$31,Data!$G$2:$G$31,"nuts",Data!$H$2:$H$31,"plant_based")+SUMIFS(Data!$R$2:$R$31,Data!$G$2:$G$31,"nuts",Data!$H$2:$H$31,"animal_based")=0,"",SUMIFS(Data!$R$2:$R$31,Data!$G$2:$G$31,"nuts",Data!$H$2:$H$31,"animal_based")/(SUMIFS(Data!$R$2:$R$31,Data!$G$2:$G$31,"nuts",Data!$H$2:$H$31,"plant_based")+SUMIFS(Data!$R$2:$R$31,Data!$G$2:$G$31,"nuts",Data!$H$2:$H$31,"animal_based")))
A13: FG1 · seeds | B13: =SUMIFS(Data!$R$2:$R$31,Data!$G$2:$G$31,"seeds")/1000 | C13: =D13+E13 | D13: =SUMIFS(Data!$S$2:$S$31,Data!$G$2:$G$31,"seeds")/1000 | E13: =SUMIFS(Data!$T$2:$T$31,Data!$G$2:$G$31,"seeds")/1000 | F13: =IF(SUMIFS(Data!$R$2:$R$31,Data!$G$2:$G$31,"seeds",Data!$H$2:$H$31,"plant_based")+SUMIFS(Data!$R$2:$R$31,Data!$G$2:$G$31,"seeds",Data!$H$2:$H$31,"animal_based")=0,"",SUMIFS(Data!$R$2:$R$31,Data!$G$2:$G$31,"seeds",Data!$H$2:$H$31,"plant_based")/(SUMIFS(Data!$R$2:$R$31,Data!$G$2:$G$31,"seeds",Data!$H$2:$H$31,"plant_based")+SUMIFS(Data!$R$2:$R$31,Data!$G$2:$G$31,"seeds",Data!$H$2:$H$31,"animal_based"))) | G13: =IF(SUMIFS(Data!$R$2:$R$31,Data!$G$2:$G$31,"seeds",Data!$H$2:$H$31,"plant_based")+SUMIFS(Data!$R$2:$R$31,Data!$G$2:$G$31,"seeds",Data!$H$2:$H$31,"animal_based")=0,"",SUMIFS(Data!$R$2:$R$31,Data!$G$2:$G$31,"seeds",Data!$H$2:$H$31,"animal_based")/(SUMIFS(Data!$R$2:$R$31,Data!$G$2:$G$31,"seeds",Data!$H$2:$H$31,"plant_based")+SUMIFS(Data!$R$2:$R$31,Data!$G$2:$G$31,"seeds",Data!$H$2:$H$31,"animal_based")))
A14: FG1 · tofu_tempeh_seitan | B14: =SUMIFS(Data!$R$2:$R$31,Data!$G$2:$G$31,"tofu_tempeh_seitan")/1000 | C14: =D14+E14 | D14: =SUMIFS(Data!$S$2:$S$31,Data!$G$2:$G$31,"tofu_tempeh_seitan")/1000 | E14: =SUMIFS(Data!$T$2:$T$31,Data!$G$2:$G$31,"tofu_tempeh_seitan")/1000 | F14: =IF(SUMIFS(Data!$R$2:$R$31,Data!$G$2:$G$31,"tofu_tempeh_seitan",Data!$H$2:$H$31,"plant_based")+SUMIFS(Data!$R$2:$R$31,Data!$G$2:$G$31,"tofu_tempeh_seitan",Data!$H$2:$H$31,"animal_based")=0,"",SUMIFS(Data!$R$2:$R$31,Data!$G$2:$G$31,"tofu_tempeh_seitan",Data!$H$2:$H$31,"plant_based")/(SUMIFS(Data!$R$2:$R$31,Data!$G$2:$G$31,"tofu_tempeh_seitan",Data!$H$2:$H$31,"plant_based")+SUMIFS(Data!$R$2:$R$31,Data!$G$2:$G$31,"tofu_tempeh_seitan",Data!$H$2:$H$31,"animal_based"))) | G14: =IF(SUMIFS(Data!$R$2:$R$31,Data!$G$2:$G$31,"tofu_tempeh_seitan",Data!$H$2:$H$31,"plant_based")+SUMIFS(Data!$R$2:$R$31,Data!$G$2:$G$31,"tofu_tempeh_seitan",Data!$H$2:$H$31,"animal_based")=0,"",SUMIFS(Data!$R$2:$R$31,Data!$G$2:$G$31,"tofu_tempeh_seitan",Data!$H$2:$H$31,"animal_based")/(SUMIFS(Data!$R$2:$R$31,Data!$G$2:$G$31,"tofu_tempeh_seitan",Data!$H$2:$H$31,"plant_based")+SUMIFS(Data!$R$2:$R$31,Data!$G$2:$G$31,"tofu_tempeh_seitan",Data!$H$2:$H$31,"animal_based")))
A15: FG1 · meat_egg_seafood_alternatives | B15: =SUMIFS(Data!$R$2:$R$31,Data!$G$2:$G$31,"meat_egg_seafood_alternatives")/1000 | C15: =D15+E15 | D15: =SUMIFS(Data!$S$2:$S$31,Data!$G$2:$G$31,"meat_egg_seafood_alternatives")/1000 | E15: =SUMIFS(Data!$T$2:$T$31,Data!$G$2:$G$31,"meat_egg_seafood_alternatives")/1000 | F15: =IF(SUMIFS(Data!$R$2:$R$31,Data!$G$2:$G$31,"meat_egg_seafood_alternatives",Data!$H$2:$H$31,"plant_based")+SUMIFS(Data!$R$2:$R$31,Data!$G$2:$G$31,"meat_egg_seafood_alternatives",Data!$H$2:$H$31,"animal_based")=0,"",SUMIFS(Data!$R$2:$R$31,Data!$G$2:$G$31,"meat_egg_seafood_alternatives",Data!$H$2:$H$31,"plant_based")/(SUMIFS(Data!$R$2:$R$31,Data!$G$2:$G$31,"meat_egg_seafood_alternatives",Data!$H$2:$H$31,"plant_based")+SUMIFS(Data!$R$2:$R$31,Data!$G$2:$G$31,"meat_egg_seafood_alternatives",Data!$H$2:$H$31,"animal_based"))) | G15: =IF(SUMIFS(Data!$R$2:$R$31,Data!$G$2:$G$31,"meat_egg_seafood_alternatives",Data!$H$2:$H$31,"plant_based")+SUMIFS(Data!$R$2:$R$31,Data!$G$2:$G$31,"meat_egg_seafood_alternatives",Data!$H$2:$H$31,"animal_based")=0,"",SUMIFS(Data!$R$2:$R$31,Data!$G$2:$G$31,"meat_egg_seafood_alternatives",Data!$H$2:$H$31,"animal_based")/(SUMIFS(Data!$R$2:$R$31,Data!$G$2:$G$31,"meat_egg_seafood_alternatives",Data!$H$2:$H$31,"plant_based")+SUMIFS(Data!$R$2:$R$31,Data!$G$2:$G$31,"meat_egg_seafood_alternatives",Data!$H$2:$H$31,"animal_based")))
A16: FG2 · dairy_animal | B16: =SUMIFS(Data!$R$2:$R$31,Data!$G$2:$G$31,"dairy_animal")/1000 | C16: =D16+E16 | D16: =SUMIFS(Data!$S$2:$S$31,Data!$G$2:$G$31,"dairy_animal")/1000 | E16: =SUMIFS(Data!$T$2:$T$31,Data!$G$2:$G$31,"dairy_animal")/1000 | F16: =IF(SUMIFS(Data!$R$2:$R$31,Data!$G$2:$G$31,"dairy_animal",Data!$H$2:$H$31,"plant_based")+SUMIFS(Data!$R$2:$R$31,Data!$G$2:$G$31,"dairy_animal",Data!$H$2:$H$31,"animal_based")=0,"",SUMIFS(Data!$R$2:$R$31,Data!$G$2:$G$31,"dairy_animal",Data!$H$2:$H$31,"plant_based")/(SUMIFS(Data!$R$2:$R$31,Data!$G$2:$G$31,"dairy_animal",Data!$H$2:$H$31,"plant_based")+SUMIFS(Data!$R$2:$R$31,Data!$G$2:$G$31,"dairy_animal",Data!$H$2:$H$31,"animal_based"))) | G16: =IF(SUMIFS(Data!$R$2:$R$31,Data!$G$2:$G$31,"dairy_animal",Data!$H$2:$H$31,"plant_based")+SUMIFS(Data!$R$2:$R$31,Data!$G$2:$G$31,"dairy_animal",Data!$H$2:$H$31,"animal_based")=0,"",SUMIFS(Data!$R$2:$R$31,Data!$G$2:$G$31,"dairy_animal",Data!$H$2:$H$31,"animal_based")/(SUMIFS(Data!$R$2:$R$31,Data!$G$2:$G$31,"dairy_animal",Data!$H$2:$H$31,"plant_based")+SUMIFS(Data!$R$2:$R$31,Data!$G$2:$G$31,"dairy_animal",Data!$H$2:$H$31,"animal_based")))
A17: FG2 · dairy_alternative_plant | B17: =SUMIFS(Data!$R$2:$R$31,Data!$G$2:$G$31,"dairy_alternative_plant")/1000 | C17: =D17+E17 | D17: =SUMIFS(Data!$S$2:$S$31,Data!$G$2:$G$31,"dairy_alternative_plant")/1000 | E17: =SUMIFS(Data!$T$2:$T$31,Data!$G$2:$G$31,"dairy_alternative_plant")/1000 | F17: =IF(SUMIFS(Data!$R$2:$R$31,Data!$G$2:$G$31,"dairy_alternative_plant",Data!$H$2:$H$31,"plant_based")+SUMIFS(Data!$R$2:$R$31,Data!$G$2:$G$31,"dairy_alternative_plant",Data!$H$2:$H$31,"animal_based")=0,"",SUMIFS(Data!$R$2:$R$31,Data!$G$2:$G$31,"dairy_alternative_plant",Data!$H$2:$H$31,"plant_based")/(SUMIFS(Data!$R$2:$R$31,Data!$G$2:$G$31,"dairy_alternative_plant",Data!$H$2:$H$31,"plant_based")+SUMIFS(Data!$R$2:$R$31,Data!$G$2:$G$31,"dairy_alternative_plant",Data!$H$2:$H$31,"animal_based"))) | G17: =IF(SUMIFS(Data!$R$2:$R$31,Data!$G$2:$G$31,"dairy_alternative_plant",Data!$H$2:$H$31,"plant_based")+SUMIFS(Data!$R$2:$R$31,Data!$G$2:$G$31,"dairy_alternative_plant",Data!$H$2:$H$31,"animal_based")=0,"",SUMIFS(Data!$R$2:$R$31,Data!$G$2:$G$31,"dairy_alternative_plant",Data!$H$2:$H$31,"animal_based")/(SUMIFS(Data!$R$2:$R$31,Data!$G$2:$G$31,"dairy_alternative_plant",Data!$H$2:$H$31,"plant_based")+SUMIFS(Data!$R$2:$R$31,Data!$G$2:$G$31,"dairy_alternative_plant",Data!$H$2:$H$31,"animal_based")))
A18: FG3 · animal_based_fat | B18: =SUMIFS(Data!$R$2:$R$31,Data!$G$2:$G$31,"animal_based_fat")/1000 | C18: =D18+E18 | D18: =SUMIFS(Data!$S$2:$S$31,Data!$G$2:$G$31,"animal_based_fat")/1000 | E18: =SUMIFS(Data!$T$2:$T$31,Data!$G$2:$G$31,"animal_based_fat")/1000 | F18: =IF(SUMIFS(Data!$R$2:$R$31,Data!$G$2:$G$31,"animal_based_fat",Data!$H$2:$H$31,"plant_based")+SUMIFS(Data!$R$2:$R$31,Data!$G$2:$G$31,"animal_based_fat",Data!$H$2:$H$31,"animal_based")=0,"",SUMIFS(Data!$R$2:$R$31,Data!$G$2:$G$31,"animal_based_fat",Data!$H$2:$H$31,"plant_based")/(SUMIFS(Data!$R$2:$R$31,Data!$G$2:$G$31,"animal_based_fat",Data!$H$2:$H$31,"plant_based")+SUMIFS(Data!$R$2:$R$31,Data!$G$2:$G$31,"animal_based_fat",Data!$H$2:$H$31,"animal_based"))) | G18: =IF(SUMIFS(Data!$R$2:$R$31,Data!$G$2:$G$31,"animal_based_fat",Data!$H$2:$H$31,"plant_based")+SUMIFS(Data!$R$2:$R$31,Data!$G$2:$G$31,"animal_based_fat",Data!$H$2:$H$31,"animal_based")=0,"",SUMIFS(Data!$R$2:$R$31,Data!$G$2:$G$31,"animal_based_fat",Data!$H$2:$H$31,"animal_based")/(SUMIFS(Data!$R$2:$R$31,Data!$G$2:$G$31,"animal_based_fat",Data!$H$2:$H$31,"plant_based")+SUMIFS(Data!$R$2:$R$31,Data!$G$2:$G$31,"animal_based_fat",Data!$H$2:$H$31,"animal_based")))
A19: FG3 · plant_based_fat | B19: =SUMIFS(Data!$R$2:$R$31,Data!$G$2:$G$31,"plant_based_fat")/1000 | C19: =D19+E19 | D19: =SUMIFS(Data!$S$2:$S$31,Data!$G$2:$G$31,"plant_based_fat")/1000 | E19: =SUMIFS(Data!$T$2:$T$31,Data!$G$2:$G$31,"plant_based_fat")/1000 | F19: =IF(SUMIFS(Data!$R$2:$R$31,Data!$G$2:$G$31,"plant_based_fat",Data!$H$2:$H$31,"plant_based")+SUMIFS(Data!$R$2:$R$31,Data!$G$2:$G$31,"plant_based_fat",Data!$H$2:$H$31,"animal_based")=0,"",SUMIFS(Data!$R$2:$R$31,Data!$G$2:$G$31,"plant_based_fat",Data!$H$2:$H$31,"plant_based")/(SUMIFS(Data!$R$2:$R$31,Data!$G$2:$G$31,"plant_based_fat",Data!$H$2:$H$31,"plant_based")+SUMIFS(Data!$R$2:$R$31,Data!$G$2:$G$31,"plant_based_fat",Data!$H$2:$H$31,"animal_based"))) | G19: =IF(SUMIFS(Data!$R$2:$R$31,Data!$G$2:$G$31,"plant_based_fat",Data!$H$2:$H$31,"plant_based")+SUMIFS(Data!$R$2:$R$31,Data!$G$2:$G$31,"plant_based_fat",Data!$H$2:$H$31,"animal_based")=0,"",SUMIFS(Data!$R$2:$R$31,Data!$G$2:$G$31,"plant_based_fat",Data!$H$2:$H$31,"animal_based")/(SUMIFS(Data!$R$2:$R$31,Data!$G$2:$G$31,"plant_based_fat",Data!$H$2:$H$31,"plant_based")+SUMIFS(Data!$R$2:$R$31,Data!$G$2:$G$31,"plant_based_fat",Data!$H$2:$H$31,"animal_based")))
A20: FG5 · whole_grain | B20: =SUMIFS(Data!$R$2:$R$31,Data!$G$2:$G$31,"whole_grain")/1000 | C20: =D20+E20 | D20: =SUMIFS(Data!$S$2:$S$31,Data!$G$2:$G$31,"whole_grain")/1000 | E20: =SUMIFS(Data!$T$2:$T$31,Data!$G$2:$G$31,"whole_grain")/1000 | F20: =IF(SUMIFS(Data!$R$2:$R$31,Data!$G$2:$G$31,"whole_grain",Data!$H$2:$H$31,"plant_based")+SUMIFS(Data!$R$2:$R$31,Data!$G$2:$G$31,"whole_grain",Data!$H$2:$H$31,"animal_based")=0,"",SUMIFS(Data!$R$2:$R$31,Data!$G$2:$G$31,"whole_grain",Data!$H$2:$H$31,"plant_based")/(SUMIFS(Data!$R$2:$R$31,Data!$G$2:$G$31,"whole_grain",Data!$H$2:$H$31,"plant_based")+SUMIFS(Data!$R$2:$R$31,Data!$G$2:$G$31,"whole_grain",Data!$H$2:$H$31,"animal_based"))) | G20: =IF(SUMIFS(Data!$R$2:$R$31,Data!$G$2:$G$31,"whole_grain",Data!$H$2:$H$31,"plant_based")+SUMIFS(Data!$R$2:$R$31,Data!$G$2:$G$31,"whole_grain",Data!$H$2:$H$31,"animal_based")=0,"",SUMIFS(Data!$R$2:$R$31,Data!$G$2:$G$31,"whole_grain",Data!$H$2:$H$31,"animal_based")/(SUMIFS(Data!$R$2:$R$31,Data!$G$2:$G$31,"whole_grain",Data!$H$2:$H$31,"plant_based")+SUMIFS(Data!$R$2:$R$31,Data!$G$2:$G$31,"whole_grain",Data!$H$2:$H$31,"animal_based")))
A21: FG5 · refined_grain | B21: =SUMIFS(Data!$R$2:$R$31,Data!$G$2:$G$31,"refined_grain")/1000 | C21: =D21+E21 | D21: =SUMIFS(Data!$S$2:$S$31,Data!$G$2:$G$31,"refined_grain")/1000 | E21: =SUMIFS(Data!$T$2:$T$31,Data!$G$2:$G$31,"refined_grain")/1000 | F21: =IF(SUMIFS(Data!$R$2:$R$31,Data!$G$2:$G$31,"refined_grain",Data!$H$2:$H$31,"plant_based")+SUMIFS(Data!$R$2:$R$31,Data!$G$2:$G$31,"refined_grain",Data!$H$2:$H$31,"animal_based")=0,"",SUMIFS(Data!$R$2:$R$31,Data!$G$2:$G$31,"refined_grain",Data!$H$2:$H$31,"plant_based")/(SUMIFS(Data!$R$2:$R$31,Data!$G$2:$G$31,"refined_grain",Data!$H$2:$H$31,"plant_based")+SUMIFS(Data!$R$2:$R$31,Data!$G$2:$G$31,"refined_grain",Data!$H$2:$H$31,"animal_based"))) | G21: =IF(SUMIFS(Data!$R$2:$R$31,Data!$G$2:$G$31,"refined_grain",Data!$H$2:$H$31,"plant_based")+SUMIFS(Data!$R$2:$R$31,Data!$G$2:$G$31,"refined_grain",Data!$H$2:$H$31,"animal_based")=0,"",SUMIFS(Data!$R$2:$R$31,Data!$G$2:$G$31,"refined_grain",Data!$H$2:$H$31,"animal_based")/(SUMIFS(Data!$R$2:$R$31,Data!$G$2:$G$31,"refined_grain",Data!$H$2:$H$31,"plant_based")+SUMIFS(Data!$R$2:$R$31,Data!$G$2:$G$31,"refined_grain",Data!$H$2:$H$31,"animal_based")))
A23: Food groups FG4, FG6 and FG7 have no subgroup and therefore do not appear above; they are detailed on the WWF tab.
A25: Retailer categories
A27: Category | B27: Mass (t) | C27: Protein (t) | D27: Plant protein (t) | E27: Animal protein (t) | F27: Plant share | G27: Animal share
A28: Pasta | B28: =SUMIFS(Data!$R$2:$R$31,Data!$E$2:$E$31,A28)/1000 | C28: =D28+E28 | D28: =SUMIFS(Data!$S$2:$S$31,Data!$E$2:$E$31,A28)/1000 | E28: =SUMIFS(Data!$T$2:$T$31,Data!$E$2:$E$31,A28)/1000 | F28: =IF(C28=0,"",D28/C28) | G28: =IF(C28=0,"",E28/C28)
A29: Milk | B29: =SUMIFS(Data!$R$2:$R$31,Data!$E$2:$E$31,A29)/1000 | C29: =D29+E29 | D29: =SUMIFS(Data!$S$2:$S$31,Data!$E$2:$E$31,A29)/1000 | E29: =SUMIFS(Data!$T$2:$T$31,Data!$E$2:$E$31,A29)/1000 | F29: =IF(C29=0,"",D29/C29) | G29: =IF(C29=0,"",E29/C29)
A30: Eggs | B30: =SUMIFS(Data!$R$2:$R$31,Data!$E$2:$E$31,A30)/1000 | C30: =D30+E30 | D30: =SUMIFS(Data!$S$2:$S$31,Data!$E$2:$E$31,A30)/1000 | E30: =SUMIFS(Data!$T$2:$T$31,Data!$E$2:$E$31,A30)/1000 | F30: =IF(C30=0,"",D30/C30) | G30: =IF(C30=0,"",E30/C30)
A31: Chicken | B31: =SUMIFS(Data!$R$2:$R$31,Data!$E$2:$E$31,A31)/1000 | C31: =D31+E31 | D31: =SUMIFS(Data!$S$2:$S$31,Data!$E$2:$E$31,A31)/1000 | E31: =SUMIFS(Data!$T$2:$T$31,Data!$E$2:$E$31,A31)/1000 | F31: =IF(C31=0,"",D31/C31) | G31: =IF(C31=0,"",E31/C31)
A32: Minced beef | B32: =SUMIFS(Data!$R$2:$R$31,Data!$E$2:$E$31,A32)/1000 | C32: =D32+E32 | D32: =SUMIFS(Data!$S$2:$S$31,Data!$E$2:$E$31,A32)/1000 | E32: =SUMIFS(Data!$T$2:$T$31,Data!$E$2:$E$31,A32)/1000 | F32: =IF(C32=0,"",D32/C32) | G32: =IF(C32=0,"",E32/C32)
A33: Cooked ham | B33: =SUMIFS(Data!$R$2:$R$31,Data!$E$2:$E$31,A33)/1000 | C33: =D33+E33 | D33: =SUMIFS(Data!$S$2:$S$31,Data!$E$2:$E$31,A33)/1000 | E33: =SUMIFS(Data!$T$2:$T$31,Data!$E$2:$E$31,A33)/1000 | F33: =IF(C33=0,"",D33/C33) | G33: =IF(C33=0,"",E33/C33)
A34: Soft cheese | B34: =SUMIFS(Data!$R$2:$R$31,Data!$E$2:$E$31,A34)/1000 | C34: =D34+E34 | D34: =SUMIFS(Data!$S$2:$S$31,Data!$E$2:$E$31,A34)/1000 | E34: =SUMIFS(Data!$T$2:$T$31,Data!$E$2:$E$31,A34)/1000 | F34: =IF(C34=0,"",D34/C34) | G34: =IF(C34=0,"",E34/C34)
A35: Sandwich bread | B35: =SUMIFS(Data!$R$2:$R$31,Data!$E$2:$E$31,A35)/1000 | C35: =D35+E35 | D35: =SUMIFS(Data!$S$2:$S$31,Data!$E$2:$E$31,A35)/1000 | E35: =SUMIFS(Data!$T$2:$T$31,Data!$E$2:$E$31,A35)/1000 | F35: =IF(C35=0,"",D35/C35) | G35: =IF(C35=0,"",E35/C35)
A36: Pizzas | B36: =SUMIFS(Data!$R$2:$R$31,Data!$E$2:$E$31,A36)/1000 | C36: =D36+E36 | D36: =SUMIFS(Data!$S$2:$S$31,Data!$E$2:$E$31,A36)/1000 | E36: =SUMIFS(Data!$T$2:$T$31,Data!$E$2:$E$31,A36)/1000 | F36: =IF(C36=0,"",D36/C36) | G36: =IF(C36=0,"",E36/C36)
A37: Canned fish | B37: =SUMIFS(Data!$R$2:$R$31,Data!$E$2:$E$31,A37)/1000 | C37: =D37+E37 | D37: =SUMIFS(Data!$S$2:$S$31,Data!$E$2:$E$31,A37)/1000 | E37: =SUMIFS(Data!$T$2:$T$31,Data!$E$2:$E$31,A37)/1000 | F37: =IF(C37=0,"",D37/C37) | G37: =IF(C37=0,"",E37/C37)
A38: Spreads | B38: =SUMIFS(Data!$R$2:$R$31,Data!$E$2:$E$31,A38)/1000 | C38: =D38+E38 | D38: =SUMIFS(Data!$S$2:$S$31,Data!$E$2:$E$31,A38)/1000 | E38: =SUMIFS(Data!$T$2:$T$31,Data!$E$2:$E$31,A38)/1000 | F38: =IF(C38=0,"",D38/C38) | G38: =IF(C38=0,"",E38/C38)
A39: Cereals | B39: =SUMIFS(Data!$R$2:$R$31,Data!$E$2:$E$31,A39)/1000 | C39: =D39+E39 | D39: =SUMIFS(Data!$S$2:$S$31,Data!$E$2:$E$31,A39)/1000 | E39: =SUMIFS(Data!$T$2:$T$31,Data!$E$2:$E$31,A39)/1000 | F39: =IF(C39=0,"",D39/C39) | G39: =IF(C39=0,"",E39/C39)
... A55: Soft drinks | B55: =SUMIFS(Data!$R$2:$R$31,Data!$E$2:$E$31,A55)/1000 | C55: =D55+E55 | D55: =SUMIFS(Data!$S$2:$S$31,Data!$E$2:$E$31,A55)/1000 | E55: =SUMIFS(Data!$T$2:$T$31,Data!$E$2:$E$31,A55)/1000 | F55: =IF(C55=0,"",D55/C55) | G55: =IF(C55=0,"",E55/C55)

Sheet By department
A1: BY DEPARTMENT
A3: Department | B3: Mass (t) | C3: Protein (t) | D3: Plant protein (t) | E3: Animal protein (t) | F3: Plant share | G3: Animal share
A4: Grocery | B4: =SUMIFS(Data!$R$2:$R$31,Data!$D$2:$D$31,A4)/1000 | C4: =D4+E4 | D4: =SUMIFS(Data!$S$2:$S$31,Data!$D$2:$D$31,A4)/1000 | E4: =SUMIFS(Data!$T$2:$T$31,Data!$D$2:$D$31,A4)/1000 | F4: =IF(C4=0,"",D4/C4) | G4: =IF(C4=0,"",E4/C4)
A5: Dairy | B5: =SUMIFS(Data!$R$2:$R$31,Data!$D$2:$D$31,A5)/1000 | C5: =D5+E5 | D5: =SUMIFS(Data!$S$2:$S$31,Data!$D$2:$D$31,A5)/1000 | E5: =SUMIFS(Data!$T$2:$T$31,Data!$D$2:$D$31,A5)/1000 | F5: =IF(C5=0,"",D5/C5) | G5: =IF(C5=0,"",E5/C5)
