Workbook

Sheet Welcome
C1: PROTEIN RATIO Retailer catalogue - example
A5: EXAMPLE - FICTITIOUS DATA
A6: Fifty products, chosen so that every table and every chart in the deliverable is populated. The codes, labels, brands, sales ranks and volumes are invented. The protein contents and the classification are real: that is what this workbook is meant to show.
A8: What this workbook contains | B8: The share of the protein you put on the market that is plant-based, and how it breaks down.
A10: How to use it | B10: Enter your sales volumes in the yellow column, further down this page. All tabs recalculate automatically.
A12: Volumes are pre-filled | B12: An estimate is already in the yellow column so that the workbook shows figures straight away. Replace it with your actual volumes.
A14: ACCURACY | B14: 0.95 | C14: Minimum confidence score of the deliverable, obtained by ensuring that: - The products with the highest volume have been categorised perfectly - Difficult products have been categorised 100% correctly - The categorisation of 500 randomly selected products is above 95%
A19: THE TABS
A20: Protein Tracker | B20: the ratio and the four classes of the GPA methodology
A21: WWF | B21: the seven food groups, whole versus composite, the detail by subgroup
A22: By category | B22: the 60 categories carrying the most protein
A23: By department | B23: the 29 departments
A24: By brand | B24: the 60 brands carrying the most protein
A25: Top and flop | B25: the 50 most plant-based products and the 50 least plant-based
A26: Data | B26: one row per product, 90,000 in total
A30: YOUR SALES VOLUMES - enter them in the yellow column
A31: Sorted by sales rank: item 1 is the one that sells the most.
A32: Sales rank | B32: EAN 13 | C32: Product | D32: Volume sold (kg)
A33: 1 | B33: DEMO000000001 | C33: Out-of-scope product 01 - 9.00 kg | D33: 844378
A34: 2 | B34: DEMO000000002 | C34: Fruit or vegetable 01 - 5.00 kg | D34: 952660
A35: 11 | B35: DEMO000000003 | C35: Refined grain 01 - 1.00 kg | D35: 844378
A36: 26 | B36: DEMO000000004 | C36: Dairy product 01 - 350 g | D36: 844378
A37: 22 | B37: DEMO000000005 | C37: Plant-based fat 01 - 920 g | D37: 457427
A38: 42 | B38: DEMO000000006 | C38: Nuts 01 - 500 g | D38: 142595
A39: 39 | B39: DEMO000000007 | C39: Red meat 01 - 1.00 kg | D39: 131564
A40: 13 | B40: DEMO000000008 | C40: Eggs 01 - 750 g | D40: 829747
A41: 46 | B41: DEMO000000009 | C41: Seeds 01 - 5.00 kg | D41: 7632
A42: 16 | B42: DEMO000000010 | C42: Whole grain 01 - 825 g | D42: 626365
A43: 33 | B43: DEMO000000011 | C43: Legume 01 - 800 g | D43: 217219
A44: 32 | B44: DEMO000000012 | C44: Plant-based dairy alternative 01 - 1.00 kg | D44: 178885
... A82: 27 | B82: DEMO000000050 | C82: Poultry 03 - 1.00 kg | D82: 273420

Sheet Protein Tracker
A1: PROTEIN TRACKER - Green Protein Alliance
A3: Plant share of protein | C3: =IF(SUMIFS(Data!$S$2:$S$51,Data!$K$2:$K$51,"<>not applicable")+SUMIFS(Data!$T$2:$T$51,Data!$K$2:$K$51,"<>not applicable")=0,"",SUMIFS(Data!$S$2:$S$51,Data!$K$2:$K$51,"<>not applicable")/(SUMIFS(Data!$S$2:$S$51,Data!$K$2:$K$51,"<>not applicable")+SUMIFS(Data!$T$2:$T$51,Data!$K$2:$K$51,"<>not applicable"))) -> 0.36297186
A4: across the Protein Tracker scope
A6: Each product falls into one class and only one. The four classes below cover the whole scope.
A8: THE FOUR CLASSES
B10: Protein (t) | C10: Share
A11: Animal core | B11: =(SUMIFS(Data!$S$2:$S$51,Data!$K$2:$K$51,"animal_core")+SUMIFS(Data!$T$2:$T$51,Data!$K$2:$K$51,"animal_core"))/1000 -> 1194.4212 | C11: =IF((SUMIFS(Data!$S$2:$S$51,Data!$K$2:$K$51,"<>not applicable")+SUMIFS(Data!$T$2:$T$51,Data!$K$2:$K$51,"<>not applicable"))=0,"",B11*1000/(SUMIFS(Data!$S$2:$S$51,Data!$K$2:$K$51,"<>not applicable")+SUMIFS(Data!$T$2:$T$51,Data!$K$2:$K$51,"<>not applicable"))) -> 0.60334021
A12: Animal and plant composite | B12: =(SUMIFS(Data!$S$2:$S$51,Data!$K$2:$K$51,"animal-plant-based composite")+SUMIFS(Data!$T$2:$T$51,Data!$K$2:$K$51,"animal-plant-based composite"))/1000 -> 176.77943 | C12: =IF((SUMIFS(Data!$S$2:$S$51,Data!$K$2:$K$51,"<>not applicable")+SUMIFS(Data!$T$2:$T$51,Data!$K$2:$K$51,"<>not applicable"))=0,"",B12*1000/(SUMIFS(Data!$S$2:$S$51,Data!$K$2:$K$51,"<>not applicable")+SUMIFS(Data!$T$2:$T$51,Data!$K$2:$K$51,"<>not applicable"))) -> 0.089296921
A13: Plant-based non-core | B13: =(SUMIFS(Data!$S$2:$S$51,Data!$K$2:$K$51,"plant_non_core")+SUMIFS(Data!$T$2:$T$51,Data!$K$2:$K$51,"plant_non_core"))/1000 -> 526.56781 | C13: =IF((SUMIFS(Data!$S$2:$S$51,Data!$K$2:$K$51,"<>not applicable")+SUMIFS(Data!$T$2:$T$51,Data!$K$2:$K$51,"<>not applicable"))=0,"",B13*1000/(SUMIFS(Data!$S$2:$S$51,Data!$K$2:$K$51,"<>not applicable")+SUMIFS(Data!$T$2:$T$51,Data!$K$2:$K$51,"<>not applicable"))) -> 0.26598617
A14: Plant-based core | B14: =(SUMIFS(Data!$S$2:$S$51,Data!$K$2:$K$51,"plant_core")+SUMIFS(Data!$T$2:$T$51,Data!$K$2:$K$51,"plant_core"))/1000 -> 81.91266 | C14: =IF((SUMIFS(Data!$S$2:$S$51,Data!$K$2:$K$51,"<>not applicable")+SUMIFS(Data!$T$2:$T$51,Data!$K$2:$K$51,"<>not applicable"))=0,"",B14*1000/(SUMIFS(Data!$S$2:$S$51,Data!$K$2:$K$51,"<>not applicable")+SUMIFS(Data!$T$2:$T$51,Data!$K$2:$K$51,"<>not applicable"))) -> 0.041376693
A15: Total | B15: =(SUMIFS(Data!$S$2:$S$51,Data!$K$2:$K$51,"<>not applicable")+SUMIFS(Data!$T$2:$T$51,Data!$K$2:$K$51,"<>not applicable"))/1000 -> 1979.6811 | C15: =IF((SUMIFS(Data!$S$2:$S$51,Data!$K$2:$K$51,"<>not applicable")+SUMIFS(Data!$T$2:$T$51,Data!$K$2:$K$51,"<>not applicable"))=0,"",B15*1000/(SUMIFS(Data!$S$2:$S$51,Data!$K$2:$K$51,"<>not applicable")+SUMIFS(Data!$T$2:$T$51,Data!$K$2:$K$51,"<>not applicable"))) -> 1
A18: THE DETAIL OF EACH CLASS
A20: The two core groups are broken down into subgroups. Please note the Animal core subgroups are not a part of the Protein Tracker methodology but are included voluntarily by Altera.
B22: Protein (t) | C22: Share
A23: Animal core
A24: Red meat | B24: =(SUMIFS(Data!$S$2:$S$51,Data!$K$2:$K$51,"animal_core",Data!$G$2:$G$51,"red_meat")+SUMIFS(Data!$T$2:$T$51,Data!$K$2:$K$51,"animal_core",Data!$G$2:$G$51,"red_meat"))/1000 -> 26.3128 | C24: =IF((SUMIFS(Data!$S$2:$S$51,Data!$K$2:$K$51,"<>not applicable")+SUMIFS(Data!$T$2:$T$51,Data!$K$2:$K$51,"<>not applicable"))=0,"",B24*1000/(SUMIFS(Data!$S$2:$S$51,Data!$K$2:$K$51,"<>not applicable")+SUMIFS(Data!$T$2:$T$51,Data!$K$2:$K$51,"<>not applicable"))) -> 0.013291433
A25: Poultry | B25: =(SUMIFS(Data!$S$2:$S$51,Data!$K$2:$K$51,"animal_core",Data!$G$2:$G$51,"poultry")+SUMIFS(Data!$T$2:$T$51,Data!$K$2:$K$51,"animal_core",Data!$G$2:$G$51,"poultry"))/1000 -> 219.85027 | C25: =IF((SUMIFS(Data!$S$2:$S$51,Data!$K$2:$K$51,"<>not applicable")+SUMIFS(Data!$T$2:$T$51,Data!$K$2:$K$51,"<>not applicable"))=0,"",B25*1000/(SUMIFS(Data!$S$2:$S$51,Data!$K$2:$K$51,"<>not applicable")+SUMIFS(Data!$T$2:$T$51,Data!$K$2:$K$51,"<>not applicable"))) -> 0.11105337
A26: Fish and seafood | B26: =(SUMIFS(Data!$S$2:$S$51,Data!$K$2:$K$51,"animal_core",Data!$G$2:$G$51,"seafood")+SUMIFS(Data!$T$2:$T$51,Data!$K$2:$K$51,"animal_core",Data!$G$2:$G$51,"seafood"))/1000 -> 174.06894 | C26: =IF((SUMIFS(Data!$S$2:$S$51,Data!$K$2:$K$51,"<>not applicable")+SUMIFS(Data!$T$2:$T$51,Data!$K$2:$K$51,"<>not applicable"))=0,"",B26*1000/(SUMIFS(Data!$S$2:$S$51,Data!$K$2:$K$51,"<>not applicable")+SUMIFS(Data!$T$2:$T$51,Data!$K$2:$K$51,"<>not applicable"))) -> 0.087927766
A27: Eggs | B27: =(SUMIFS(Data!$S$2:$S$51,Data!$K$2:$K$51,"animal_core",Data!$G$2:$G$51,"eggs")+SUMIFS(Data!$T$2:$T$51,Data!$K$2:$K$51,"animal_core",Data!$G$2:$G$51,"eggs"))/1000 -> 209.41584 | C27: =IF((SUMIFS(Data!$S$2:$S$51,Data!$K$2:$K$51,"<>not applicable")+SUMIFS(Data!$T$2:$T$51,Data!$K$2:$K$51,"<>not applicable"))=0,"",B27*1000/(SUMIFS(Data!$S$2:$S$51,Data!$K$2:$K$51,"<>not applicable")+SUMIFS(Data!$T$2:$T$51,Data!$K$2:$K$51,"<>not applicable"))) -> 0.10578261
A28: Other animals (snails) | B28: =(SUMIFS(Data!$S$2:$S$51,Data!$K$2:$K$51,"animal_core",Data!$G$2:$G$51,"other_animal")+SUMIFS(Data!$T$2:$T$51,Data!$K$2:$K$51,"animal_core",Data!$G$2:$G$51,"other_animal"))/1000 -> 1.50304 | C28: =IF((SUMIFS(Data!$S$2:$S$51,Data!$K$2:$K$51,"<>not applicable")+SUMIFS(Data!$T$2:$T$51,Data!$K$2:$K$51,"<>not applicable"))=0,"",B28*1000/(SUMIFS(Data!$S$2:$S$51,Data!$K$2:$K$51,"<>not applicable")+SUMIFS(Data!$T$2:$T$51,Data!$K$2:$K$51,"<>not applicable"))) -> 0.00075923338
A29: Cheese | B29: =(SUMIFS(Data!$S$2:$S$51,Data!$K$2:$K$51,"animal_core",Data!$G$2:$G$51,"dairy_animal",Data!$AC$2:$AC$51,10)+SUMIFS(Data!$T$2:$T$51,Data!$K$2:$K$51,"animal_core",Data!$G$2:$G$51,"dairy_animal",Data!$AC$2:$AC$51,10))/1000 -> 152.86693 | C29: =IF((SUMIFS(Data!$S$2:$S$51,Data!$K$2:$K$51,"<>not applicable")+SUMIFS(Data!$T$2:$T$51,Data!$K$2:$K$51,"<>not applicable"))=0,"",B29*1000/(SUMIFS(Data!$S$2:$S$51,Data!$K$2:$K$51,"<>not applicable")+SUMIFS(Data!$T$2:$T$51,Data!$K$2:$K$51,"<>not applicable"))) -> 0.077217953
A30: Milk, yoghurts and creams | B30: =(SUMIFS(Data!$S$2:$S$51,Data!$K$2:$K$51,"animal_core",Data!$G$2:$G$51,"dairy_animal",Data!$AC$2:$AC$51,1)+SUMIFS(Data!$T$2:$T$51,Data!$K$2:$K$51,"animal_core",Data!$G$2:$G$51,"dairy_animal",Data!$AC$2:$AC$51,1))/1000 -> 385.98017 | C30: =IF((SUMIFS(Data!$S$2:$S$51,Data!$K$2:$K$51,"<>not applicable")+SUMIFS(Data!$T$2:$T$51,Data!$K$2:$K$51,"<>not applicable"))=0,"",B30*1000/(SUMIFS(Data!$S$2:$S$51,Data!$K$2:$K$51,"<>not applicable")+SUMIFS(Data!$T$2:$T$51,Data!$K$2:$K$51,"<>not applicable"))) -> 0.19497088
A31: Other | B31: =(SUMIFS(Data!$S$2:$S$51,Data!$K$2:$K$51,"animal_core")+SUMIFS(Data!$T$2:$T$51,Data!$K$2:$K$51,"animal_core"))/1000-SUM(B24:B30) -> 24.423253 | C31: =IF((SUMIFS(Data!$S$2:$S$51,Data!$K$2:$K$51,"<>not applicable")+SUMIFS(Data!$T$2:$T$51,Data!$K$2:$K$51,"<>not applicable"))=0,"",B31*1000/(SUMIFS(Data!$S$2:$S$51,Data!$K$2:$K$51,"<>not applicable")+SUMIFS(Data!$T$2:$T$51,Data!$K$2:$K$51,"<>not applicable"))) -> 0.012336963
A32: Plant-based core
A33: Pulses | B33: =(SUMIFS(Data!$S$2:$S$51,Data!$K$2:$K$51,"plant_core",Data!$G$2:$G$51,"legumes")+SUMIFS(Data!$T$2:$T$51,Data!$K$2:$K$51,"plant_core",Data!$G$2:$G$51,"legumes"))/1000 -> 19.115272 | C33: =IF((SUMIFS(Data!$S$2:$S$51,Data!$K$2:$K$51,"<>not applicable")+SUMIFS(Data!$T$2:$T$51,Data!$K$2:$K$51,"<>not applicable"))=0,"",B33*1000/(SUMIFS(Data!$S$2:$S$51,Data!$K$2:$K$51,"<>not applicable")+SUMIFS(Data!$T$2:$T$51,Data!$K$2:$K$51,"<>not applicable"))) -> 0.0096557327
A34: Nuts | B34: =(SUMIFS(Data!$S$2:$S$51,Data!$K$2:$K$51,"plant_core",Data!$G$2:$G$51,"nuts")+SUMIFS(Data!$T$2:$T$51,Data!$K$2:$K$51,"plant_core",Data!$G$2:$G$51,"nuts"))/1000 -> 36.460974 | C34: =IF((SUMIFS(Data!$S$2:$S$51,Data!$K$2:$K$51,"<>not applicable")+SUMIFS(Data!$T$2:$T$51,Data!$K$2:$K$51,"<>not applicable"))=0,"",B34*1000/(SUMIFS(Data!$S$2:$S$51,Data!$K$2:$K$51,"<>not applicable")+SUMIFS(Data!$T$2:$T$51,Data!$K$2:$K$51,"<>not applicable"))) -> 0.018417599
A35: Seeds | B35: =(SUMIFS(Data!$S$2:$S$51,Data!$K$2:$K$51,"plant_core",Data!$G$2:$G$51,"seeds")+SUMIFS(Data!$T$2:$T$51,Data!$K$2:$K$51,"plant_core",Data!$G$2:$G$51,"seeds"))/1000 -> 11.448 | C35: =IF((SUMIFS(Data!$S$2:$S$51,Data!$K$2:$K$51,"<>not applicable")+SUMIFS(Data!$T$2:$T$51,Data!$K$2:$K$51,"<>not applicable"))=0,"",B35*1000/(SUMIFS(Data!$S$2:$S$51,Data!$K$2:$K$51,"<>not applicable")+SUMIFS(Data!$T$2:$T$51,Data!$K$2:$K$51,"<>not applicable"))) -> 0.0057827494
A36: Plant-based meat alternatives | B36: =(SUMIFS(Data!$S$2:$S$51,Data!$K$2:$K$51,"plant_core",Data!$G$2:$G$51,"meat_egg_seafood_alternatives")+SUMIFS(Data!$T$2:$T$51,Data!$K$2:$K$51,"plant_core",Data!$G$2:$G$51,"meat_egg_seafood_alternatives"))/1000 -> 0 | C36: =IF((SUMIFS(Data!$S$2:$S$51,Data!$K$2:$K$51,"<>not applicable")+SUMIFS(Data!$T$2:$T$51,Data!$K$2:$K$51,"<>not applicable"))=0,"",B36*1000/(SUMIFS(Data!$S$2:$S$51,Data!$K$2:$K$51,"<>not applicable")+SUMIFS(Data!$T$2:$T$51,Data!$K$2:$K$51,"<>not applicable"))) -> 0
A37: Tofu, tempeh, seitan | B37: =(SUMIFS(Data!$S$2:$S$51,Data!$K$2:$K$51,"plant_core",Data!$G$2:$G$51,"tofu_tempeh_seitan")+SUMIFS(Data!$T$2:$T$51,Data!$K$2:$K$51,"plant_core",Data!$G$2:$G$51,"tofu_tempeh_seitan"))/1000 -> 2.366464 | C37: =IF((SUMIFS(Data!$S$2:$S$51,Data!$K$2:$K$51,"<>not applicable")+SUMIFS(Data!$T$2:$T$51,Data!$K$2:$K$51,"<>not applicable"))=0,"",B37*1000/(SUMIFS(Data!$S$2:$S$51,Data!$K$2:$K$51,"<>not applicable")+SUMIFS(Data!$T$2:$T$51,Data!$K$2:$K$51,"<>not applicable"))) -> 0.0011953763
A38: Plant-based dairy alternatives | B38: =(SUMIFS(Data!$S$2:$S$51,Data!$K$2:$K$51,"plant_core",Data!$G$2:$G$51,"dairy_alternative_plant")+SUMIFS(Data!$T$2:$T$51,Data!$K$2:$K$51,"plant_core",Data!$G$2:$G$51,"dairy_alternative_plant"))/1000 -> 12.52195 | C38: =IF((SUMIFS(Data!$S$2:$S$51,Data!$K$2:$K$51,"<>not applicable")+SUMIFS(Data!$T$2:$T$51,Data!$K$2:$K$51,"<>not applicable"))=0,"",B38*1000/(SUMIFS(Data!$S$2:$S$51,Data!$K$2:$K$51,"<>not applicable")+SUMIFS(Data!$T$2:$T$51,Data!$K$2:$K$51,"<>not applicable"))) -> 0.0063252358
A39: Other | B39: =(SUMIFS(Data!$S$2:$S$51,Data!$K$2:$K$51,"plant_core")+SUMIFS(Data!$T$2:$T$51,Data!$K$2:$K$51,"plant_core"))/1000-SUM(B33:B38) -> 0 | C39: =IF((SUMIFS(Data!$S$2:$S$51,Data!$K$2:$K$51,"<>not applicable")+SUMIFS(Data!$T$2:$T$51,Data!$K$2:$K$51,"<>not applicable"))=0,"",B39*1000/(SUMIFS(Data!$S$2:$S$51,Data!$K$2:$K$51,"<>not applicable")+SUMIFS(Data!$T$2:$T$51,Data!$K$2:$K$51,"<>not applicable"))) -> 0
A40: Total | B40: =(SUMIFS(Data!$S$2:$S$51,Data!$K$2:$K$51,"<>not applicable")+SUMIFS(Data!$T$2:$T$51,Data!$K$2:$K$51,"<>not applicable"))/1000 -> 1979.6811 | C40: =IF((SUMIFS(Data!$S$2:$S$51,Data!$K$2:$K$51,"<>not applicable")+SUMIFS(Data!$T$2:$T$51,Data!$K$2:$K$51,"<>not applicable"))=0,"",B40*1000/(SUMIFS(Data!$S$2:$S$51,Data!$K$2:$K$51,"<>not applicable")+SUMIFS(Data!$T$2:$T$51,Data!$K$2:$K$51,"<>not applicable"))) -> 1
A43: MASS AND PLANT / ANIMAL SPLIT
A45: Class | B45: Mass (t) | C45: Protein (t) | D45: Plant protein (t) | E45: Animal protein (t) | F45: Plant share | G45: Animal share
A46: Plant core | B46: =SUMIFS(Data!$R$2:$R$51,Data!$K$2:$K$51,"plant_core")/1000 -> 538.7137 | C46: =D46+E46 -> 81.91266 | D46: =SUMIFS(Data!$S$2:$S$51,Data!$K$2:$K$51,"plant_core")/1000 -> 81.91266 | E46: =SUMIFS(Data!$T$2:$T$51,Data!$K$2:$K$51,"plant_core")/1000 -> 0 | F46: =IF(C46=0,"",D46/C46) -> 1 | G46: =IF(C46=0,"",E46/C46) -> 0
A47: Plant non-core | B47: =SUMIFS(Data!$R$2:$R$51,Data!$K$2:$K$51,"plant_non_core")/1000 -> 23135.603 | C47: =D47+E47 -> 526.56781 | D47: =SUMIFS(Data!$S$2:$S$51,Data!$K$2:$K$51,"plant_non_core")/1000 -> 526.56781 | E47: =SUMIFS(Data!$T$2:$T$51,Data!$K$2:$K$51,"plant_non_core")/1000 -> 0 | F47: =IF(C47=0,"",D47/C47) -> 1 | G47: =IF(C47=0,"",E47/C47) -> 0
A48: Animal-plant-based composite | B48: =SUMIFS(Data!$R$2:$R$51,Data!$K$2:$K$51,"composite")/1000 -> 0 | C48: =D48+E48 -> 0 | D48: =SUMIFS(Data!$S$2:$S$51,Data!$K$2:$K$51,"composite")/1000 -> 0 | E48: =SUMIFS(Data!$T$2:$T$51,Data!$K$2:$K$51,"composite")/1000 -> 0 | F48: =IF(C48=0,"",D48/C48) | G48: =IF(C48=0,"",E48/C48)
A49: Animal core | B49: =SUMIFS(Data!$R$2:$R$51,Data!$K$2:$K$51,"animal_core")/1000 -> 14551.646 | C49: =D49+E49 -> 1194.4212 | D49: =SUMIFS(Data!$S$2:$S$51,Data!$K$2:$K$51,"animal_core")/1000 -> 0 | E49: =SUMIFS(Data!$T$2:$T$51,Data!$K$2:$K$51,"animal_core")/1000 -> 1194.4212 | F49: =IF(C49=0,"",D49/C49) -> 0 | G49: =IF(C49=0,"",E49/C49) -> 1
A50: Total | B50: =SUM(B46:B49) -> 38225.963 | C50: =SUM(C46:C49) -> 1802.9017 | D50: =SUM(D46:D49) -> 608.48047 | E50: =SUM(E46:E49) -> 1194.4212 | F50: =IF(C50=0,"",D50/C50) -> 0.33750063 | G50: =IF(C50=0,"",E50/C50) -> 0.66249937
A52: Outside the scope
...

Sheet WWF
A1: WWF - PLANET-BASED DIETS · REPORT IN APPENDIX D FORMAT
A3: METHODOLOGY | B3: WWF Planet-Based Diets
A4: INPUT DATA | B4: retailer catalogue - example, 50 products, volumes entered on the Welcome tab
A5: STEP | B5: Step 1 - product level
A7: WHOLE PRODUCTS
B9: Dairy equivalents - Retailer | F9: Product mass - Retailer | I9: Protein - Retailer
B10: Mass (t) | C10: Share | D10: PHD | F10: Mass (t) | G10: Share | I10: Protein (t) | J10: Share
A11: FOOD GROUP 1
A12: Plant-Based | B12: =(SUMIFS(Data!$AD$2:$AD$51,Data!$G$2:$G$51,"legumes") + SUMIFS(Data!$AD$2:$AD$51,Data!$G$2:$G$51,"nuts") + SUMIFS(Data!$AD$2:$AD$51,Data!$G$2:$G$51,"seeds") + SUMIFS(Data!$AD$2:$AD$51,Data!$G$2:$G$51,"meat_egg_seafood_alternatives") + SUMIFS(Data!$AD$2:$AD$51,Data!$G$2:$G$51,"tofu_tempeh_seitan"))/1000 -> 379.27659 | C12: =IF(SUMIFS(Data!$AD$2:$AD$51,Data!$I$2:$I$51,"No")=0,"",B12*1000/SUMIFS(Data!$AD$2:$AD$51,Data!$I$2:$I$51,"No")) -> 0.010511999 | D12: 0.1 | F12: =(SUMIFS(Data!$R$2:$R$51,Data!$G$2:$G$51,"legumes") + SUMIFS(Data!$R$2:$R$51,Data!$G$2:$G$51,"nuts") + SUMIFS(Data!$R$2:$R$51,Data!$G$2:$G$51,"seeds") + SUMIFS(Data!$R$2:$R$51,Data!$G$2:$G$51,"meat_egg_seafood_alternatives") + SUMIFS(Data!$R$2:$R$51,Data!$G$2:$G$51,"tofu_tempeh_seitan"))/1000 -> 379.27659 | G12: =IF(SUMIFS(Data!$R$2:$R$51,Data!$I$2:$I$51,"No")=0,"",F12*1000/SUMIFS(Data!$R$2:$R$51,Data!$I$2:$I$51,"No")) -> 0.012240736 | I12: =(SUMIFS(Data!$S$2:$S$51,Data!$G$2:$G$51,"legumes")+SUMIFS(Data!$T$2:$T$51,Data!$G$2:$G$51,"legumes") + SUMIFS(Data!$S$2:$S$51,Data!$G$2:$G$51,"nuts")+SUMIFS(Data!$T$2:$T$51,Data!$G$2:$G$51,"nuts") + SUMIFS(Data!$S$2:$S$51,Data!$G$2:$G$51,"seeds")+SUMIFS(Data!$T$2:$T$51,Data!$G$2:$G$51,"seeds") + SUMIFS(Data!$S$2:$S$51,Data!$G$2:$G$51,"meat_egg_seafood_alternatives")+SUMIFS(Data!$T$2:$T$51,Data!$G$2:$G$51,"meat_egg_seafood_alternatives") + SUMIFS(Data!$S$2:$S$51,Data!$G$2:$G$51,"tofu_tempeh_seitan")+SUMIFS(Data!$T$2:$T$51,Data!$G$2:$G$51,"tofu_tempeh_seitan"))/1000 -> 72.502372 | J12: =IF((SUMIFS(Data!$S$2:$S$51,Data!$I$2:$I$51,"No")+SUMIFS(Data!$T$2:$T$51,Data!$I$2:$I$51,"No"))=0,"",I12*1000/(SUMIFS(Data!$S$2:$S$51,Data!$I$2:$I$51,"No")+SUMIFS(Data!$T$2:$T$51,Data!$I$2:$I$51,"No"))) -> 0.041164281
A13: Pulses | B13: =(SUMIFS(Data!$AD$2:$AD$51,Data!$G$2:$G$51,"legumes"))/1000 -> 173.7752 | C13: =IF(SUMIFS(Data!$AD$2:$AD$51,Data!$I$2:$I$51,"No")=0,"",B13*1000/SUMIFS(Data!$AD$2:$AD$51,Data!$I$2:$I$51,"No")) -> 0.0048163391 | D13: — | F13: =(SUMIFS(Data!$R$2:$R$51,Data!$G$2:$G$51,"legumes"))/1000 -> 173.7752 | G13: =IF(SUMIFS(Data!$R$2:$R$51,Data!$I$2:$I$51,"No")=0,"",F13*1000/SUMIFS(Data!$R$2:$R$51,Data!$I$2:$I$51,"No")) -> 0.0056084041 | I13: =(SUMIFS(Data!$S$2:$S$51,Data!$G$2:$G$51,"legumes")+SUMIFS(Data!$T$2:$T$51,Data!$G$2:$G$51,"legumes"))/1000 -> 19.115272 | J13: =IF((SUMIFS(Data!$S$2:$S$51,Data!$I$2:$I$51,"No")+SUMIFS(Data!$T$2:$T$51,Data!$I$2:$I$51,"No"))=0,"",I13*1000/(SUMIFS(Data!$S$2:$S$51,Data!$I$2:$I$51,"No")+SUMIFS(Data!$T$2:$T$51,Data!$I$2:$I$51,"No"))) -> 0.010852975
A14: Nuts | B14: =(SUMIFS(Data!$AD$2:$AD$51,Data!$G$2:$G$51,"nuts"))/1000 -> 133.1031 | C14: =IF(SUMIFS(Data!$AD$2:$AD$51,Data!$I$2:$I$51,"No")=0,"",B14*1000/SUMIFS(Data!$AD$2:$AD$51,Data!$I$2:$I$51,"No")) -> 0.0036890745 | D14: — | F14: =(SUMIFS(Data!$R$2:$R$51,Data!$G$2:$G$51,"nuts"))/1000 -> 133.1031 | G14: =IF(SUMIFS(Data!$R$2:$R$51,Data!$I$2:$I$51,"No")=0,"",F14*1000/SUMIFS(Data!$R$2:$R$51,Data!$I$2:$I$51,"No")) -> 0.0042957566 | I14: =(SUMIFS(Data!$S$2:$S$51,Data!$G$2:$G$51,"nuts")+SUMIFS(Data!$T$2:$T$51,Data!$G$2:$G$51,"nuts"))/1000 -> 36.460974 | J14: =IF((SUMIFS(Data!$S$2:$S$51,Data!$I$2:$I$51,"No")+SUMIFS(Data!$T$2:$T$51,Data!$I$2:$I$51,"No"))=0,"",I14*1000/(SUMIFS(Data!$S$2:$S$51,Data!$I$2:$I$51,"No")+SUMIFS(Data!$T$2:$T$51,Data!$I$2:$I$51,"No"))) -> 0.02070125
A15: Seeds | B15: =(SUMIFS(Data!$AD$2:$AD$51,Data!$G$2:$G$51,"seeds"))/1000 -> 38.16 | C15: =IF(SUMIFS(Data!$AD$2:$AD$51,Data!$I$2:$I$51,"No")=0,"",B15*1000/SUMIFS(Data!$AD$2:$AD$51,Data!$I$2:$I$51,"No")) -> 0.0010576394 | D15: — | F15: =(SUMIFS(Data!$R$2:$R$51,Data!$G$2:$G$51,"seeds"))/1000 -> 38.16 | G15: =IF(SUMIFS(Data!$R$2:$R$51,Data!$I$2:$I$51,"No")=0,"",F15*1000/SUMIFS(Data!$R$2:$R$51,Data!$I$2:$I$51,"No")) -> 0.0012315722 | I15: =(SUMIFS(Data!$S$2:$S$51,Data!$G$2:$G$51,"seeds")+SUMIFS(Data!$T$2:$T$51,Data!$G$2:$G$51,"seeds"))/1000 -> 11.448 | J15: =IF((SUMIFS(Data!$S$2:$S$51,Data!$I$2:$I$51,"No")+SUMIFS(Data!$T$2:$T$51,Data!$I$2:$I$51,"No"))=0,"",I15*1000/(SUMIFS(Data!$S$2:$S$51,Data!$I$2:$I$51,"No")+SUMIFS(Data!$T$2:$T$51,Data!$I$2:$I$51,"No"))) -> 0.0064997692
A16: Alternative Products | B16: =(SUMIFS(Data!$AD$2:$AD$51,Data!$G$2:$G$51,"meat_egg_seafood_alternatives"))/1000 -> 19.44789 | C16: =IF(SUMIFS(Data!$AD$2:$AD$51,Data!$I$2:$I$51,"No")=0,"",B16*1000/SUMIFS(Data!$AD$2:$AD$51,Data!$I$2:$I$51,"No")) -> 0.00053901611 | D16: — | F16: =(SUMIFS(Data!$R$2:$R$51,Data!$G$2:$G$51,"meat_egg_seafood_alternatives"))/1000 -> 19.44789 | G16: =IF(SUMIFS(Data!$R$2:$R$51,Data!$I$2:$I$51,"No")=0,"",F16*1000/SUMIFS(Data!$R$2:$R$51,Data!$I$2:$I$51,"No")) -> 0.00062765933 | I16: =(SUMIFS(Data!$S$2:$S$51,Data!$G$2:$G$51,"meat_egg_seafood_alternatives")+SUMIFS(Data!$T$2:$T$51,Data!$G$2:$G$51,"meat_egg_seafood_alternatives"))/1000 -> 3.1116624 | J16: =IF((SUMIFS(Data!$S$2:$S$51,Data!$I$2:$I$51,"No")+SUMIFS(Data!$T$2:$T$51,Data!$I$2:$I$51,"No"))=0,"",I16*1000/(SUMIFS(Data!$S$2:$S$51,Data!$I$2:$I$51,"No")+SUMIFS(Data!$T$2:$T$51,Data!$I$2:$I$51,"No"))) -> 0.0017666918
A17: Tofu, tempeh & seitan | B17: =(SUMIFS(Data!$AD$2:$AD$51,Data!$G$2:$G$51,"tofu_tempeh_seitan"))/1000 -> 14.7904 | C17: =IF(SUMIFS(Data!$AD$2:$AD$51,Data!$I$2:$I$51,"No")=0,"",B17*1000/SUMIFS(Data!$AD$2:$AD$51,Data!$I$2:$I$51,"No")) -> 0.0004099295 | D17: — | F17: =(SUMIFS(Data!$R$2:$R$51,Data!$G$2:$G$51,"tofu_tempeh_seitan"))/1000 -> 14.7904 | G17: =IF(SUMIFS(Data!$R$2:$R$51,Data!$I$2:$I$51,"No")=0,"",F17*1000/SUMIFS(Data!$R$2:$R$51,Data!$I$2:$I$51,"No")) -> 0.00047734395 | I17: =(SUMIFS(Data!$S$2:$S$51,Data!$G$2:$G$51,"tofu_tempeh_seitan")+SUMIFS(Data!$T$2:$T$51,Data!$G$2:$G$51,"tofu_tempeh_seitan"))/1000 -> 2.366464 | J17: =IF((SUMIFS(Data!$S$2:$S$51,Data!$I$2:$I$51,"No")+SUMIFS(Data!$T$2:$T$51,Data!$I$2:$I$51,"No"))=0,"",I17*1000/(SUMIFS(Data!$S$2:$S$51,Data!$I$2:$I$51,"No")+SUMIFS(Data!$T$2:$T$51,Data!$I$2:$I$51,"No"))) -> 0.0013435945
A18: Animal-Based | B18: =(SUMIFS(Data!$AD$2:$AD$51,Data!$G$2:$G$51,"red_meat") + SUMIFS(Data!$AD$2:$AD$51,Data!$G$2:$G$51,"poultry") + SUMIFS(Data!$AD$2:$AD$51,Data!$G$2:$G$51,"seafood") + SUMIFS(Data!$AD$2:$AD$51,Data!$G$2:$G$51,"eggs") + SUMIFS(Data!$AD$2:$AD$51,Data!$G$2:$G$51,"other_animal"))/1000 -> 3389.8151 | C18: =IF(SUMIFS(Data!$AD$2:$AD$51,Data!$I$2:$I$51,"No")=0,"",B18*1000/SUMIFS(Data!$AD$2:$AD$51,Data!$I$2:$I$51,"No")) -> 0.093951834 | D18: 0.06 | F18: =(SUMIFS(Data!$R$2:$R$51,Data!$G$2:$G$51,"red_meat") + SUMIFS(Data!$R$2:$R$51,Data!$G$2:$G$51,"poultry") + SUMIFS(Data!$R$2:$R$51,Data!$G$2:$G$51,"seafood") + SUMIFS(Data!$R$2:$R$51,Data!$G$2:$G$51,"eggs") + SUMIFS(Data!$R$2:$R$51,Data!$G$2:$G$51,"other_animal"))/1000 -> 3389.8151 | G18: =IF(SUMIFS(Data!$R$2:$R$51,Data!$I$2:$I$51,"No")=0,"",F18*1000/SUMIFS(Data!$R$2:$R$51,Data!$I$2:$I$51,"No")) -> 0.10940256 | I18: =(SUMIFS(Data!$S$2:$S$51,Data!$G$2:$G$51,"red_meat")+SUMIFS(Data!$T$2:$T$51,Data!$G$2:$G$51,"red_meat") + SUMIFS(Data!$S$2:$S$51,Data!$G$2:$G$51,"poultry")+SUMIFS(Data!$T$2:$T$51,Data!$G$2:$G$51,"poultry") + SUMIFS(Data!$S$2:$S$51,Data!$G$2:$G$51,"seafood")+SUMIFS(Data!$T$2:$T$51,Data!$G$2:$G$51,"seafood") + SUMIFS(Data!$S$2:$S$51,Data!$G$2:$G$51,"eggs")+SUMIFS(Data!$T$2:$T$51,Data!$G$2:$G$51,"eggs") + SUMIFS(Data!$S$2:$S$51,Data!$G$2:$G$51,"other_animal")+SUMIFS(Data!$T$2:$T$51,Data!$G$2:$G$51,"other_animal"))/1000 -> 631.1509 | J18: =IF((SUMIFS(Data!$S$2:$S$51,Data!$I$2:$I$51,"No")+SUMIFS(Data!$T$2:$T$51,Data!$I$2:$I$51,"No"))=0,"",I18*1000/(SUMIFS(Data!$S$2:$S$51,Data!$I$2:$I$51,"No")+SUMIFS(Data!$T$2:$T$51,Data!$I$2:$I$51,"No"))) -> 0.35834514
A19: Red meat | B19: =(SUMIFS(Data!$AD$2:$AD$51,Data!$G$2:$G$51,"red_meat"))/1000 -> 131.564 | C19: =IF(SUMIFS(Data!$AD$2:$AD$51,Data!$I$2:$I$51,"No")=0,"",B19*1000/SUMIFS(Data!$AD$2:$AD$51,Data!$I$2:$I$51,"No")) -> 0.0036464169 | D19: — | F19: =(SUMIFS(Data!$R$2:$R$51,Data!$G$2:$G$51,"red_meat"))/1000 -> 131.564 | G19: =IF(SUMIFS(Data!$R$2:$R$51,Data!$I$2:$I$51,"No")=0,"",F19*1000/SUMIFS(Data!$R$2:$R$51,Data!$I$2:$I$51,"No")) -> 0.0042460839 | I19: =(SUMIFS(Data!$S$2:$S$51,Data!$G$2:$G$51,"red_meat")+SUMIFS(Data!$T$2:$T$51,Data!$G$2:$G$51,"red_meat"))/1000 -> 26.3128 | J19: =IF((SUMIFS(Data!$S$2:$S$51,Data!$I$2:$I$51,"No")+SUMIFS(Data!$T$2:$T$51,Data!$I$2:$I$51,"No"))=0,"",I19*1000/(SUMIFS(Data!$S$2:$S$51,Data!$I$2:$I$51,"No")+SUMIFS(Data!$T$2:$T$51,Data!$I$2:$I$51,"No"))) -> 0.014939476
A20: Poultry | B20: =(SUMIFS(Data!$AD$2:$AD$51,Data!$G$2:$G$51,"poultry"))/1000 -> 1040.133 | C20: =IF(SUMIFS(Data!$AD$2:$AD$51,Data!$I$2:$I$51,"No")=0,"",B20*1000/SUMIFS(Data!$AD$2:$AD$51,Data!$I$2:$I$51,"No")) -> 0.02882824 | D20: — | F20: =(SUMIFS(Data!$R$2:$R$51,Data!$G$2:$G$51,"poultry"))/1000 -> 1040.133 | G20: =IF(SUMIFS(Data!$R$2:$R$51,Data!$I$2:$I$51,"No")=0,"",F20*1000/SUMIFS(Data!$R$2:$R$51,Data!$I$2:$I$51,"No")) -> 0.033569152 | I20: =(SUMIFS(Data!$S$2:$S$51,Data!$G$2:$G$51,"poultry")+SUMIFS(Data!$T$2:$T$51,Data!$G$2:$G$51,"poultry"))/1000 -> 219.85027 | J20: =IF((SUMIFS(Data!$S$2:$S$51,Data!$I$2:$I$51,"No")+SUMIFS(Data!$T$2:$T$51,Data!$I$2:$I$51,"No"))=0,"",I20*1000/(SUMIFS(Data!$S$2:$S$51,Data!$I$2:$I$51,"No")+SUMIFS(Data!$T$2:$T$51,Data!$I$2:$I$51,"No"))) -> 0.1248232
A21: Fish & Shellfish | B21: =(SUMIFS(Data!$AD$2:$AD$51,Data!$G$2:$G$51,"seafood"))/1000 -> 774.237 | C21: =IF(SUMIFS(Data!$AD$2:$AD$51,Data!$I$2:$I$51,"No")=0,"",B21*1000/SUMIFS(Data!$AD$2:$AD$51,Data!$I$2:$I$51,"No")) -> 0.021458689 | D21: — | F21: =(SUMIFS(Data!$R$2:$R$51,Data!$G$2:$G$51,"seafood"))/1000 -> 774.237 | G21: =IF(SUMIFS(Data!$R$2:$R$51,Data!$I$2:$I$51,"No")=0,"",F21*1000/SUMIFS(Data!$R$2:$R$51,Data!$I$2:$I$51,"No")) -> 0.02498765 | I21: =(SUMIFS(Data!$S$2:$S$51,Data!$G$2:$G$51,"seafood")+SUMIFS(Data!$T$2:$T$51,Data!$G$2:$G$51,"seafood"))/1000 -> 174.06894 | J21: =IF((SUMIFS(Data!$S$2:$S$51,Data!$I$2:$I$51,"No")+SUMIFS(Data!$T$2:$T$51,Data!$I$2:$I$51,"No"))=0,"",I21*1000/(SUMIFS(Data!$S$2:$S$51,Data!$I$2:$I$51,"No")+SUMIFS(Data!$T$2:$T$51,Data!$I$2:$I$51,"No"))) -> 0.098830183
A22: Eggs | B22: =(SUMIFS(Data!$AD$2:$AD$51,Data!$G$2:$G$51,"eggs"))/1000 -> 1434.4871 | C22: =IF(SUMIFS(Data!$AD$2:$AD$51,Data!$I$2:$I$51,"No")=0,"",B22*1000/SUMIFS(Data!$AD$2:$AD$51,Data!$I$2:$I$51,"No")) -> 0.039758125 | D22: — | F22: =(SUMIFS(Data!$R$2:$R$51,Data!$G$2:$G$51,"eggs"))/1000 -> 1434.4871 | G22: =IF(SUMIFS(Data!$R$2:$R$51,Data!$I$2:$I$51,"No")=0,"",F22*1000/SUMIFS(Data!$R$2:$R$51,Data!$I$2:$I$51,"No")) -> 0.046296497 | I22: =(SUMIFS(Data!$S$2:$S$51,Data!$G$2:$G$51,"eggs")+SUMIFS(Data!$T$2:$T$51,Data!$G$2:$G$51,"eggs"))/1000 -> 209.41584 | J22: =IF((SUMIFS(Data!$S$2:$S$51,Data!$I$2:$I$51,"No")+SUMIFS(Data!$T$2:$T$51,Data!$I$2:$I$51,"No"))=0,"",I22*1000/(SUMIFS(Data!$S$2:$S$51,Data!$I$2:$I$51,"No")+SUMIFS(Data!$T$2:$T$51,Data!$I$2:$I$51,"No"))) -> 0.1188989
A23: Other (e.g. snails) | B23: =(SUMIFS(Data!$AD$2:$AD$51,Data!$G$2:$G$51,"other_animal"))/1000 -> 9.394 | C23: =IF(SUMIFS(Data!$AD$2:$AD$51,Data!$I$2:$I$51,"No")=0,"",B23*1000/SUMIFS(Data!$AD$2:$AD$51,Data!$I$2:$I$51,"No")) -> 0.00026036333 | D23: — | F23: =(SUMIFS(Data!$R$2:$R$51,Data!$G$2:$G$51,"other_animal"))/1000 -> 9.394 | G23: =IF(SUMIFS(Data!$R$2:$R$51,Data!$I$2:$I$51,"No")=0,"",F23*1000/SUMIFS(Data!$R$2:$R$51,Data!$I$2:$I$51,"No")) -> 0.00030318105 | I23: =(SUMIFS(Data!$S$2:$S$51,Data!$G$2:$G$51,"other_animal")+SUMIFS(Data!$T$2:$T$51,Data!$G$2:$G$51,"other_animal"))/1000 -> 1.50304 | J23: =IF((SUMIFS(Data!$S$2:$S$51,Data!$I$2:$I$51,"No")+SUMIFS(Data!$T$2:$T$51,Data!$I$2:$I$51,"No"))=0,"",I23*1000/(SUMIFS(Data!$S$2:$S$51,Data!$I$2:$I$51,"No")+SUMIFS(Data!$T$2:$T$51,Data!$I$2:$I$51,"No"))) -> 0.00085337291
A24: FOOD GROUP 2
A25: Dairy | B25: =(SUMIFS(Data!$AD$2:$AD$51,Data!$G$2:$G$51,"dairy_animal"))/1000 -> 15964.03 | C25: =IF(SUMIFS(Data!$AD$2:$AD$51,Data!$I$2:$I$51,"No")=0,"",B25*1000/SUMIFS(Data!$AD$2:$AD$51,Data!$I$2:$I$51,"No")) -> 0.44245774 | D25: 0.19 | F25: =(SUMIFS(Data!$R$2:$R$51,Data!$G$2:$G$51,"dairy_animal"))/1000 -> 10868.466 | G25: =IF(SUMIFS(Data!$R$2:$R$51,Data!$I$2:$I$51,"No")=0,"",F25*1000/SUMIFS(Data!$R$2:$R$51,Data!$I$2:$I$51,"No")) -> 0.35076782 | I25: =(SUMIFS(Data!$S$2:$S$51,Data!$G$2:$G$51,"dairy_animal")+SUMIFS(Data!$T$2:$T$51,Data!$G$2:$G$51,"dairy_animal"))/1000 -> 538.8471 | J25: =IF((SUMIFS(Data!$S$2:$S$51,Data!$I$2:$I$51,"No")+SUMIFS(Data!$T$2:$T$51,Data!$I$2:$I$51,"No"))=0,"",I25*1000/(SUMIFS(Data!$S$2:$S$51,Data!$I$2:$I$51,"No")+SUMIFS(Data!$T$2:$T$51,Data!$I$2:$I$51,"No"))) -> 0.30593831
A26: Dairy Alternatives | B26: =(SUMIFS(Data!$AD$2:$AD$51,Data!$G$2:$G$51,"dairy_alternative_plant"))/1000 -> 178.885 | C26: =IF(SUMIFS(Data!$AD$2:$AD$51,Data!$I$2:$I$51,"No")=0,"",B26*1000/SUMIFS(Data!$AD$2:$AD$51,Data!$I$2:$I$51,"No")) -> 0.0049579619 | D26: N/A | F26: =(SUMIFS(Data!$R$2:$R$51,Data!$G$2:$G$51,"dairy_alternative_plant"))/1000 -> 178.885 | G26: =IF(SUMIFS(Data!$R$2:$R$51,Data!$I$2:$I$51,"No")=0,"",F26*1000/SUMIFS(Data!$R$2:$R$51,Data!$I$2:$I$51,"No")) -> 0.0057733173 | I26: =(SUMIFS(Data!$S$2:$S$51,Data!$G$2:$G$51,"dairy_alternative_plant")+SUMIFS(Data!$T$2:$T$51,Data!$G$2:$G$51,"dairy_alternative_plant"))/1000 -> 12.52195 | J26: =IF((SUMIFS(Data!$S$2:$S$51,Data!$I$2:$I$51,"No")+SUMIFS(Data!$T$2:$T$51,Data!$I$2:$I$51,"No"))=0,"",I26*1000/(SUMIFS(Data!$S$2:$S$51,Data!$I$2:$I$51,"No")+SUMIFS(Data!$T$2:$T$51,Data!$I$2:$I$51,"No"))) -> 0.00710952
A27: FOOD GROUP 3
A28: Animal-Based Fats | B28: =(SUMIFS(Data!$AD$2:$AD$51,Data!$G$2:$G$51,"animal_based_fat"))/1000 -> 150.10125 | C28: =IF(SUMIFS(Data!$AD$2:$AD$51,Data!$I$2:$I$51,"No")=0,"",B28*1000/SUMIFS(Data!$AD$2:$AD$51,Data!$I$2:$I$51,"No")) -> 0.0041601938 | D28: 0.01 | F28: =(SUMIFS(Data!$R$2:$R$51,Data!$G$2:$G$51,"animal_based_fat"))/1000 -> 150.10125 | G28: =IF(SUMIFS(Data!$R$2:$R$51,Data!$I$2:$I$51,"No")=0,"",F28*1000/SUMIFS(Data!$R$2:$R$51,Data!$I$2:$I$51,"No")) -> 0.0048443533 | I28: =(SUMIFS(Data!$S$2:$S$51,Data!$G$2:$G$51,"animal_based_fat")+SUMIFS(Data!$T$2:$T$51,Data!$G$2:$G$51,"animal_based_fat"))/1000 -> 1.5010125 | J28: =IF((SUMIFS(Data!$S$2:$S$51,Data!$I$2:$I$51,"No")+SUMIFS(Data!$T$2:$T$51,Data!$I$2:$I$51,"No"))=0,"",I28*1000/(SUMIFS(Data!$S$2:$S$51,Data!$I$2:$I$51,"No")+SUMIFS(Data!$T$2:$T$51,Data!$I$2:$I$51,"No"))) -> 0.00085222177
A29: Plant-Based Fats | B29: =(SUMIFS(Data!$AD$2:$AD$51,Data!$G$2:$G$51,"plant_based_fat"))/1000 -> 748.20852 | C29: =IF(SUMIFS(Data!$AD$2:$AD$51,Data!$I$2:$I$51,"No")=0,"",B29*1000/SUMIFS(Data!$AD$2:$AD$51,Data!$I$2:$I$51,"No")) -> 0.020737285 | D29: 0.03 | F29: =(SUMIFS(Data!$R$2:$R$51,Data!$G$2:$G$51,"plant_based_fat"))/1000 -> 748.20852 | G29: =IF(SUMIFS(Data!$R$2:$R$51,Data!$I$2:$I$51,"No")=0,"",F29*1000/SUMIFS(Data!$R$2:$R$51,Data!$I$2:$I$51,"No")) -> 0.02414761 | I29: =(SUMIFS(Data!$S$2:$S$51,Data!$G$2:$G$51,"plant_based_fat")+SUMIFS(Data!$T$2:$T$51,Data!$G$2:$G$51,"plant_based_fat"))/1000 -> 3.7410426 | J29: =IF((SUMIFS(Data!$S$2:$S$51,Data!$I$2:$I$51,"No")+SUMIFS(Data!$T$2:$T$51,Data!$I$2:$I$51,"No"))=0,"",I29*1000/(SUMIFS(Data!$S$2:$S$51,Data!$I$2:$I$51,"No")+SUMIFS(Data!$T$2:$T$51,Data!$I$2:$I$51,"No"))) -> 0.0021240316
A30: FOOD GROUP 4
A31: Fruits & Vegetables | B31: =(SUMIFS(Data!$AD$2:$AD$51,Data!$F$2:$F$51,"FG4"))/1000 -> 9000.99 | C31: =IF(SUMIFS(Data!$AD$2:$AD$51,Data!$I$2:$I$51,"No")=0,"",B31*1000/SUMIFS(Data!$AD$2:$AD$51,Data!$I$2:$I$51,"No")) -> 0.24947069 | D31: 0.38 | F31: =(SUMIFS(Data!$R$2:$R$51,Data!$F$2:$F$51,"FG4"))/1000 -> 9000.99 | G31: =IF(SUMIFS(Data!$R$2:$R$51,Data!$I$2:$I$51,"No")=0,"",F31*1000/SUMIFS(Data!$R$2:$R$51,Data!$I$2:$I$51,"No")) -> 0.29049708 | I31: =(SUMIFS(Data!$S$2:$S$51,Data!$F$2:$F$51,"FG4")+SUMIFS(Data!$T$2:$T$51,Data!$F$2:$F$51,"FG4"))/1000 -> 95.410494 | J31: =IF((SUMIFS(Data!$S$2:$S$51,Data!$I$2:$I$51,"No")+SUMIFS(Data!$T$2:$T$51,Data!$I$2:$I$51,"No"))=0,"",I31*1000/(SUMIFS(Data!$S$2:$S$51,Data!$I$2:$I$51,"No")+SUMIFS(Data!$T$2:$T$51,Data!$I$2:$I$51,"No"))) -> 0.054170701
A32: FOOD GROUP 5
A33: Whole Grains | B33: =(SUMIFS(Data!$AD$2:$AD$51,Data!$G$2:$G$51,"whole_grain"))/1000 -> 516.75113 | C33: =IF(SUMIFS(Data!$AD$2:$AD$51,Data!$I$2:$I$51,"No")=0,"",B33*1000/SUMIFS(Data!$AD$2:$AD$51,Data!$I$2:$I$51,"No")) -> 0.014322231 | D33: 0.18 | F33: =(SUMIFS(Data!$R$2:$R$51,Data!$G$2:$G$51,"whole_grain"))/1000 -> 516.75113 | G33: =IF(SUMIFS(Data!$R$2:$R$51,Data!$I$2:$I$51,"No")=0,"",F33*1000/SUMIFS(Data!$R$2:$R$51,Data!$I$2:$I$51,"No")) -> 0.016677576 | I33: =(SUMIFS(Data!$S$2:$S$51,Data!$G$2:$G$51,"whole_grain")+SUMIFS(Data!$T$2:$T$51,Data!$G$2:$G$51,"whole_grain"))/1000 -> 47.541103 | J33: =IF((SUMIFS(Data!$S$2:$S$51,Data!$I$2:$I$51,"No")+SUMIFS(Data!$T$2:$T$51,Data!$I$2:$I$51,"No"))=0,"",I33*1000/(SUMIFS(Data!$S$2:$S$51,Data!$I$2:$I$51,"No")+SUMIFS(Data!$T$2:$T$51,Data!$I$2:$I$51,"No"))) -> 0.026992156
A34: Refined Grains | B34: =(SUMIFS(Data!$AD$2:$AD$51,Data!$G$2:$G$51,"refined_grain"))/1000 -> 2400.598 | C34: =IF(SUMIFS(Data!$AD$2:$AD$51,Data!$I$2:$I$51,"No")=0,"",B34*1000/SUMIFS(Data!$AD$2:$AD$51,Data!$I$2:$I$51,"No")) -> 0.066534776 | D34: 0 | F34: =(SUMIFS(Data!$R$2:$R$51,Data!$G$2:$G$51,"refined_grain"))/1000 -> 2400.598 | G34: =IF(SUMIFS(Data!$R$2:$R$51,Data!$I$2:$I$51,"No")=0,"",F34*1000/SUMIFS(Data!$R$2:$R$51,Data!$I$2:$I$51,"No")) -> 0.077476669 | I34: =(SUMIFS(Data!$S$2:$S$51,Data!$G$2:$G$51,"refined_grain")+SUMIFS(Data!$T$2:$T$51,Data!$G$2:$G$51,"refined_grain"))/1000 -> 234.947 | J34: =IF((SUMIFS(Data!$S$2:$S$51,Data!$I$2:$I$51,"No")+SUMIFS(Data!$T$2:$T$51,Data!$I$2:$I$51,"No"))=0,"",I34*1000/(SUMIFS(Data!$S$2:$S$51,Data!$I$2:$I$51,"No")+SUMIFS(Data!$T$2:$T$51,Data!$I$2:$I$51,"No"))) -> 0.13339459
A35: FOOD GROUP 6
A36: Starchy Vegetables | B36: =(SUMIFS(Data!$AD$2:$AD$51,Data!$F$2:$F$51,"FG6"))/1000 -> 2110.945 | C36: =IF(SUMIFS(Data!$AD$2:$AD$51,Data!$I$2:$I$51,"No")=0,"",B36*1000/SUMIFS(Data!$AD$2:$AD$51,Data!$I$2:$I$51,"No")) -> 0.058506777 | D36: 0.04 | F36: =(SUMIFS(Data!$R$2:$R$51,Data!$F$2:$F$51,"FG6"))/1000 -> 2110.945 | G36: =IF(SUMIFS(Data!$R$2:$R$51,Data!$I$2:$I$51,"No")=0,"",F36*1000/SUMIFS(Data!$R$2:$R$51,Data!$I$2:$I$51,"No")) -> 0.068128436 | I36: =(SUMIFS(Data!$S$2:$S$51,Data!$F$2:$F$51,"FG6")+SUMIFS(Data!$T$2:$T$51,Data!$F$2:$F$51,"FG6"))/1000 -> 44.963129 | J36: =IF((SUMIFS(Data!$S$2:$S$51,Data!$I$2:$I$51,"No")+SUMIFS(Data!$T$2:$T$51,Data!$I$2:$I$51,"No"))=0,"",I36*1000/(SUMIFS(Data!$S$2:$S$51,Data!$I$2:$I$51,"No")+SUMIFS(Data!$T$2:$T$51,Data!$I$2:$I$51,"No"))) -> 0.025528473
A37: FOOD GROUP 7
A38: Plant-Based | B38: =(SUMIFS(Data!$AD$2:$AD$51,Data!$F$2:$F$51,"FG7",Data!$H$2:$H$51,"plant_based"))/1000 -> 0 | C38: =IF(SUMIFS(Data!$AD$2:$AD$51,Data!$I$2:$I$51,"No")=0,"",B38*1000/SUMIFS(Data!$AD$2:$AD$51,Data!$I$2:$I$51,"No")) -> 0 | D38: N/A | F38: =(SUMIFS(Data!$R$2:$R$51,Data!$F$2:$F$51,"FG7",Data!$H$2:$H$51,"plant_based"))/1000 -> 0 | G38: =IF(SUMIFS(Data!$R$2:$R$51,Data!$I$2:$I$51,"No")=0,"",F38*1000/SUMIFS(Data!$R$2:$R$51,Data!$I$2:$I$51,"No")) -> 0 | I38: =(SUMIFS(Data!$S$2:$S$51,Data!$F$2:$F$51,"FG7",Data!$H$2:$H$51,"plant_based")+SUMIFS(Data!$T$2:$T$51,Data!$F$2:$F$51,"FG7",Data!$H$2:$H$51,"plant_based"))/1000 -> 0 | J38: =IF((SUMIFS(Data!$S$2:$S$51,Data!$I$2:$I$51,"No")+SUMIFS(Data!$T$2:$T$51,Data!$I$2:$I$51,"No"))=0,"",I38*1000/(SUMIFS(Data!$S$2:$S$51,Data!$I$2:$I$51,"No")+SUMIFS(Data!$T$2:$T$51,Data!$I$2:$I$51,"No"))) -> 0
A39: Animal-Based | B39: =(SUMIFS(Data!$AD$2:$AD$51,Data!$F$2:$F$51,"FG7",Data!$H$2:$H$51,"animal_based"))/1000 -> 1240.7495 | C39: =IF(SUMIFS(Data!$AD$2:$AD$51,Data!$I$2:$I$51,"No")=0,"",B39*1000/SUMIFS(Data!$AD$2:$AD$51,Data!$I$2:$I$51,"No")) -> 0.03438851 | D39: N/A | F39: =(SUMIFS(Data!$R$2:$R$51,Data!$F$2:$F$51,"FG7",Data!$H$2:$H$51,"animal_based"))/1000 -> 1240.7495 | G39: =IF(SUMIFS(Data!$R$2:$R$51,Data!$I$2:$I$51,"No")=0,"",F39*1000/SUMIFS(Data!$R$2:$R$51,Data!$I$2:$I$51,"No")) -> 0.04004383 | I39: =(SUMIFS(Data!$S$2:$S$51,Data!$F$2:$F$51,"FG7",Data!$H$2:$H$51,"animal_based")+SUMIFS(Data!$T$2:$T$51,Data!$F$2:$F$51,"FG7",Data!$H$2:$H$51,"animal_based"))/1000 -> 78.167219 | J39: =IF((SUMIFS(Data!$S$2:$S$51,Data!$I$2:$I$51,"No")+SUMIFS(Data!$T$2:$T$51,Data!$I$2:$I$51,"No"))=0,"",I39*1000/(SUMIFS(Data!$S$2:$S$51,Data!$I$2:$I$51,"No")+SUMIFS(Data!$T$2:$T$51,Data!$I$2:$I$51,"No"))) -> 0.04438058
A40: Origin not determined | B40: =(SUMIFS(Data!$AD$2:$AD$51,Data!$F$2:$F$51,"FG7",Data!$H$2:$H$51,"not applicable"))/1000 -> 0 | C40: =IF(SUMIFS(Data!$AD$2:$AD$51,Data!$I$2:$I$51,"No")=0,"",B40*1000/SUMIFS(Data!$AD$2:$AD$51,Data!$I$2:$I$51,"No")) -> 0 | D40: — | F40: =(SUMIFS(Data!$R$2:$R$51,Data!$F$2:$F$51,"FG7",Data!$H$2:$H$51,"not applicable"))/1000 -> 0 | G40: =IF(SUMIFS(Data!$R$2:$R$51,Data!$I$2:$I$51,"No")=0,"",F40*1000/SUMIFS(Data!$R$2:$R$51,Data!$I$2:$I$51,"No")) -> 0 | I40: =(SUMIFS(Data!$S$2:$S$51,Data!$F$2:$F$51,"FG7",Data!$H$2:$H$51,"not applicable")+SUMIFS(Data!$T$2:$T$51,Data!$F$2:$F$51,"FG7",Data!$H$2:$H$51,"not applicable"))/1000 -> 0 | J40: =IF((SUMIFS(Data!$S$2:$S$51,Data!$I$2:$I$51,"No")+SUMIFS(Data!$T$2:$T$51,Data!$I$2:$I$51,"No"))=0,"",I40*1000/(SUMIFS(Data!$S$2:$S$51,Data!$I$2:$I$51,"No")+SUMIFS(Data!$T$2:$T$51,Data!$I$2:$I$51,"No"))) -> 0
A42: FOOD GROUP 1 PROPORTION BY SOURCE
A43: Plant | C43: =IF(((SUMIFS(Data!$AD$2:$AD$51,Data!$G$2:$G$51,"legumes") + SUMIFS(Data!$AD$2:$AD$51,Data!$G$2:$G$51,"nuts") + SUMIFS(Data!$AD$2:$AD$51,Data!$G$2:$G$51,"seeds") + SUMIFS(Data!$AD$2:$AD$51,Data!$G$2:$G$51,"meat_egg_seafood_alternatives") + SUMIFS(Data!$AD$2:$AD$51,Data!$G$2:$G$51,"tofu_tempeh_seitan"))+(SUMIFS(Data!$AD$2:$AD$51,Data!$G$2:$G$51,"red_meat") + SUMIFS(Data!$AD$2:$AD$51,Data!$G$2:$G$51,"poultry") + SUMIFS(Data!$AD$2:$AD$51,Data!$G$2:$G$51,"seafood") + SUMIFS(Data!$AD$2:$AD$51,Data!$G$2:$G$51,"eggs") + SUMIFS(Data!$AD$2:$AD$51,Data!$G$2:$G$51,"other_animal")))=0,"",(SUMIFS(Data!$AD$2:$AD$51,Data!$G$2:$G$51,"legumes") + SUMIFS(Data!$AD$2:$AD$51,Data!$G$2:$G$51,"nuts") + SUMIFS(Data!$AD$2:$AD$51,Data!$G$2:$G$51,"seeds") + SUMIFS(Data!$AD$2:$AD$51,Data!$G$2:$G$51,"meat_egg_seafood_alternatives") + SUMIFS(Data!$AD$2:$AD$51,Data!$G$2:$G$51,"tofu_tempeh_seitan"))/((SUMIFS(Data!$AD$2:$AD$51,Data!$G$2:$G$51,"legumes") + SUMIFS(Data!$AD$2:$AD$51,Data!$G$2:$G$51,"nuts") + SUMIFS(Data!$AD$2:$AD$51,Data!$G$2:$G$51,"seeds") + SUMIFS(Data!$AD$2:$AD$51,Data!$G$2:$G$51,"meat_egg_seafood_alternatives") + SUMIFS(Data!$AD$2:$AD$51,Data!$G$2:$G$51,"tofu_tempeh_seitan"))+(SUMIFS(Data!$AD$2:$AD$51,Data!$G$2:$G$51,"red_meat") + SUMIFS(Data!$AD$2:$AD$51,Data!$G$2:$G$51,"poultry") + SUMIFS(Data!$AD$2:$AD$51,Data!$G$2:$G$51,"seafood") + SUMIFS(Data!$AD$2:$AD$51,Data!$G$2:$G$51,"eggs") + SUMIFS(Data!$AD$2:$AD$51,Data!$G$2:$G$51,"other_animal")))) -> 0.10062812 | D43: 0.6
A44: Animal | C44: =IF(((SUMIFS(Data!$AD$2:$AD$51,Data!$G$2:$G$51,"legumes") + SUMIFS(Data!$AD$2:$AD$51,Data!$G$2:$G$51,"nuts") + SUMIFS(Data!$AD$2:$AD$51,Data!$G$2:$G$51,"seeds") + SUMIFS(Data!$AD$2:$AD$51,Data!$G$2:$G$51,"meat_egg_seafood_alternatives") + SUMIFS(Data!$AD$2:$AD$51,Data!$G$2:$G$51,"tofu_tempeh_seitan"))+(SUMIFS(Data!$AD$2:$AD$51,Data!$G$2:$G$51,"red_meat") + SUMIFS(Data!$AD$2:$AD$51,Data!$G$2:$G$51,"poultry") + SUMIFS(Data!$AD$2:$AD$51,Data!$G$2:$G$51,"seafood") + SUMIFS(Data!$AD$2:$AD$51,Data!$G$2:$G$51,"eggs") + SUMIFS(Data!$AD$2:$AD$51,Data!$G$2:$G$51,"other_animal")))=0,"",(SUMIFS(Data!$AD$2:$AD$51,Data!$G$2:$G$51,"red_meat") + SUMIFS(Data!$AD$2:$AD$51,Data!$G$2:$G$51,"poultry") + SUMIFS(Data!$AD$2:$AD$51,Data!$G$2:$G$51,"seafood") + SUMIFS(Data!$AD$2:$AD$51,Data!$G$2:$G$51,"eggs") + SUMIFS(Data!$AD$2:$AD$51,Data!$G$2:$G$51,"other_animal"))/((SUMIFS(Data!$AD$2:$AD$51,Data!$G$2:$G$51,"legumes") + SUMIFS(Data!$AD$2:$AD$51,Data!$G$2:$G$51,"nuts") + SUMIFS(Data!$AD$2:$AD$51,Data!$G$2:$G$51,"seeds") + SUMIFS(Data!$AD$2:$AD$51,Data!$G$2:$G$51,"meat_egg_seafood_alternatives") + SUMIFS(Data!$AD$2:$AD$51,Data!$G$2:$G$51,"tofu_tempeh_seitan"))+(SUMIFS(Data!$AD$2:$AD$51,Data!$G$2:$G$51,"red_meat") + SUMIFS(Data!$AD$2:$AD$51,Data!$G$2:$G$51,"poultry") + SUMIFS(Data!$AD$2:$AD$51,Data!$G$2:$G$51,"seafood") + SUMIFS(Data!$AD$2:$AD$51,Data!$G$2:$G$51,"eggs") + SUMIFS(Data!$AD$2:$AD$51,Data!$G$2:$G$51,"other_animal")))) -> 0.89937188 | D44: 0.4
...

Sheet By category
A1: BY CATEGORY
A3: WWF sub-groups
A5: WWF subgroup | B5: Mass (t) | C5: Protein (t) | D5: Plant protein (t) | E5: Animal protein (t) | F5: Plant share (weight) | G5: Animal share (weight)
A6: FG1 · red_meat | B6: =SUMIFS(Data!$R$2:$R$51,Data!$G$2:$G$51,"red_meat")/1000 -> 131.564 | C6: =D6+E6 -> 26.3128 | D6: =SUMIFS(Data!$S$2:$S$51,Data!$G$2:$G$51,"red_meat")/1000 -> 0 | E6: =SUMIFS(Data!$T$2:$T$51,Data!$G$2:$G$51,"red_meat")/1000 -> 26.3128 | F6: =IF(SUMIFS(Data!$R$2:$R$51,Data!$G$2:$G$51,"red_meat",Data!$H$2:$H$51,"plant_based")+SUMIFS(Data!$R$2:$R$51,Data!$G$2:$G$51,"red_meat",Data!$H$2:$H$51,"animal_based")=0,"",SUMIFS(Data!$R$2:$R$51,Data!$G$2:$G$51,"red_meat",Data!$H$2:$H$51,"plant_based")/(SUMIFS(Data!$R$2:$R$51,Data!$G$2:$G$51,"red_meat",Data!$H$2:$H$51,"plant_based")+SUMIFS(Data!$R$2:$R$51,Data!$G$2:$G$51,"red_meat",Data!$H$2:$H$51,"animal_based"))) -> 0 | G6: =IF(SUMIFS(Data!$R$2:$R$51,Data!$G$2:$G$51,"red_meat",Data!$H$2:$H$51,"plant_based")+SUMIFS(Data!$R$2:$R$51,Data!$G$2:$G$51,"red_meat",Data!$H$2:$H$51,"animal_based")=0,"",SUMIFS(Data!$R$2:$R$51,Data!$G$2:$G$51,"red_meat",Data!$H$2:$H$51,"animal_based")/(SUMIFS(Data!$R$2:$R$51,Data!$G$2:$G$51,"red_meat",Data!$H$2:$H$51,"plant_based")+SUMIFS(Data!$R$2:$R$51,Data!$G$2:$G$51,"red_meat",Data!$H$2:$H$51,"animal_based"))) -> 1
A7: FG1 · poultry | B7: =SUMIFS(Data!$R$2:$R$51,Data!$G$2:$G$51,"poultry")/1000 -> 1040.133 | C7: =D7+E7 -> 219.85027 | D7: =SUMIFS(Data!$S$2:$S$51,Data!$G$2:$G$51,"poultry")/1000 -> 0 | E7: =SUMIFS(Data!$T$2:$T$51,Data!$G$2:$G$51,"poultry")/1000 -> 219.85027 | F7: =IF(SUMIFS(Data!$R$2:$R$51,Data!$G$2:$G$51,"poultry",Data!$H$2:$H$51,"plant_based")+SUMIFS(Data!$R$2:$R$51,Data!$G$2:$G$51,"poultry",Data!$H$2:$H$51,"animal_based")=0,"",SUMIFS(Data!$R$2:$R$51,Data!$G$2:$G$51,"poultry",Data!$H$2:$H$51,"plant_based")/(SUMIFS(Data!$R$2:$R$51,Data!$G$2:$G$51,"poultry",Data!$H$2:$H$51,"plant_based")+SUMIFS(Data!$R$2:$R$51,Data!$G$2:$G$51,"poultry",Data!$H$2:$H$51,"animal_based"))) -> 0 | G7: =IF(SUMIFS(Data!$R$2:$R$51,Data!$G$2:$G$51,"poultry",Data!$H$2:$H$51,"plant_based")+SUMIFS(Data!$R$2:$R$51,Data!$G$2:$G$51,"poultry",Data!$H$2:$H$51,"animal_based")=0,"",SUMIFS(Data!$R$2:$R$51,Data!$G$2:$G$51,"poultry",Data!$H$2:$H$51,"animal_based")/(SUMIFS(Data!$R$2:$R$51,Data!$G$2:$G$51,"poultry",Data!$H$2:$H$51,"plant_based")+SUMIFS(Data!$R$2:$R$51,Data!$G$2:$G$51,"poultry",Data!$H$2:$H$51,"animal_based"))) -> 1
A8: FG1 · seafood | B8: =SUMIFS(Data!$R$2:$R$51,Data!$G$2:$G$51,"seafood")/1000 -> 774.237 | C8: =D8+E8 -> 174.06894 | D8: =SUMIFS(Data!$S$2:$S$51,Data!$G$2:$G$51,"seafood")/1000 -> 0 | E8: =SUMIFS(Data!$T$2:$T$51,Data!$G$2:$G$51,"seafood")/1000 -> 174.06894 | F8: =IF(SUMIFS(Data!$R$2:$R$51,Data!$G$2:$G$51,"seafood",Data!$H$2:$H$51,"plant_based")+SUMIFS(Data!$R$2:$R$51,Data!$G$2:$G$51,"seafood",Data!$H$2:$H$51,"animal_based")=0,"",SUMIFS(Data!$R$2:$R$51,Data!$G$2:$G$51,"seafood",Data!$H$2:$H$51,"plant_based")/(SUMIFS(Data!$R$2:$R$51,Data!$G$2:$G$51,"seafood",Data!$H$2:$H$51,"plant_based")+SUMIFS(Data!$R$2:$R$51,Data!$G$2:$G$51,"seafood",Data!$H$2:$H$51,"animal_based"))) -> 0 | G8: =IF(SUMIFS(Data!$R$2:$R$51,Data!$G$2:$G$51,"seafood",Data!$H$2:$H$51,"plant_based")+SUMIFS(Data!$R$2:$R$51,Data!$G$2:$G$51,"seafood",Data!$H$2:$H$51,"animal_based")=0,"",SUMIFS(Data!$R$2:$R$51,Data!$G$2:$G$51,"seafood",Data!$H$2:$H$51,"animal_based")/(SUMIFS(Data!$R$2:$R$51,Data!$G$2:$G$51,"seafood",Data!$H$2:$H$51,"plant_based")+SUMIFS(Data!$R$2:$R$51,Data!$G$2:$G$51,"seafood",Data!$H$2:$H$51,"animal_based"))) -> 1
A9: FG1 · eggs | B9: =SUMIFS(Data!$R$2:$R$51,Data!$G$2:$G$51,"eggs")/1000 -> 1434.4871 | C9: =D9+E9 -> 209.41584 | D9: =SUMIFS(Data!$S$2:$S$51,Data!$G$2:$G$51,"eggs")/1000 -> 0 | E9: =SUMIFS(Data!$T$2:$T$51,Data!$G$2:$G$51,"eggs")/1000 -> 209.41584 | F9: =IF(SUMIFS(Data!$R$2:$R$51,Data!$G$2:$G$51,"eggs",Data!$H$2:$H$51,"plant_based")+SUMIFS(Data!$R$2:$R$51,Data!$G$2:$G$51,"eggs",Data!$H$2:$H$51,"animal_based")=0,"",SUMIFS(Data!$R$2:$R$51,Data!$G$2:$G$51,"eggs",Data!$H$2:$H$51,"plant_based")/(SUMIFS(Data!$R$2:$R$51,Data!$G$2:$G$51,"eggs",Data!$H$2:$H$51,"plant_based")+SUMIFS(Data!$R$2:$R$51,Data!$G$2:$G$51,"eggs",Data!$H$2:$H$51,"animal_based"))) -> 0 | G9: =IF(SUMIFS(Data!$R$2:$R$51,Data!$G$2:$G$51,"eggs",Data!$H$2:$H$51,"plant_based")+SUMIFS(Data!$R$2:$R$51,Data!$G$2:$G$51,"eggs",Data!$H$2:$H$51,"animal_based")=0,"",SUMIFS(Data!$R$2:$R$51,Data!$G$2:$G$51,"eggs",Data!$H$2:$H$51,"animal_based")/(SUMIFS(Data!$R$2:$R$51,Data!$G$2:$G$51,"eggs",Data!$H$2:$H$51,"plant_based")+SUMIFS(Data!$R$2:$R$51,Data!$G$2:$G$51,"eggs",Data!$H$2:$H$51,"animal_based"))) -> 1
A10: FG1 · other_animal | B10: =SUMIFS(Data!$R$2:$R$51,Data!$G$2:$G$51,"other_animal")/1000 -> 9.394 | C10: =D10+E10 -> 1.50304 | D10: =SUMIFS(Data!$S$2:$S$51,Data!$G$2:$G$51,"other_animal")/1000 -> 0 | E10: =SUMIFS(Data!$T$2:$T$51,Data!$G$2:$G$51,"other_animal")/1000 -> 1.50304 | F10: =IF(SUMIFS(Data!$R$2:$R$51,Data!$G$2:$G$51,"other_animal",Data!$H$2:$H$51,"plant_based")+SUMIFS(Data!$R$2:$R$51,Data!$G$2:$G$51,"other_animal",Data!$H$2:$H$51,"animal_based")=0,"",SUMIFS(Data!$R$2:$R$51,Data!$G$2:$G$51,"other_animal",Data!$H$2:$H$51,"plant_based")/(SUMIFS(Data!$R$2:$R$51,Data!$G$2:$G$51,"other_animal",Data!$H$2:$H$51,"plant_based")+SUMIFS(Data!$R$2:$R$51,Data!$G$2:$G$51,"other_animal",Data!$H$2:$H$51,"animal_based"))) -> 0 | G10: =IF(SUMIFS(Data!$R$2:$R$51,Data!$G$2:$G$51,"other_animal",Data!$H$2:$H$51,"plant_based")+SUMIFS(Data!$R$2:$R$51,Data!$G$2:$G$51,"other_animal",Data!$H$2:$H$51,"animal_based")=0,"",SUMIFS(Data!$R$2:$R$51,Data!$G$2:$G$51,"other_animal",Data!$H$2:$H$51,"animal_based")/(SUMIFS(Data!$R$2:$R$51,Data!$G$2:$G$51,"other_animal",Data!$H$2:$H$51,"plant_based")+SUMIFS(Data!$R$2:$R$51,Data!$G$2:$G$51,"other_animal",Data!$H$2:$H$51,"animal_based"))) -> 1
A11: FG1 · legumes | B11: =SUMIFS(Data!$R$2:$R$51,Data!$G$2:$G$51,"legumes")/1000 -> 173.7752 | C11: =D11+E11 -> 19.115272 | D11: =SUMIFS(Data!$S$2:$S$51,Data!$G$2:$G$51,"legumes")/1000 -> 19.115272 | E11: =SUMIFS(Data!$T$2:$T$51,Data!$G$2:$G$51,"legumes")/1000 -> 0 | F11: =IF(SUMIFS(Data!$R$2:$R$51,Data!$G$2:$G$51,"legumes",Data!$H$2:$H$51,"plant_based")+SUMIFS(Data!$R$2:$R$51,Data!$G$2:$G$51,"legumes",Data!$H$2:$H$51,"animal_based")=0,"",SUMIFS(Data!$R$2:$R$51,Data!$G$2:$G$51,"legumes",Data!$H$2:$H$51,"plant_based")/(SUMIFS(Data!$R$2:$R$51,Data!$G$2:$G$51,"legumes",Data!$H$2:$H$51,"plant_based")+SUMIFS(Data!$R$2:$R$51,Data!$G$2:$G$51,"legumes",Data!$H$2:$H$51,"animal_based"))) -> 1 | G11: =IF(SUMIFS(Data!$R$2:$R$51,Data!$G$2:$G$51,"legumes",Data!$H$2:$H$51,"plant_based")+SUMIFS(Data!$R$2:$R$51,Data!$G$2:$G$51,"legumes",Data!$H$2:$H$51,"animal_based")=0,"",SUMIFS(Data!$R$2:$R$51,Data!$G$2:$G$51,"legumes",Data!$H$2:$H$51,"animal_based")/(SUMIFS(Data!$R$2:$R$51,Data!$G$2:$G$51,"legumes",Data!$H$2:$H$51,"plant_based")+SUMIFS(Data!$R$2:$R$51,Data!$G$2:$G$51,"legumes",Data!$H$2:$H$51,"animal_based"))) -> 0
A12: FG1 · nuts | B12: =SUMIFS(Data!$R$2:$R$51,Data!$G$2:$G$51,"nuts")/1000 -> 133.1031 | C12: =D12+E12 -> 36.460974 | D12: =SUMIFS(Data!$S$2:$S$51,Data!$G$2:$G$51,"nuts")/1000 -> 36.460974 | E12: =SUMIFS(Data!$T$2:$T$51,Data!$G$2:$G$51,"nuts")/1000 -> 0 | F12: =IF(SUMIFS(Data!$R$2:$R$51,Data!$G$2:$G$51,"nuts",Data!$H$2:$H$51,"plant_based")+SUMIFS(Data!$R$2:$R$51,Data!$G$2:$G$51,"nuts",Data!$H$2:$H$51,"animal_based")=0,"",SUMIFS(Data!$R$2:$R$51,Data!$G$2:$G$51,"nuts",Data!$H$2:$H$51,"plant_based")/(SUMIFS(Data!$R$2:$R$51,Data!$G$2:$G$51,"nuts",Data!$H$2:$H$51,"plant_based")+SUMIFS(Data!$R$2:$R$51,Data!$G$2:$G$51,"nuts",Data!$H$2:$H$51,"animal_based"))) -> 1 | G12: =IF(SUMIFS(Data!$R$2:$R$51,Data!$G$2:$G$51,"nuts",Data!$H$2:$H$51,"plant_based")+SUMIFS(Data!$R$2:$R$51,Data!$G$2:$G$51,"nuts",Data!$H$2:$H$51,"animal_based")=0,"",SUMIFS(Data!$R$2:$R$51,Data!$G$2:$G$51,"nuts",Data!$H$2:$H$51,"animal_based")/(SUMIFS(Data!$R$2:$R$51,Data!$G$2:$G$51,"nuts",Data!$H$2:$H$51,"plant_based")+SUMIFS(Data!$R$2:$R$51,Data!$G$2:$G$51,"nuts",Data!$H$2:$H$51,"animal_based"))) -> 0
A13: FG1 · seeds | B13: =SUMIFS(Data!$R$2:$R$51,Data!$G$2:$G$51,"seeds")/1000 -> 38.16 | C13: =D13+E13 -> 11.448 | D13: =SUMIFS(Data!$S$2:$S$51,Data!$G$2:$G$51,"seeds")/1000 -> 11.448 | E13: =SUMIFS(Data!$T$2:$T$51,Data!$G$2:$G$51,"seeds")/1000 -> 0 | F13: =IF(SUMIFS(Data!$R$2:$R$51,Data!$G$2:$G$51,"seeds",Data!$H$2:$H$51,"plant_based")+SUMIFS(Data!$R$2:$R$51,Data!$G$2:$G$51,"seeds",Data!$H$2:$H$51,"animal_based")=0,"",SUMIFS(Data!$R$2:$R$51,Data!$G$2:$G$51,"seeds",Data!$H$2:$H$51,"plant_based")/(SUMIFS(Data!$R$2:$R$51,Data!$G$2:$G$51,"seeds",Data!$H$2:$H$51,"plant_based")+SUMIFS(Data!$R$2:$R$51,Data!$G$2:$G$51,"seeds",Data!$H$2:$H$51,"animal_based"))) -> 1 | G13: =IF(SUMIFS(Data!$R$2:$R$51,Data!$G$2:$G$51,"seeds",Data!$H$2:$H$51,"plant_based")+SUMIFS(Data!$R$2:$R$51,Data!$G$2:$G$51,"seeds",Data!$H$2:$H$51,"animal_based")=0,"",SUMIFS(Data!$R$2:$R$51,Data!$G$2:$G$51,"seeds",Data!$H$2:$H$51,"animal_based")/(SUMIFS(Data!$R$2:$R$51,Data!$G$2:$G$51,"seeds",Data!$H$2:$H$51,"plant_based")+SUMIFS(Data!$R$2:$R$51,Data!$G$2:$G$51,"seeds",Data!$H$2:$H$51,"animal_based"))) -> 0
A14: FG1 · tofu_tempeh_seitan | B14: =SUMIFS(Data!$R$2:$R$51,Data!$G$2:$G$51,"tofu_tempeh_seitan")/1000 -> 14.7904 | C14: =D14+E14 -> 2.366464 | D14: =SUMIFS(Data!$S$2:$S$51,Data!$G$2:$G$51,"tofu_tempeh_seitan")/1000 -> 2.366464 | E14: =SUMIFS(Data!$T$2:$T$51,Data!$G$2:$G$51,"tofu_tempeh_seitan")/1000 -> 0 | F14: =IF(SUMIFS(Data!$R$2:$R$51,Data!$G$2:$G$51,"tofu_tempeh_seitan",Data!$H$2:$H$51,"plant_based")+SUMIFS(Data!$R$2:$R$51,Data!$G$2:$G$51,"tofu_tempeh_seitan",Data!$H$2:$H$51,"animal_based")=0,"",SUMIFS(Data!$R$2:$R$51,Data!$G$2:$G$51,"tofu_tempeh_seitan",Data!$H$2:$H$51,"plant_based")/(SUMIFS(Data!$R$2:$R$51,Data!$G$2:$G$51,"tofu_tempeh_seitan",Data!$H$2:$H$51,"plant_based")+SUMIFS(Data!$R$2:$R$51,Data!$G$2:$G$51,"tofu_tempeh_seitan",Data!$H$2:$H$51,"animal_based"))) -> 1 | G14: =IF(SUMIFS(Data!$R$2:$R$51,Data!$G$2:$G$51,"tofu_tempeh_seitan",Data!$H$2:$H$51,"plant_based")+SUMIFS(Data!$R$2:$R$51,Data!$G$2:$G$51,"tofu_tempeh_seitan",Data!$H$2:$H$51,"animal_based")=0,"",SUMIFS(Data!$R$2:$R$51,Data!$G$2:$G$51,"tofu_tempeh_seitan",Data!$H$2:$H$51,"animal_based")/(SUMIFS(Data!$R$2:$R$51,Data!$G$2:$G$51,"tofu_tempeh_seitan",Data!$H$2:$H$51,"plant_based")+SUMIFS(Data!$R$2:$R$51,Data!$G$2:$G$51,"tofu_tempeh_seitan",Data!$H$2:$H$51,"animal_based"))) -> 0
A15: FG1 · meat_egg_seafood_alternatives | B15: =SUMIFS(Data!$R$2:$R$51,Data!$G$2:$G$51,"meat_egg_seafood_alternatives")/1000 -> 19.44789 | C15: =D15+E15 -> 3.1116624 | D15: =SUMIFS(Data!$S$2:$S$51,Data!$G$2:$G$51,"meat_egg_seafood_alternatives")/1000 -> 1.5558312 | E15: =SUMIFS(Data!$T$2:$T$51,Data!$G$2:$G$51,"meat_egg_seafood_alternatives")/1000 -> 1.5558312 | F15: =IF(SUMIFS(Data!$R$2:$R$51,Data!$G$2:$G$51,"meat_egg_seafood_alternatives",Data!$H$2:$H$51,"plant_based")+SUMIFS(Data!$R$2:$R$51,Data!$G$2:$G$51,"meat_egg_seafood_alternatives",Data!$H$2:$H$51,"animal_based")=0,"",SUMIFS(Data!$R$2:$R$51,Data!$G$2:$G$51,"meat_egg_seafood_alternatives",Data!$H$2:$H$51,"plant_based")/(SUMIFS(Data!$R$2:$R$51,Data!$G$2:$G$51,"meat_egg_seafood_alternatives",Data!$H$2:$H$51,"plant_based")+SUMIFS(Data!$R$2:$R$51,Data!$G$2:$G$51,"meat_egg_seafood_alternatives",Data!$H$2:$H$51,"animal_based"))) -> 0 | G15: =IF(SUMIFS(Data!$R$2:$R$51,Data!$G$2:$G$51,"meat_egg_seafood_alternatives",Data!$H$2:$H$51,"plant_based")+SUMIFS(Data!$R$2:$R$51,Data!$G$2:$G$51,"meat_egg_seafood_alternatives",Data!$H$2:$H$51,"animal_based")=0,"",SUMIFS(Data!$R$2:$R$51,Data!$G$2:$G$51,"meat_egg_seafood_alternatives",Data!$H$2:$H$51,"animal_based")/(SUMIFS(Data!$R$2:$R$51,Data!$G$2:$G$51,"meat_egg_seafood_alternatives",Data!$H$2:$H$51,"plant_based")+SUMIFS(Data!$R$2:$R$51,Data!$G$2:$G$51,"meat_egg_seafood_alternatives",Data!$H$2:$H$51,"animal_based"))) -> 1
A16: FG2 · dairy_animal | B16: =SUMIFS(Data!$R$2:$R$51,Data!$G$2:$G$51,"dairy_animal")/1000 -> 10868.466 | C16: =D16+E16 -> 538.8471 | D16: =SUMIFS(Data!$S$2:$S$51,Data!$G$2:$G$51,"dairy_animal")/1000 -> 0 | E16: =SUMIFS(Data!$T$2:$T$51,Data!$G$2:$G$51,"dairy_animal")/1000 -> 538.8471 | F16: =IF(SUMIFS(Data!$R$2:$R$51,Data!$G$2:$G$51,"dairy_animal",Data!$H$2:$H$51,"plant_based")+SUMIFS(Data!$R$2:$R$51,Data!$G$2:$G$51,"dairy_animal",Data!$H$2:$H$51,"animal_based")=0,"",SUMIFS(Data!$R$2:$R$51,Data!$G$2:$G$51,"dairy_animal",Data!$H$2:$H$51,"plant_based")/(SUMIFS(Data!$R$2:$R$51,Data!$G$2:$G$51,"dairy_animal",Data!$H$2:$H$51,"plant_based")+SUMIFS(Data!$R$2:$R$51,Data!$G$2:$G$51,"dairy_animal",Data!$H$2:$H$51,"animal_based"))) -> 0 | G16: =IF(SUMIFS(Data!$R$2:$R$51,Data!$G$2:$G$51,"dairy_animal",Data!$H$2:$H$51,"plant_based")+SUMIFS(Data!$R$2:$R$51,Data!$G$2:$G$51,"dairy_animal",Data!$H$2:$H$51,"animal_based")=0,"",SUMIFS(Data!$R$2:$R$51,Data!$G$2:$G$51,"dairy_animal",Data!$H$2:$H$51,"animal_based")/(SUMIFS(Data!$R$2:$R$51,Data!$G$2:$G$51,"dairy_animal",Data!$H$2:$H$51,"plant_based")+SUMIFS(Data!$R$2:$R$51,Data!$G$2:$G$51,"dairy_animal",Data!$H$2:$H$51,"animal_based"))) -> 1
A17: FG2 · dairy_alternative_plant | B17: =SUMIFS(Data!$R$2:$R$51,Data!$G$2:$G$51,"dairy_alternative_plant")/1000 -> 178.885 | C17: =D17+E17 -> 12.52195 | D17: =SUMIFS(Data!$S$2:$S$51,Data!$G$2:$G$51,"dairy_alternative_plant")/1000 -> 12.52195 | E17: =SUMIFS(Data!$T$2:$T$51,Data!$G$2:$G$51,"dairy_alternative_plant")/1000 -> 0 | F17: =IF(SUMIFS(Data!$R$2:$R$51,Data!$G$2:$G$51,"dairy_alternative_plant",Data!$H$2:$H$51,"plant_based")+SUMIFS(Data!$R$2:$R$51,Data!$G$2:$G$51,"dairy_alternative_plant",Data!$H$2:$H$51,"animal_based")=0,"",SUMIFS(Data!$R$2:$R$51,Data!$G$2:$G$51,"dairy_alternative_plant",Data!$H$2:$H$51,"plant_based")/(SUMIFS(Data!$R$2:$R$51,Data!$G$2:$G$51,"dairy_alternative_plant",Data!$H$2:$H$51,"plant_based")+SUMIFS(Data!$R$2:$R$51,Data!$G$2:$G$51,"dairy_alternative_plant",Data!$H$2:$H$51,"animal_based"))) -> 1 | G17: =IF(SUMIFS(Data!$R$2:$R$51,Data!$G$2:$G$51,"dairy_alternative_plant",Data!$H$2:$H$51,"plant_based")+SUMIFS(Data!$R$2:$R$51,Data!$G$2:$G$51,"dairy_alternative_plant",Data!$H$2:$H$51,"animal_based")=0,"",SUMIFS(Data!$R$2:$R$51,Data!$G$2:$G$51,"dairy_alternative_plant",Data!$H$2:$H$51,"animal_based")/(SUMIFS(Data!$R$2:$R$51,Data!$G$2:$G$51,"dairy_alternative_plant",Data!$H$2:$H$51,"plant_based")+SUMIFS(Data!$R$2:$R$51,Data!$G$2:$G$51,"dairy_alternative_plant",Data!$H$2:$H$51,"animal_based"))) -> 0
A18: FG3 · animal_based_fat | B18: =SUMIFS(Data!$R$2:$R$51,Data!$G$2:$G$51,"animal_based_fat")/1000 -> 150.10125 | C18: =D18+E18 -> 1.5010125 | D18: =SUMIFS(Data!$S$2:$S$51,Data!$G$2:$G$51,"animal_based_fat")/1000 -> 0 | E18: =SUMIFS(Data!$T$2:$T$51,Data!$G$2:$G$51,"animal_based_fat")/1000 -> 1.5010125 | F18: =IF(SUMIFS(Data!$R$2:$R$51,Data!$G$2:$G$51,"animal_based_fat",Data!$H$2:$H$51,"plant_based")+SUMIFS(Data!$R$2:$R$51,Data!$G$2:$G$51,"animal_based_fat",Data!$H$2:$H$51,"animal_based")=0,"",SUMIFS(Data!$R$2:$R$51,Data!$G$2:$G$51,"animal_based_fat",Data!$H$2:$H$51,"plant_based")/(SUMIFS(Data!$R$2:$R$51,Data!$G$2:$G$51,"animal_based_fat",Data!$H$2:$H$51,"plant_based")+SUMIFS(Data!$R$2:$R$51,Data!$G$2:$G$51,"animal_based_fat",Data!$H$2:$H$51,"animal_based"))) -> 0 | G18: =IF(SUMIFS(Data!$R$2:$R$51,Data!$G$2:$G$51,"animal_based_fat",Data!$H$2:$H$51,"plant_based")+SUMIFS(Data!$R$2:$R$51,Data!$G$2:$G$51,"animal_based_fat",Data!$H$2:$H$51,"animal_based")=0,"",SUMIFS(Data!$R$2:$R$51,Data!$G$2:$G$51,"animal_based_fat",Data!$H$2:$H$51,"animal_based")/(SUMIFS(Data!$R$2:$R$51,Data!$G$2:$G$51,"animal_based_fat",Data!$H$2:$H$51,"plant_based")+SUMIFS(Data!$R$2:$R$51,Data!$G$2:$G$51,"animal_based_fat",Data!$H$2:$H$51,"animal_based"))) -> 1
A19: FG3 · plant_based_fat | B19: =SUMIFS(Data!$R$2:$R$51,Data!$G$2:$G$51,"plant_based_fat")/1000 -> 748.20852 | C19: =D19+E19 -> 3.7410426 | D19: =SUMIFS(Data!$S$2:$S$51,Data!$G$2:$G$51,"plant_based_fat")/1000 -> 3.7410426 | E19: =SUMIFS(Data!$T$2:$T$51,Data!$G$2:$G$51,"plant_based_fat")/1000 -> 0 | F19: =IF(SUMIFS(Data!$R$2:$R$51,Data!$G$2:$G$51,"plant_based_fat",Data!$H$2:$H$51,"plant_based")+SUMIFS(Data!$R$2:$R$51,Data!$G$2:$G$51,"plant_based_fat",Data!$H$2:$H$51,"animal_based")=0,"",SUMIFS(Data!$R$2:$R$51,Data!$G$2:$G$51,"plant_based_fat",Data!$H$2:$H$51,"plant_based")/(SUMIFS(Data!$R$2:$R$51,Data!$G$2:$G$51,"plant_based_fat",Data!$H$2:$H$51,"plant_based")+SUMIFS(Data!$R$2:$R$51,Data!$G$2:$G$51,"plant_based_fat",Data!$H$2:$H$51,"animal_based"))) -> 1 | G19: =IF(SUMIFS(Data!$R$2:$R$51,Data!$G$2:$G$51,"plant_based_fat",Data!$H$2:$H$51,"plant_based")+SUMIFS(Data!$R$2:$R$51,Data!$G$2:$G$51,"plant_based_fat",Data!$H$2:$H$51,"animal_based")=0,"",SUMIFS(Data!$R$2:$R$51,Data!$G$2:$G$51,"plant_based_fat",Data!$H$2:$H$51,"animal_based")/(SUMIFS(Data!$R$2:$R$51,Data!$G$2:$G$51,"plant_based_fat",Data!$H$2:$H$51,"plant_based")+SUMIFS(Data!$R$2:$R$51,Data!$G$2:$G$51,"plant_based_fat",Data!$H$2:$H$51,"animal_based"))) -> 0
A20: FG5 · whole_grain | B20: =SUMIFS(Data!$R$2:$R$51,Data!$G$2:$G$51,"whole_grain")/1000 -> 516.75113 | C20: =D20+E20 -> 47.541103 | D20: =SUMIFS(Data!$S$2:$S$51,Data!$G$2:$G$51,"whole_grain")/1000 -> 47.541103 | E20: =SUMIFS(Data!$T$2:$T$51,Data!$G$2:$G$51,"whole_grain")/1000 -> 0 | F20: =IF(SUMIFS(Data!$R$2:$R$51,Data!$G$2:$G$51,"whole_grain",Data!$H$2:$H$51,"plant_based")+SUMIFS(Data!$R$2:$R$51,Data!$G$2:$G$51,"whole_grain",Data!$H$2:$H$51,"animal_based")=0,"",SUMIFS(Data!$R$2:$R$51,Data!$G$2:$G$51,"whole_grain",Data!$H$2:$H$51,"plant_based")/(SUMIFS(Data!$R$2:$R$51,Data!$G$2:$G$51,"whole_grain",Data!$H$2:$H$51,"plant_based")+SUMIFS(Data!$R$2:$R$51,Data!$G$2:$G$51,"whole_grain",Data!$H$2:$H$51,"animal_based"))) -> 1 | G20: =IF(SUMIFS(Data!$R$2:$R$51,Data!$G$2:$G$51,"whole_grain",Data!$H$2:$H$51,"plant_based")+SUMIFS(Data!$R$2:$R$51,Data!$G$2:$G$51,"whole_grain",Data!$H$2:$H$51,"animal_based")=0,"",SUMIFS(Data!$R$2:$R$51,Data!$G$2:$G$51,"whole_grain",Data!$H$2:$H$51,"animal_based")/(SUMIFS(Data!$R$2:$R$51,Data!$G$2:$G$51,"whole_grain",Data!$H$2:$H$51,"plant_based")+SUMIFS(Data!$R$2:$R$51,Data!$G$2:$G$51,"whole_grain",Data!$H$2:$H$51,"animal_based"))) -> 0
A21: FG5 · refined_grain | B21: =SUMIFS(Data!$R$2:$R$51,Data!$G$2:$G$51,"refined_grain")/1000 -> 2400.598 | C21: =D21+E21 -> 234.947 | D21: =SUMIFS(Data!$S$2:$S$51,Data!$G$2:$G$51,"refined_grain")/1000 -> 234.947 | E21: =SUMIFS(Data!$T$2:$T$51,Data!$G$2:$G$51,"refined_grain")/1000 -> 0 | F21: =IF(SUMIFS(Data!$R$2:$R$51,Data!$G$2:$G$51,"refined_grain",Data!$H$2:$H$51,"plant_based")+SUMIFS(Data!$R$2:$R$51,Data!$G$2:$G$51,"refined_grain",Data!$H$2:$H$51,"animal_based")=0,"",SUMIFS(Data!$R$2:$R$51,Data!$G$2:$G$51,"refined_grain",Data!$H$2:$H$51,"plant_based")/(SUMIFS(Data!$R$2:$R$51,Data!$G$2:$G$51,"refined_grain",Data!$H$2:$H$51,"plant_based")+SUMIFS(Data!$R$2:$R$51,Data!$G$2:$G$51,"refined_grain",Data!$H$2:$H$51,"animal_based"))) -> 1 | G21: =IF(SUMIFS(Data!$R$2:$R$51,Data!$G$2:$G$51,"refined_grain",Data!$H$2:$H$51,"plant_based")+SUMIFS(Data!$R$2:$R$51,Data!$G$2:$G$51,"refined_grain",Data!$H$2:$H$51,"animal_based")=0,"",SUMIFS(Data!$R$2:$R$51,Data!$G$2:$G$51,"refined_grain",Data!$H$2:$H$51,"animal_based")/(SUMIFS(Data!$R$2:$R$51,Data!$G$2:$G$51,"refined_grain",Data!$H$2:$H$51,"plant_based")+SUMIFS(Data!$R$2:$R$51,Data!$G$2:$G$51,"refined_grain",Data!$H$2:$H$51,"animal_based"))) -> 0
A23: Food groups FG4, FG6 and FG7 have no subgroup and therefore do not appear above; they are detailed on the WWF tab.
A25: Retailer categories
A27: Category | B27: Mass (t) | C27: Protein (t) | D27: Plant protein (t) | E27: Animal protein (t) | F27: Plant share | G27: Animal share
A28: {=UNIQUE(Data!E2:E994)} -> Out-of-scope product - category | B28: =SUMIFS(Data!$R$2:$R$51,Data!$E$2:$E$51,A28)/100 -> 83634.205 | C28: =D28+E28 -> 91.737669 | D28: =SUMIFS(Data!$S$2:$S$51,Data!$E$2:$E$51,A28)/1000 -> 91.737669 | E28: =SUMIFS(Data!$T$2:$T$51,Data!$E$2:$E$51,A28)/1000 -> 0 | F28: =IF(C28=0,"",D28/C28) -> 1 | G28: =IF(C28=0,"",E28/C28) -> 0
